Workbook
Name 대분류: '설정시트'!$C$7:$C$20
Name 결제수단: '설정시트'!$D$23:$I$23

Sheet 예시)설정

Sheet 예시)자산관리

Sheet 예시)월간

Sheet 설정시트
C3: 연도 | D3: 2024
C6: 대분류 | D6: 소분류
C7: 수입 | D7: 🍪 월급 | E7: 🍪 부수입 | F7: 🐻 월급 | G7: 🐻 부수입 | H7: 기타
C8: 저축 | D8: 주택청약 | E8: 우리은행 | F8: 케이뱅크 | G8: 연금저축
C9: 🍪고정비 | D9: 관리비 | E9: 월세 | F9: 대출이자 | G9: 통신비 | H9: 보험료 | I9: 곗돈
C10: 🐻고정비 | D10: 관리비 | E10: 대출이자 | F10: 통신비 | G10: 보험료 | H10: 곗돈
C11: 🍪생필품 | D11: 주방/욕실 | E11: 소모품 | F11: 기타
C12: 🐻생필품 | D12: 주방/욕실 | E12: 소모품 | F12: 기타
C13: 🍪식비 | D13: 식재료비 | E13: 회사점심 | F13: 간식/카페 | G13: 외식/배달 | H13: 기타
C14: 🐻식비 | D14: 식재료비 | E14: 회사점심 | F14: 간식/카페 | G14: 외식/배달 | H14: 기타
C15: 🍪여가비 | D15: 의류/잡화 | E15: OTT | F15: 문화생활 | G15: 자기계발 | H15: 미용 | I15: 기타
C16: 🐻여가비 | D16: 의류/잡화 | E16: OTT | F16: 문화생활 | G16: 자기계발 | H16: 미용 | I16: 기타
C17: 🍪기타 | D17: 약국 | E17: 병원비 | F17: 영양제 | G17: 교통비 | H17: 주유비 | I17: 기타
C18: 🐻기타 | D18: 약국 | E18: 병원비 | F18: 영양제 | G18: 교통비 | H18: 주유비 | I18: 기타
C19: 🍪이벤트성 | D19: 축의/부의금 | E19: 생신/생일선물 | F19: 명절/어버이날 | G19: 여행 | H19: 기타
C20: 🐻 이벤트성 | D20: 축의/부의금 | E20: 생신/생일선물 | F20: 명절/어버이날 | G20: 여행 | H20: 기타
C23: 결제수단 | D23: 체크카드 | E23: 현금/이체 | F23: 현대카드 | G23: 국민카드 | H23: 현백카드 | I23: 하나카드

Sheet 연간시트
C6: 2024 | F6: 수입 | J6: 저축/현금 | N6: 지출
F8: =W52 -> 125456964 | J8: =X52 -> 81966782 | N8: =Y52 -> 43490182
V13: 지출 | W13: 합계
V14: =$C$81 -> 총🍪고정비 | W14: =$E$81 -> 4918833 | X14: =_xlfn.RANK.EQ(W14,$W$14:$W$25,0) + ROW(AE1)/10000 -> 4.0001 | Y14: =SMALL($X$14:$X$25, ROW(AE1)) -> 1.0007 | Z14: =INDEX($V$14:$V$25,MATCH(Y14,$X$14:$X$25,0)) -> 총🍪여가비 | AA14: =INDEX($W$14:$W$25,MATCH(Y14,$X$14:$X$25,0)) -> 9653644
V15: =$C$88 -> 총🐻고정비 | W15: =$E$88 -> 1682699 | X15: =_xlfn.RANK.EQ(W15,$W$14:$W$25,0) + ROW(AE2)/10000 -> 10.0002 | Y15: =SMALL($X$14:$X$25, ROW(AE2)) -> 2.0005 | Z15: =INDEX($V$14:$V$25,MATCH(Y15,$X$14:$X$25,0)) -> 총🍪식비 | AA15: =INDEX($W$14:$W$25,MATCH(Y15,$X$14:$X$25,0)) -> 7072524
V16: =$C$95 -> 총🍪생필품 | W16: =$E$95 -> 565896 | X16: =_xlfn.RANK.EQ(W16,$W$14:$W$25,0) + ROW(AE3)/10000 -> 11.0003 | Y16: =SMALL($X$14:$X$25, ROW(AE3)) -> 3.0012 | Z16: =INDEX($V$14:$V$25,MATCH(Y16,$X$14:$X$25,0)) -> 총🐻 이벤트성 | AA16: =INDEX($W$14:$W$25,MATCH(Y16,$X$14:$X$25,0)) -> 4973395
V17: =$C$102 -> 총🐻생필품 | W17: =$E$102 -> 438375 | X17: =_xlfn.RANK.EQ(W17,$W$14:$W$25,0) + ROW(AE4)/10000 -> 12.0004 | Y17: =SMALL($X$14:$X$25, ROW(AE4)) -> 4.0001 | Z17: =INDEX($V$14:$V$25,MATCH(Y17,$X$14:$X$25,0)) -> 총🍪고정비 | AA17: =INDEX($W$14:$W$25,MATCH(Y17,$X$14:$X$25,0)) -> 4918833
V18: =$C$109 -> 총🍪식비 | W18: =$E$109 -> 7072524 | X18: =_xlfn.RANK.EQ(W18,$W$14:$W$25,0) + ROW(AE5)/10000 -> 2.0005 | Y18: =SMALL($X$14:$X$25, ROW(AE5)) -> 5.0011 | Z18: =INDEX($V$14:$V$25,MATCH(Y18,$X$14:$X$25,0)) -> 총🍪이벤트성 | AA18: =INDEX($W$14:$W$25,MATCH(Y18,$X$14:$X$25,0)) -> 3359230
V19: =$C$116 -> 총🐻식비 | W19: =$E$116 -> 2521432 | X19: =_xlfn.RANK.EQ(W19,$W$14:$W$25,0) + ROW(AE6)/10000 -> 8.0006 | Y19: =SMALL($X$14:$X$25, ROW(AE6)) -> 6.0008 | Z19: =INDEX($V$14:$V$25,MATCH(Y19,$X$14:$X$25,0)) -> 총🐻여가비 | AA19: =INDEX($W$14:$W$25,MATCH(Y19,$X$14:$X$25,0)) -> 3057072
V20: =$C$123 -> 총🍪여가비 | W20: =$E$123 -> 9653644 | X20: =_xlfn.RANK.EQ(W20,$W$14:$W$25,0) + ROW(AE7)/10000 -> 1.0007 | Y20: =SMALL($X$14:$X$25, ROW(AE7)) -> 7.001 | Z20: =INDEX($V$14:$V$25,MATCH(Y20,$X$14:$X$25,0)) -> 총🐻기타 | AA20: =INDEX($W$14:$W$25,MATCH(Y20,$X$14:$X$25,0)) -> 2917235
V21: =$C$130 -> 총🐻여가비 | W21: =$E$130 -> 3057072 | X21: =_xlfn.RANK.EQ(W21,$W$14:$W$25,0) + ROW(AE8)/10000 -> 6.0008 | Y21: =SMALL($X$14:$X$25, ROW(AE8)) -> 8.0006 | Z21: =INDEX($V$14:$V$25,MATCH(Y21,$X$14:$X$25,0)) -> 총🐻식비 | AA21: =INDEX($W$14:$W$25,MATCH(Y21,$X$14:$X$25,0)) -> 2521432
V22: =$C$137 -> 총🍪기타 | W22: =$E$137 -> 2329847 | X22: =_xlfn.RANK.EQ(W22,$W$14:$W$25,0) + ROW(AE9)/10000 -> 9.0009 | Y22: =SMALL($X$14:$X$25, ROW(AE9)) -> 9.0009 | Z22: =INDEX($V$14:$V$25,MATCH(Y22,$X$14:$X$25,0)) -> 총🍪기타 | AA22: =INDEX($W$14:$W$25,MATCH(Y22,$X$14:$X$25,0)) -> 2329847
V23: =$C$144 -> 총🐻기타 | W23: =$E$144 -> 2917235 | X23: =_xlfn.RANK.EQ(W23,$W$14:$W$25,0) + ROW(AE10)/10000 -> 7.001 | Y23: =SMALL($X$14:$X$25, ROW(AE10)) -> 10.0002 | Z23: =INDEX($V$14:$V$25,MATCH(Y23,$X$14:$X$25,0)) -> 총🐻고정비 | AA23: =INDEX($W$14:$W$25,MATCH(Y23,$X$14:$X$25,0)) -> 1682699
V24: =$C$151 -> 총🍪이벤트성 | W24: =$E$151 -> 3359230 | X24: =_xlfn.RANK.EQ(W24,$W$14:$W$25,0) + ROW(AE11)/10000 -> 5.0011 | Y24: =SMALL($X$14:$X$25, ROW(AE11)) -> 11.0003 | Z24: =INDEX($V$14:$V$25,MATCH(Y24,$X$14:$X$25,0)) -> 총🍪생필품 | AA24: =INDEX($W$14:$W$25,MATCH(Y24,$X$14:$X$25,0)) -> 565896
V25: =$C$158 -> 총🐻 이벤트성 | W25: =$E$158 -> 4973395 | X25: =_xlfn.RANK.EQ(W25,$W$14:$W$25,0) + ROW(AE12)/10000 -> 3.0012 | Y25: =SMALL($X$14:$X$25, ROW(AE12)) -> 12.0004 | Z25: =INDEX($V$14:$V$25,MATCH(Y25,$X$14:$X$25,0)) -> 총🐻생필품 | AA25: =INDEX($W$14:$W$25,MATCH(Y25,$X$14:$X$25,0)) -> 438375
V29: 결제수단 | W29: 합계
V30: ='1월'!$E$14 -> 체크카드 | W30: ='1월'!$F14+'2월'!$F14+'3월'!$F14+'4월'!$F14+'5월'!$F14+'6월'!$F14+'7월'!$F14+'8월'!$F14+'9월'!$F14+'10월'!$F14+'11월'!$F14+'12월'!$F14 -> 1813541 | X30: =_xlfn.RANK.EQ(W30,$W$30:$W$35,0) + ROW(AE1)/10000 -> 5.0001 | Y30: =SMALL($X$30:$X$35, ROW(AE1)) -> 1.0002 | Z30: =INDEX($V$30:$V$35,MATCH(Y30,$X$30:$X$35,0)) -> 현금/이체 | AA30: =INDEX($W$30:$W$35,MATCH(Y30,$X$30:$X$35,0)) -> 21080493
V31: ='1월'!$E$15 -> 현금/이체 | W31: ='1월'!$F15+'2월'!$F15+'3월'!$F15+'4월'!$F15+'5월'!$F15+'6월'!$F15+'7월'!$F15+'8월'!$F15+'9월'!$F15+'10월'!$F15+'11월'!$F15+'12월'!$F15 -> 21080493 | X31: =_xlfn.RANK.EQ(W31,$W$30:$W$35,0) + ROW(AE2)/10000 -> 1.0002 | Y31: =SMALL($X$30:$X$35, ROW(AE2)) -> 2.0003 | Z31: =INDEX($V$30:$V$35,MATCH(Y31,$X$30:$X$35,0)) -> 현대카드 | AA31: =INDEX($W$30:$W$35,MATCH(Y31,$X$30:$X$35,0)) -> 10041441
V32: ='1월'!$E$16 -> 현대카드 | W32: ='1월'!$F16+'2월'!$F16+'3월'!$F16+'4월'!$F16+'5월'!$F16+'6월'!$F16+'7월'!$F16+'8월'!$F16+'9월'!$F16+'10월'!$F16+'11월'!$F16+'12월'!$F16 -> 10041441 | X32: =_xlfn.RANK.EQ(W32,$W$30:$W$35,0) + ROW(AE3)/10000 -> 2.0003 | Y32: =SMALL($X$30:$X$35, ROW(AE3)) -> 3.0004 | Z32: =INDEX($V$30:$V$35,MATCH(Y32,$X$30:$X$35,0)) -> 국민카드 | AA32: =INDEX($W$30:$W$35,MATCH(Y32,$X$30:$X$35,0)) -> 9975889
V33: ='1월'!$E$17 -> 국민카드 | W33: ='1월'!$F17+'2월'!$F17+'3월'!$F17+'4월'!$F17+'5월'!$F17+'6월'!$F17+'7월'!$F17+'8월'!$F17+'9월'!$F17+'10월'!$F17+'11월'!$F17+'12월'!$F17 -> 9975889 | X33: =_xlfn.RANK.EQ(W33,$W$30:$W$35,0) + ROW(AE4)/10000 -> 3.0004 | Y33: =SMALL($X$30:$X$35, ROW(AE4)) -> 4.0006 | Z33: =INDEX($V$30:$V$35,MATCH(Y33,$X$30:$X$35,0)) -> 하나카드 | AA33: =INDEX($W$30:$W$35,MATCH(Y33,$X$30:$X$35,0)) -> 7422033
V34: ='1월'!$E$18 -> 현백카드 | W34: ='1월'!$F18+'2월'!$F18+'3월'!$F18+'4월'!$F18+'5월'!$F18+'6월'!$F18+'7월'!$F18+'8월'!$F18+'9월'!$F18+'10월'!$F18+'11월'!$F18+'12월'!$F18 -> 691870 | X34: =_xlfn.RANK.EQ(W34,$W$30:$W$35,0) + ROW(AE5)/10000 -> 6.0005 | Y34: =SMALL($X$30:$X$35, ROW(AE5)) -> 5.0001 | Z34: =INDEX($V$30:$V$35,MATCH(Y34,$X$30:$X$35,0)) -> 체크카드 | AA34: =INDEX($W$30:$W$35,MATCH(Y34,$X$30:$X$35,0)) -> 1813541
V35: ='1월'!$E$19 -> 하나카드 | W35: ='1월'!$F19+'2월'!$F19+'3월'!$F19+'4월'!$F19+'5월'!$F19+'6월'!$F19+'7월'!$F19+'8월'!$F19+'9월'!$F19+'10월'!$F19+'11월'!$F19+'12월'!$F19 -> 7422033 | X35: =_xlfn.RANK.EQ(W35,$W$30:$W$35,0) + ROW(AE6)/10000 -> 4.0006 | Y35: =SMALL($X$30:$X$35, ROW(AE6)) -> 6.0005 | Z35: =INDEX($V$30:$V$35,MATCH(Y35,$X$30:$X$35,0)) -> 현백카드 | AA35: =INDEX($W$30:$W$35,MATCH(Y35,$X$30:$X$35,0)) -> 691870
W39: 수입 | X39: 저축/현금 | Y39: 지출 | Z39: 저축률 | AB39: 수입 | AC39: 합계
V40: 1월 | W40: =F64 -> 0 | X40: =SUM(F73:F74) -> 0 | Y40: =SUM(F81,F88,F95,F102,F109,F116,F123,F130,F137,F144,F151,F158) -> 0 | Z40: =X40/W40 -> #DIV/0! | AB40: =D56 -> 🍪 월급 | AC40: =E56 -> 31681500 | AD40: =_xlfn.RANK.EQ(AC40,$AC$40:$AC$47,0) + ROW(AE1)/10000 -> 2.0001 | AE40: =SMALL($AD$40:$AD$47, ROW(AE1)) -> 1.0003 | AF40: =INDEX($AB$40:$AB$47,MATCH(AE40,$AD$40:$AD$47,0)) -> 🐻 월급 | AG40: =INDEX($AC$40:$AC$47,MATCH(AE40,$AD$40:$AD$47,0)) -> 65870183
V41: 2월 | W41: =G64 -> 0 | X41: =SUM(G73:G74) -> 0 | Y41: =SUM(G81,G88,G95,G102,G109,G116,G123,G130,G137,G144,G151,G158) -> 0 | Z41: =X41/W41 -> #DIV/0! | AB41: =D57 -> 🍪 부수입 | AC41: =E57 -> 5801000 | AD41: =_xlfn.RANK.EQ(AC41,$AC$40:$AC$47,0) + ROW(AE2)/10000 -> 5.0002 | AE41: =SMALL($AD$40:$AD$47, ROW(AE2)) -> 2.0001 | AF41: =INDEX($AB$40:$AB$47,MATCH(AE41,$AD$40:$AD$47,0)) -> 🍪 월급 | AG41: =INDEX($AC$40:$AC$47,MATCH(AE41,$AD$40:$AD$47,0)) -> 31681500
V42: 3월 | W42: =H64 -> 0 | X42: =SUM(H73:H74) -> 0 | Y42: =SUM(H81,H88,H95,H102,H109,H116,H123,H130,H137,H144,H151,H158) -> 0 | Z42: =X42/W42 -> #DIV/0! | AB42: =D58 -> 🐻 월급 | AC42: =E58 -> 65870183 | AD42: =_xlfn.RANK.EQ(AC42,$AC$40:$AC$47,0) + ROW(AE3)/10000 -> 1.0003 | AE42: =SMALL($AD$40:$AD$47, ROW(AE3)) -> 3.0004 | AF42: =INDEX($AB$40:$AB$47,MATCH(AE42,$AD$40:$AD$47,0)) -> 🐻 부수입 | AG42: =INDEX($AC$40:$AC$47,MATCH(AE42,$AD$40:$AD$47,0)) -> 15364050
V43: 4월 | W43: =I64 -> 0 | X43: =SUM(I73:I74) -> 0 | Y43: =SUM(I81,I88,I95,I102,I109,I116,I123,I130,I137,I144,I151,I158) -> 0 | Z43: =X43/W43 -> #DIV/0! | AB43: =D59 -> 🐻 부수입 | AC43: =E59 -> 15364050 | AD43: =_xlfn.RANK.EQ(AC43,$AC$40:$AC$47,0) + ROW(AE4)/10000 -> 3.0004 | AE43: =SMALL($AD$40:$AD$47, ROW(AE4)) -> 4.0005 | AF43: =INDEX($AB$40:$AB$47,MATCH(AE43,$AD$40:$AD$47,0)) -> 기타 | AG43: =INDEX($AC$40:$AC$47,MATCH(AE43,$AD$40:$AD$47,0)) -> 6740231
V44: 5월 | W44: =J64 -> 6200000 | X44: =SUM(J73:J74) -> 4399422 | Y44: =SUM(J81,J88,J95,J102,J109,J116,J123,J130,J137,J144,J151,J158) -> 1800578 | Z44: =X44/W44 -> 0.70958419 | AB44: =D60 -> 기타 | AC44: =E60 -> 6740231 | AD44: =_xlfn.RANK.EQ(AC44,$AC$40:$AC$47,0) + ROW(AE5)/10000 -> 4.0005 | AE44: =SMALL($AD$40:$AD$47, ROW(AE5)) -> 5.0002 | AF44: =INDEX($AB$40:$AB$47,MATCH(AE44,$AD$40:$AD$47,0)) -> 🍪 부수입 | AG44: =INDEX($AC$40:$AC$47,MATCH(AE44,$AD$40:$AD$47,0)) -> 5801000
V45: 6월 | W45: =K64 -> 28071244 | X45: =SUM(K73:K74) -> 20866479 | Y45: =SUM(K81,K88,K95,K102,K109,K116,K123,K130,K137,K144,K151,K158) -> 7204765 | Z45: =X45/W45 -> 0.74334002 | AB45: =D61 | AC45: =E61 -> 0 | AD45: =_xlfn.RANK.EQ(AC45,$AC$40:$AC$47,0) + ROW(AE6)/10000 -> 6.0006 | AE45: =SMALL($AD$40:$AD$47, ROW(AE6)) -> 6.0006 | AF45: =INDEX($AB$40:$AB$47,MATCH(AE45,$AD$40:$AD$47,0)) | AG45: =INDEX($AC$40:$AC$47,MATCH(AE45,$AD$40:$AD$47,0)) -> 0
V46: 7월 | W46: =L64 -> 10065820 | X46: =SUM(L73:L74) -> 4614307 | Y46: =SUM(L81,L88,L95,L102,L109,L116,L123,L130,L137,L144,L151,L158) -> 5451513 | Z46: =X46/W46 -> 0.45841342 | AB46: =D62 | AC46: =E62 -> 0 | AD46: =_xlfn.RANK.EQ(AC46,$AC$40:$AC$47,0) + ROW(AE7)/10000 -> 6.0007 | AE46: =SMALL($AD$40:$AD$47, ROW(AE7)) -> 6.0007 | AF46: =INDEX($AB$40:$AB$47,MATCH(AE46,$AD$40:$AD$47,0)) | AG46: =INDEX($AC$40:$AC$47,MATCH(AE46,$AD$40:$AD$47,0)) -> 0
V47: 8월 | W47: =M64 -> 3332030 | X47: =SUM(M73:M74) -> -3415305 | Y47: =SUM(M81,M88,M95,M102,M109,M116,M123,M130,M137,M144,M151,M158) -> 6747335 | Z47: =X47/W47 -> -1.0249923 | AB47: =D63 | AC47: =E63 -> 0 | AD47: =_xlfn.RANK.EQ(AC47,$AC$40:$AC$47,0) + ROW(AE8)/10000 -> 6.0008 | AE47: =SMALL($AD$40:$AD$47, ROW(AE8)) -> 6.0008 | AF47: =INDEX($AB$40:$AB$47,MATCH(AE47,$AD$40:$AD$47,0)) | AG47: =INDEX($AC$40:$AC$47,MATCH(AE47,$AD$40:$AD$47,0)) -> 0
V48: 9월 | W48: =N64 -> 46239400 | X48: =SUM(N73:N74) -> 38355780 | Y48: =SUM(N81,N88,N95,N102,N109,N116,N123,N130,N137,N144,N151,N158) -> 7883620 | Z48: =X48/W48 -> 0.82950428
V49: 10월 | W49: =O64 -> 8930120 | X49: =SUM(O73:O74) -> 5611522 | Y49: =SUM(O81,O88,O95,O102,O109,O116,O123,O130,O137,O144,O151,O158) -> 3318598 | Z49: =X49/W49 -> 0.62838148
V50: 11월 | W50: =P64 -> 8712580 | X50: =SUM(P73:P74) -> 5273142 | Y50: =SUM(P81,P88,P95,P102,P109,P116,P123,P130,P137,P144,P151,P158) -> 3439438 | Z50: =X50/W50 -> 0.60523312
V51: 12월 | W51: =Q64 -> 13905770 | X51: =SUM(Q73:Q74) -> 6261435 | Y51: =SUM(Q81,Q88,Q95,Q102,Q109,Q116,Q123,Q130,Q137,Q144,Q151,Q158) -> 7644335 | Z51: =X51/W51 -> 0.45027604
W52: =SUM(W40:W51) -> 125456964 | X52: =SUM(X40:X51) -> 81966782 | Y52: =SUM(Y40:Y51) -> 43490182
C55: 대분류 | D55: 소분류 | E55: 합계 | F55: 1월 | G55: 2월 | H55: 3월 | I55: 4월 | J55: 5월 | K55: 6월 | L55: 7월 | M55: 8월 | N55: 9월 | O55: 10월 | P55: 11월 | Q55: 12월 | R55: 평균
C56: 수입 | D56: 🍪 월급 | E56: =SUM(F56:Q56) -> 31681500 | F56: {=INDIRECT("1월!$F$25")} -> 0 | G56: {=INDIRECT("2월!$F$25")} -> 0 | H56: {=INDIRECT("3월!$F$25")} -> 0 | I56: {=INDIRECT("4월!$F$25")} -> 0 | J56: {=INDIRECT("5월!$F$25")} -> 3300000 | K56: {=INDIRECT("6월!$F$25")} -> 3831300 | L56: {=INDIRECT("7월!$F$25")} -> 3257030 | M56: {=INDIRECT("8월!$F$25")} -> 3257030 | N56: {=INDIRECT("9월!$F$25")} -> 3836270 | O56: {=INDIRECT("10월!$F$25")} -> 3270300 | P56: {=INDIRECT("11월!$F$25")} -> 3257030 | Q56: {=INDIRECT("12월!$F$25")} -> 7672540 | R56: =IFERROR(SUM(F56:Q56)/W$69,"") -> 3960187.5 | W56: 작성여부
D57: 🍪 부수입 | E57: =SUM(F57:Q57) -> 5801000 | F57: {=INDIRECT("1월!$F$26")} -> 0 | G57: {=INDIRECT("2월!$F$26")} -> 0 | H57: {=INDIRECT("3월!$F$26")} -> 0 | I57: {=INDIRECT("4월!$F$26")} -> 0 | J57: {=INDIRECT("5월!$F$26")} -> 2900000 | K57: {=INDIRECT("6월!$F$26")} -> 2901000 | L57: {=INDIRECT("7월!$F$26")} -> 0 | M57: {=INDIRECT("8월!$F$26")} -> 0 | N57: {=INDIRECT("9월!$F$26")} -> 0 | O57: {=INDIRECT("10월!$F$26")} -> 0 | P57: {=INDIRECT("11월!$F$26")} -> 0 | Q57: {=INDIRECT("12월!$F$26")} -> 0 | R57: =IFERROR(SUM(F57:Q57)/W$69,"") -> 725125 | V57: 1월 | W57: =IF(COUNTIF(F56:F158, "<>0") > 0, 1, 0) -> 0
D58: 🐻 월급 | E58: =SUM(F58:Q58) -> 65870183 | F58: {=INDIRECT("1월!$F$27")} -> 0 | G58: {=INDIRECT("2월!$F$27")} -> 0 | H58: {=INDIRECT("3월!$F$27")} -> 0 | I58: {=INDIRECT("4월!$F$27")} -> 0 | J58: {=INDIRECT("5월!$F$27")} -> 0 | K58: {=INDIRECT("6월!$F$27")} -> 8440744 | L58: {=INDIRECT("7월!$F$27")} -> 3125670 | M58: {=INDIRECT("8월!$F$27")} -> 0 | N58: {=INDIRECT("9월!$F$27")} -> 38127639 | O58: {=INDIRECT("10월!$F$27")} -> 5631530 | P58: {=INDIRECT("11월!$F$27")} -> 5353370 | Q58: {=INDIRECT("12월!$F$27")} -> 5191230 | R58: =IFERROR(SUM(F58:Q58)/W$69,"") -> 8233772.9 | V58: 2월 | W58: =IF(COUNTIF(G56:G158, "<>0") > 0, 1, 0) -> 0
...

Sheet 자산관리
C22: 대분류 | D22: 소분류 | E22: 1월 | F22: 2월 | G22: 3월 | H22: 4월 | I22: 5월 | J22: 6월 | K22: 7월 | L22: 8월 | M22: 9월 | N22: 10월 | O22: 11월 | P22: 12월
C23: 부채 | D23: 전세대출 | E23: 60000000 | F23: 60000000 | G23: 60000000 | H23: 60000000 | I23: 60000000 | J23: 60000000 | K23: 60000000 | L23: 60000000 | M23: 60000000 | N23: 60000000 | O23: 60000000 | P23: 60000000
C29: 부채 합계 | E29: =SUM(E23:E28) -> 60000000 | F29: =SUM(F23:F28) -> 60000000 | G29: =SUM(G23:G28) -> 60000000 | H29: =SUM(H23:H28) -> 60000000 | I29: =SUM(I23:I28) -> 60000000 | J29: =SUM(J23:J28) -> 60000000 | K29: =SUM(K23:K28) -> 60000000 | L29: =SUM(L23:L28) -> 60000000 | ... P29: =SUM(P23:P28) -> 60000000
C30: 비유동자산 | D30: 아트포레-전세보증금 | E30: 340000000 | F30: 340000000 | G30: 340000000 | H30: 340000000 | I30: 340000000 | J30: 340000000 | K30: 340000000 | L30: 340000000 | M30: 340000000 | N30: 300000000 | O30: 300000000 | P30: 300000000
D31: SK뷰-전세보증금 | N31: 50000000 | O31: 50000000 | P31: 50000000
D32: 🐻주택청약 | E32: 10010010 | F32: 10060010 | G32: 10110010 | H32: 10160010 | I32: 10210010 | J32: 10260010 | K32: 10260010 | L32: 10260010 | M32: 10260010 | N32: 10260010 | O32: 10260010 | P32: 10260010
D33: 🍪주택청약 | E33: 2380000 | F33: 2400000 | G33: 2420000 | H33: 2440000 | I33: 2460000 | J33: 3000000 | K33: 3000000 | L33: 3000000 | M33: 3000000 | N33: 3000000 | O33: 3000000 | P33: 3000000
C37: 비유동자산 합계 | E37: =SUM(E30:E36) -> 352390010 | F37: =SUM(F30:F36) -> 352460010 | G37: =SUM(G30:G36) -> 352530010 | H37: =SUM(H30:H36) -> 352600010 | I37: =SUM(I30:I36) -> 352670010 | J37: =SUM(J30:J36) -> 353260010 | K37: =SUM(K30:K36) -> 353260010 | L37: =SUM(L30:L36) -> 353260010 | ... P37: =SUM(P30:P36) -> 363260010
C38: 유동자산 (투자) | D38: 🐻주식 | J38: 10914659 | K38: 9125617 | L38: 8434149 | M38: =10635233+143752 -> 10778985 | N38: =10635233+143752 -> 10778985
D39: 🐻연금저축 | J39: 5755642 | K39: 7711965 | L39: 8000049 | M39: 8072426 | N39: 8072426
D40: 🍪주식 | J40: 1956027 | K40: 1920301
D41: 🍪연금저축 | J41: 3724782 | K41: 3834193 | N41: 4244327
E43: - | G43: -
C45: 유동자산(투자) 합계 | E45: =SUM(E38:E44) -> 0 | F45: =SUM(F38:F44) -> 0 | G45: =SUM(G38:G44) -> 0 | H45: =SUM(H38:H44) -> 0 | I45: =SUM(I38:I44) -> 0 | J45: =SUM(J38:J44) -> 22351110 | K45: =SUM(K38:K44) -> 22592076 | L45: =SUM(L38:L44) -> 16434198 | ... P45: =SUM(P38:P44) -> 0
D46: 🐻우리은행적금 | E46: 500000 | F46: 1000000 | G46: 1500000 | H46: 2000000 | I46: 2500000 | J46: 3000000 | K46: 3500000 | L46: 4000000 | M46: 4500000 | N46: 5000000 | O46: 5500000 | P46: 6000000
D47: 🐻K뱅크-예금 | E47: 10000000 | F47: 10000000 | G47: 10000000 | H47: 10000000 | I47: 10000000 | J47: 10000000 | K47: 10000000 | L47: 10000000 | M47: 10000000 | N47: 10000000 | O47: 10000000 | P47: 0
D48: 🐻K뱅크-생활통장 | E48: 3000000 | F48: 3000000 | G48: 3000000 | H48: 3000000 | I48: 3000000 | J48: 3000000 | K48: 3000000 | L48: 1850000 | M48: 3000000 | N48: 3000000 | O48: 3000000 | P48: 3000000
D49: 🐻K뱅크-파킹 | J49: 12500000 | K49: 12500000 | L49: 16550000 | M49: 45000000 | N49: 54000000 | O49: 59000000 | P49: 73000000
D50: 🍪우리은행적금 | E50: 500000 | F50: 1000000 | G50: 1500000 | H50: 2000000 | I50: 2500000 | J50: 3000000 | K50: 3500000 | L50: 4000000 | M50: 4500000 | N50: 5000000 | O50: 5500000 | P50: 6000000
D51: 🍪K뱅크-예금 | E51: 35000000 | F51: 35000000 | G51: 35000000 | H51: 35000000 | I51: 35000000 | J51: 35000000 | K51: 35000000 | L51: 35000000 | M51: 15000000 | N51: 15000000 | O51: 15000000 | P51: 0
D52: 🍪K뱅크-생활통장 | E52: 3000000 | F52: 3000000 | G52: 3000000 | H52: 3000000 | I52: 3000000 | J52: 3000000 | K52: 3000000 | L52: 3000000 | M52: 3000000 | N52: 3000000 | O52: 3000000 | P52: 3000000
D53: 🍪K뱅크-파킹 | E53: 16000000 | F53: 16000000 | G53: 16000000 | H53: 16000000 | I53: 16000000 | J53: 16000000 | K53: 16000000 | L53: 16000000 | M53: 36000000 | N53: 21000000 | O53: 24000000 | P53: 39000000
C54: 유동자산(현금) 합계 | E54: =SUM(E46:E53) -> 68000000 | F54: =SUM(F46:F53) -> 69000000 | G54: =SUM(G46:G53) -> 70000000 | H54: =SUM(H46:H53) -> 71000000 | I54: =SUM(I46:I53) -> 72000000 | J54: =SUM(J46:J53) -> 85500000 | K54: =SUM(K46:K53) -> 86500000 | L54: =SUM(L46:L53) -> 90400000 | ... P54: =SUM(P46:P53) -> 130000000
C55: 순자산 | E55: =SUM(E37,E54) -> 420390010 | F55: =SUM(F37,F54) -> 421460010 | G55: =SUM(G37,G54) -> 422530010 | H55: =SUM(H37,H54) -> 423600010 | I55: =SUM(I37,I54) -> 424670010 | J55: =SUM(J37,J54) -> 438760010 | K55: =SUM(K37,K54) -> 439760010 | L55: =SUM(L37,L54) -> 443660010 | ... P55: =SUM(P37,P54) -> 493260010
C56: 증감액 | F56: =IF(F55=0, "",F55-E55) -> 1070000 | G56: =IF(G55=0, "",G55-F55) -> 1070000 | H56: =IF(H55=0, "",H55-G55) -> 1070000 | I56: =IF(I55=0, "",I55-H55) -> 1070000 | J56: =IF(J55=0, "",J55-I55) -> 14090000 | K56: =IF(K55=0, "",K55-J55) -> 1000000 | L56: =IF(L55=0, "",L55-K55) -> 3900000 | M56: =IF(M55=0, "",M55-L55) -> 30600000 | ... P56: =IF(P55=0, "",P55-O55) -> 5000000
C57: 주식칸도 만들어봄♥

Sheet 1월
C3: 2024 | D3: 1
R8: S | S8: M | T8: T | U8: W | V8: T | W8: F | X8: S | Y8: 누적 | AB8: 대분류 | AC8: 합계
R9: =DATE($C$3,$D$3,1)-WEEKDAY(DATE($C$3,$D$3,1))+1 -> 45291 | S9: =R9 + 1 -> 45292 | T9: =S9 + 1 -> 45293 | U9: =T9 + 1 -> 45294 | V9: =U9 + 1 -> 45295 | W9: =V9 + 1 -> 45296 | X9: =W9 + 1 -> 45297 | AB9: =$H$25 -> 🍪고정비 | AC9: =$K$31 -> 0 | AD9: =_xlfn.RANK.EQ(AC9,$AB$9:$AC$20,0) + ROW(AB1)/10000 -> 1.0001 | AE9: =SMALL($AD$9:$AD$20, ROW(AB1)) -> 1.0001 | AF9: =INDEX($AB$9:$AB$20,MATCH(AE9,$AD$9:$AD$20,0)) -> 🍪고정비 | AG9: =INDEX($AC$9:$AC$20,MATCH(AE9,$AD$9:$AD$20,0)) -> 0
R10: =SUMIFS($K$62:$K$500,$H$62:$H$500,R9,$I$62:$I$500,"<>수입",$I$62:$I$500,"<>저축") -> 0 | S10: =SUMIFS($K$62:$K$500,$H$62:$H$500,S9,$I$62:$I$500,"<>수입",$I$62:$I$500,"<>저축") -> 0 | T10: =SUMIFS($K$62:$K$500,$H$62:$H$500,T9,$I$62:$I$500,"<>수입",$I$62:$I$500,"<>저축") -> 0 | U10: =SUMIFS($K$62:$K$500,$H$62:$H$500,U9,$I$62:$I$500,"<>수입",$I$62:$I$500,"<>저축") -> 0 | V10: =SUMIFS($K$62:$K$500,$H$62:$H$500,V9,$I$62:$I$500,"<>수입",$I$62:$I$500,"<>저축") -> 0 | W10: =SUMIFS($K$62:$K$500,$H$62:$H$500,W9,$I$62:$I$500,"<>수입",$I$62:$I$500,"<>저축") -> 0 | X10: =SUMIFS($K$62:$K$500,$H$62:$H$500,X9,$I$62:$I$500,"<>수입",$I$62:$I$500,"<>저축") -> 0 | Y10: =SUM(R10:X10) -> 0 | AB10: =$H$33 -> 🐻고정비 | AC10: =$K$39 -> 0 | AD10: =_xlfn.RANK.EQ(AC10,$AB$9:$AC$20,0) + ROW(AB2)/10000 -> 1.0002 | AE10: =SMALL($AD$9:$AD$20, ROW(AB2)) -> 1.0002 | AF10: =INDEX($AB$9:$AB$20,MATCH(AE10,$AD$9:$AD$20,0)) -> 🐻고정비 | AG10: =INDEX($AC$9:$AC$20,MATCH(AE10,$AD$9:$AD$20,0)) -> 0
C11: 항목 | D11: 금액 | R11: =R9 + 7 -> 45298 | S11: =S9 + 7 -> 45299 | T11: =T9 + 7 -> 45300 | U11: =U9 + 7 -> 45301 | V11: =V9 + 7 -> 45302 | W11: =W9 + 7 -> 45303 | X11: =X9 + 7 -> 45304 | AB11: =$H$41 -> 🍪생필품 | AC11: =$K$47 -> 0 | AD11: =_xlfn.RANK.EQ(AC11,$AB$9:$AC$20,0) + ROW(AB3)/10000 -> 1.0003 | AE11: =SMALL($AD$9:$AD$20, ROW(AB3)) -> 1.0003 | AF11: =INDEX($AB$9:$AB$20,MATCH(AE11,$AD$9:$AD$20,0)) -> 🍪생필품 | AG11: =INDEX($AC$9:$AC$20,MATCH(AE11,$AD$9:$AD$20,0)) -> 0
C12: 총수입 | D12: =F33 -> 0 | R12: =SUMIFS($K$62:$K$500,$H$62:$H$500,R11,$I$62:$I$500,"<>수입",$I$62:$I$500,"<>저축") -> 0 | S12: =SUMIFS($K$62:$K$500,$H$62:$H$500,S11,$I$62:$I$500,"<>수입",$I$62:$I$500,"<>저축") -> 0 | T12: =SUMIFS($K$62:$K$500,$H$62:$H$500,T11,$I$62:$I$500,"<>수입",$I$62:$I$500,"<>저축") -> 0 | U12: =SUMIFS($K$62:$K$500,$H$62:$H$500,U11,$I$62:$I$500,"<>수입",$I$62:$I$500,"<>저축") -> 0 | V12: =SUMIFS($K$62:$K$500,$H$62:$H$500,V11,$I$62:$I$500,"<>수입",$I$62:$I$500,"<>저축") -> 0 | W12: =SUMIFS($K$62:$K$500,$H$62:$H$500,W11,$I$62:$I$500,"<>수입",$I$62:$I$500,"<>저축") -> 0 | X12: =SUMIFS($K$62:$K$500,$H$62:$H$500,X11,$I$62:$I$500,"<>수입",$I$62:$I$500,"<>저축") -> 0 | Y12: =SUM(R12:X12) -> 0 | AB12: =$H$49 -> 🐻생필품 | AC12: =$K$55 -> 0 | AD12: =_xlfn.RANK.EQ(AC12,$AB$9:$AC$20,0) + ROW(AB4)/10000 -> 1.0004 | AE12: =SMALL($AD$9:$AD$20, ROW(AB4)) -> 1.0004 | AF12: =INDEX($AB$9:$AB$20,MATCH(AE12,$AD$9:$AD$20,0)) -> 🐻생필품 | AG12: =INDEX($AC$9:$AC$20,MATCH(AE12,$AD$9:$AD$20,0)) -> 0
E13: 결제수단 | F13: 금액 | R13: =R11+7 -> 45305 | S13: =S11+7 -> 45306 | T13: =T11+7 -> 45307 | U13: =U11+7 -> 45308 | V13: =V11+7 -> 45309 | W13: =W11+7 -> 45310 | X13: =X11+7 -> 45311 | AB13: =$M$25 -> 🍪식비 | AC13: =$P$31 -> 0 | AD13: =_xlfn.RANK.EQ(AC13,$AB$9:$AC$20,0) + ROW(AB5)/10000 -> 1.0005 | AE13: =SMALL($AD$9:$AD$20, ROW(AB5)) -> 1.0005 | AF13: =INDEX($AB$9:$AB$20,MATCH(AE13,$AD$9:$AD$20,0)) -> 🍪식비 | AG13: =INDEX($AC$9:$AC$20,MATCH(AE13,$AD$9:$AD$20,0)) -> 0
C14: 총지출 | D14: =SUM($K$31+$K$39+$K$47+$K$55+$P$31+$P$39+$P$47+$P$55+X31+X39+X47+X55) -> 0 | E14: 체크카드 | F14: =SUMIFS($K$62:$K$500,$L$62:$L$500,E14,$I$62:$I$500,"<>수입",$I$62:$I$500,"<>저축") -> 0 | R14: =SUMIFS($K$62:$K$500,$H$62:$H$500,R13,$I$62:$I$500,"<>수입",$I$62:$I$500,"<>저축") -> 0 | S14: =SUMIFS($K$62:$K$500,$H$62:$H$500,S13,$I$62:$I$500,"<>수입",$I$62:$I$500,"<>저축") -> 0 | T14: =SUMIFS($K$62:$K$500,$H$62:$H$500,T13,$I$62:$I$500,"<>수입",$I$62:$I$500,"<>저축") -> 0 | U14: =SUMIFS($K$62:$K$500,$H$62:$H$500,U13,$I$62:$I$500,"<>수입",$I$62:$I$500,"<>저축") -> 0 | V14: =SUMIFS($K$62:$K$500,$H$62:$H$500,V13,$I$62:$I$500,"<>수입",$I$62:$I$500,"<>저축") -> 0 | W14: =SUMIFS($K$62:$K$500,$H$62:$H$500,W13,$I$62:$I$500,"<>수입",$I$62:$I$500,"<>저축") -> 0 | X14: =SUMIFS($K$62:$K$500,$H$62:$H$500,X13,$I$62:$I$500,"<>수입",$I$62:$I$500,"<>저축") -> 0 | Y14: =SUM(R14:X14) -> 0 | AB14: =$M$33 -> 🐻식비 | AC14: =$P$39 -> 0 | AD14: =_xlfn.RANK.EQ(AC14,$AB$9:$AC$20,0) + ROW(AB6)/10000 -> 1.0006 | AE14: =SMALL($AD$9:$AD$20, ROW(AB6)) -> 1.0006 | AF14: =INDEX($AB$9:$AB$20,MATCH(AE14,$AD$9:$AD$20,0)) -> 🐻식비 | AG14: =INDEX($AC$9:$AC$20,MATCH(AE14,$AD$9:$AD$20,0)) -> 0
E15: 현금/이체 | F15: =SUMIFS($K$62:$K$500,$L$62:$L$500,E15,$I$62:$I$500,"<>수입",$I$62:$I$500,"<>저축") -> 0 | R15: =R13+7 -> 45312 | S15: =S13+7 -> 45313 | T15: =T13+7 -> 45314 | U15: =U13+7 -> 45315 | V15: =V13+7 -> 45316 | W15: =W13+7 -> 45317 | X15: =X13+7 -> 45318 | AB15: =$M$41 -> 🍪여가비 | AC15: =$P$47 -> 0 | AD15: =_xlfn.RANK.EQ(AC15,$AB$9:$AC$20,0) + ROW(AB7)/10000 -> 1.0007 | AE15: =SMALL($AD$9:$AD$20, ROW(AB7)) -> 1.0007 | AF15: =INDEX($AB$9:$AB$20,MATCH(AE15,$AD$9:$AD$20,0)) -> 🍪여가비 | AG15: =INDEX($AC$9:$AC$20,MATCH(AE15,$AD$9:$AD$20,0)) -> 0
C16: 총저축 | D16: =F43 -> 0 | E16: 현대카드 | F16: =SUMIFS($K$62:$K$500,$L$62:$L$500,E16,$I$62:$I$500,"<>수입",$I$62:$I$500,"<>저축") -> 0 | H16: 이벤트 | R16: =SUMIFS($K$62:$K$500,$H$62:$H$500,R15,$I$62:$I$500,"<>수입",$I$62:$I$500,"<>저축") -> 0 | S16: =SUMIFS($K$62:$K$500,$H$62:$H$500,S15,$I$62:$I$500,"<>수입",$I$62:$I$500,"<>저축") -> 0 | T16: =SUMIFS($K$62:$K$500,$H$62:$H$500,T15,$I$62:$I$500,"<>수입",$I$62:$I$500,"<>저축") -> 0 | U16: =SUMIFS($K$62:$K$500,$H$62:$H$500,U15,$I$62:$I$500,"<>수입",$I$62:$I$500,"<>저축") -> 0 | V16: =SUMIFS($K$62:$K$500,$H$62:$H$500,V15,$I$62:$I$500,"<>수입",$I$62:$I$500,"<>저축") -> 0 | W16: =SUMIFS($K$62:$K$500,$H$62:$H$500,W15,$I$62:$I$500,"<>수입",$I$62:$I$500,"<>저축") -> 0 | X16: =SUMIFS($K$62:$K$500,$H$62:$H$500,X15,$I$62:$I$500,"<>수입",$I$62:$I$500,"<>저축") -> 0 | Y16: =SUM(R16:X16) -> 0 | AB16: =$M$49 -> 🐻여가비 | AC16: =$P$55 -> 0 | AD16: =_xlfn.RANK.EQ(AC16,$AB$9:$AC$20,0) + ROW(AB8)/10000 -> 1.0008 | AE16: =SMALL($AD$9:$AD$20, ROW(AB8)) -> 1.0008 | AF16: =INDEX($AB$9:$AB$20,MATCH(AE16,$AD$9:$AD$20,0)) -> 🐻여가비 | AG16: =INDEX($AC$9:$AC$20,MATCH(AE16,$AD$9:$AD$20,0)) -> 0
E17: 국민카드 | F17: =SUMIFS($K$62:$K$500,$L$62:$L$500,E17,$I$62:$I$500,"<>수입",$I$62:$I$500,"<>저축") -> 0 | R17: =R15+7 -> 45319 | S17: =S15+7 -> 45320 | T17: =T15+7 -> 45321 | U17: =U15+7 -> 45322 | V17: =V15+7 -> 45323 | W17: =W15+7 -> 45324 | X17: =X15+7 -> 45325 | AB17: =$R$25 -> 🍪기타 | AC17: =$X$31 -> 0 | AD17: =_xlfn.RANK.EQ(AC17,$AB$9:$AC$20,0) + ROW(AB9)/10000 -> 1.0009 | AE17: =SMALL($AD$9:$AD$20, ROW(AB9)) -> 1.0009 | AF17: =INDEX($AB$9:$AB$20,MATCH(AE17,$AD$9:$AD$20,0)) -> 🍪기타 | AG17: =INDEX($AC$9:$AC$20,MATCH(AE17,$AD$9:$AD$20,0)) -> 0
C18: 잉여현금 | D18: =D12-D14-D16 -> 0 | E18: 현백카드 | F18: =SUMIFS($K$62:$K$500,$L$62:$L$500,E18,$I$62:$I$500,"<>수입",$I$62:$I$500,"<>저축") -> 0 | R18: =SUMIFS($K$62:$K$500,$H$62:$H$500,R17,$I$62:$I$500,"<>수입",$I$62:$I$500,"<>저축") -> 0 | S18: =SUMIFS($K$62:$K$500,$H$62:$H$500,S17,$I$62:$I$500,"<>수입",$I$62:$I$500,"<>저축") -> 0 | T18: =SUMIFS($K$62:$K$500,$H$62:$H$500,T17,$I$62:$I$500,"<>수입",$I$62:$I$500,"<>저축") -> 0 | U18: =SUMIFS($K$62:$K$500,$H$62:$H$500,U17,$I$62:$I$500,"<>수입",$I$62:$I$500,"<>저축") -> 0 | V18: =SUMIFS($K$62:$K$500,$H$62:$H$500,V17,$I$62:$I$500,"<>수입",$I$62:$I$500,"<>저축") -> 0 | W18: =SUMIFS($K$62:$K$500,$H$62:$H$500,W17,$I$62:$I$500,"<>수입",$I$62:$I$500,"<>저축") -> 0 | X18: =SUMIFS($K$62:$K$500,$H$62:$H$500,X17,$I$62:$I$500,"<>수입",$I$62:$I$500,"<>저축") -> 0 | Y18: =SUM(R18:X18) -> 0 | AB18: =$R$33 -> 🐻기타 | AC18: =$X$39 -> 0 | AD18: =_xlfn.RANK.EQ(AC18,$AB$9:$AC$20,0) + ROW(AB10)/10000 -> 1.001 | AE18: =SMALL($AD$9:$AD$20, ROW(AB10)) -> 1.001 | AF18: =INDEX($AB$9:$AB$20,MATCH(AE18,$AD$9:$AD$20,0)) -> 🐻기타 | AG18: =INDEX($AC$9:$AC$20,MATCH(AE18,$AD$9:$AD$20,0)) -> 0
C19: 총저축률 | D19: =(D16+D18)/D12 -> #DIV/0! | E19: 하나카드 | F19: =SUMIFS($K$62:$K$500,$L$62:$L$500,E19,$I$62:$I$500,"<>수입",$I$62:$I$500,"<>저축") -> 0 | R19: =R17+7 -> 45326 | S19: =S17+7 -> 45327 | T19: =T17+7 -> 45328 | U19: =U17+7 -> 45329 | V19: =V17+7 -> 45330 | W19: =W17+7 -> 45331 | X19: =X17+7 -> 45332 | AB19: =$R$41 -> 🍪이벤트성 | AC19: =$X$47 -> 0 | AD19: =_xlfn.RANK.EQ(AC19,$AB$9:$AC$20,0) + ROW(AB11)/10000 -> 1.0011 | AE19: =SMALL($AD$9:$AD$20, ROW(AB11)) -> 1.0011 | AF19: =INDEX($AB$9:$AB$20,MATCH(AE19,$AD$9:$AD$20,0)) -> 🍪이벤트성 | AG19: =INDEX($AC$9:$AC$20,MATCH(AE19,$AD$9:$AD$20,0)) -> 0
C20: 현금저축률 | D20: =D18/D12 -> #DIV/0! | E20: 총지출 | F20: =SUM($F$14:$F$19) -> 0 | R20: =SUMIFS($K$62:$K$500,$H$62:$H$500,R19,$I$62:$I$500,"<>수입",$I$62:$I$500,"<>저축") -> 0 | S20: =SUMIFS($K$62:$K$500,$H$62:$H$500,S19,$I$62:$I$500,"<>수입",$I$62:$I$500,"<>저축") -> 0 | T20: =SUMIFS($K$62:$K$500,$H$62:$H$500,T19,$I$62:$I$500,"<>수입",$I$62:$I$500,"<>저축") -> 0 | U20: =SUMIFS($K$62:$K$500,$H$62:$H$500,U19,$I$62:$I$500,"<>수입",$I$62:$I$500,"<>저축") -> 0 | V20: =SUMIFS($K$62:$K$500,$H$62:$H$500,V19,$I$62:$I$500,"<>수입",$I$62:$I$500,"<>저축") -> 0 | W20: =SUMIFS($K$62:$K$500,$H$62:$H$500,W19,$I$62:$I$500,"<>수입",$I$62:$I$500,"<>저축") -> 0 | X20: =SUMIFS($K$62:$K$500,$H$62:$H$500,X19,$I$62:$I$500,"<>수입",$I$62:$I$500,"<>저축") -> 0 | Y20: =SUM(R20:X20) -> 0 | AB20: =$R$49 -> 🐻 이벤트성 | AC20: =$X$55 -> 0 | AD20: =_xlfn.RANK.EQ(AC20,$AB$9:$AC$20,0) + ROW(AB12)/10000 -> 1.0012 | AE20: =SMALL($AD$9:$AD$20, ROW(AB12)) -> 1.0012 | AF20: =INDEX($AB$9:$AB$20,MATCH(AE20,$AD$9:$AD$20,0)) -> 🐻 이벤트성 | AG20: =INDEX($AC$9:$AC$20,MATCH(AE20,$AD$9:$AD$20,0)) -> 0
C24: 대분류 | D24: 소분류 | E24: 목표 | F24: 합계 | H24: 대분류 | I24: 소분류 | J24: 예산 | K24: 합계 | M24: 대분류 | N24: 소분류 | O24: 예산 | P24: 합계 | R24: 대분류 | T24: 소분류 | V24: 예산 | X24: 합계
C25: 수입 | D25: 🍪 월급 | F25: =SUMIFS($K$62:$K$500,$I$62:$I$500,$C$25,$J$62:$J$500,D25) -> 0 | H25: 🍪고정비 | I25: 관리비 | K25: =SUMIFS($K$62:$K$500,$I$62:$I$500,$H$25,$J$62:$J$500,I25) -> 0 | M25: 🍪식비 | N25: 식재료비 | P25: =SUMIFS($K$62:$K$500,$I$62:$I$500,$M$25,$J$62:$J$500,N25) -> 0 | R25: 🍪기타 | T25: 약국 | X25: =SUMIFS($K$62:$K$500,$I$62:$I$500,$R$25,$J$62:$J$500,T25) -> 0
D26: 🍪 부수입 | F26: =SUMIFS($K$62:$K$500,$I$62:$I$500,$C$25,$J$62:$J$500,D26) -> 0 | I26: 월세 | K26: =SUMIFS($K$62:$K$500,$I$62:$I$500,$H$25,$J$62:$J$500,I26) -> 0 | N26: 회사점심 | P26: =SUMIFS($K$62:$K$500,$I$62:$I$500,$M$25,$J$62:$J$500,N26) -> 0 | T26: 병원비 | X26: =SUMIFS($K$62:$K$500,$I$62:$I$500,$R$25,$J$62:$J$500,T26) -> 0
D27: 🐻 월급 | F27: =SUMIFS($K$62:$K$500,$I$62:$I$500,$C$25,$J$62:$J$500,D27) -> 0 | I27: 대출이자 | K27: =SUMIFS($K$62:$K$500,$I$62:$I$500,$H$25,$J$62:$J$500,I27) -> 0 | N27: 간식/카페 | P27: =SUMIFS($K$62:$K$500,$I$62:$I$500,$M$25,$J$62:$J$500,N27) -> 0 | T27: 영양제 | X27: =SUMIFS($K$62:$K$500,$I$62:$I$500,$R$25,$J$62:$J$500,T27) -> 0
D28: 🐻 부수입 | F28: =SUMIFS($K$62:$K$500,$I$62:$I$500,$C$25,$J$62:$J$500,D28) -> 0 | I28: 통신비 | K28: =SUMIFS($K$62:$K$500,$I$62:$I$500,$H$25,$J$62:$J$500,I28) -> 0 | N28: 외식/배달 | P28: =SUMIFS($K$62:$K$500,$I$62:$I$500,$M$25,$J$62:$J$500,N28) -> 0 | T28: 교통비 | X28: =SUMIFS($K$62:$K$500,$I$62:$I$500,$R$25,$J$62:$J$500,T28) -> 0
D29: 기타 | F29: =SUMIFS($K$62:$K$500,$I$62:$I$500,$C$25,$J$62:$J$500,D29) -> 0 | I29: 보험료 | K29: =SUMIFS($K$62:$K$500,$I$62:$I$500,$H$25,$J$62:$J$500,I29) -> 0 | N29: 기타 | P29: =SUMIFS($K$62:$K$500,$I$62:$I$500,$M$25,$J$62:$J$500,N29) -> 0 | T29: 주유비 | X29: =SUMIFS($K$62:$K$500,$I$62:$I$500,$R$25,$J$62:$J$500,T29) -> 0
F30: =SUMIFS($K$62:$K$500,$I$62:$I$500,$C$25,$J$62:$J$500,D30) -> 0 | I30: 곗돈 | K30: =SUMIFS($K$62:$K$500,$I$62:$I$500,$H$25,$J$62:$J$500,I30) -> 0 | P30: =SUMIFS($K$62:$K$500,$I$62:$I$500,$M$25,$J$62:$J$500,N30) -> 0 | T30: 기타 | X30: =SUMIFS($K$62:$K$500,$I$62:$I$500,$R$25,$J$62:$J$500,T30) -> 0
F31: =SUMIFS($K$62:$K$500,$I$62:$I$500,$C$25,$J$62:$J$500,D31) -> 0 | H31: =IF(H25=0,"","총"&H25) -> 총🍪고정비 | K31: =SUM(K25:K30) -> 0 | M31: =IF(M25=0,"","총"&M25) -> 총🍪식비 | P31: =SUM(P25:P30) -> 0 | R31: =IF(R25=0,"","총"&R25) -> 총🍪기타 | X31: =SUM(X25:X30) -> 0
F32: =SUMIFS($K$62:$K$500,$I$62:$I$500,$C$25,$J$62:$J$500,D32) -> 0 | K32: =K31-J25 -> 0 | P32: =P31-O25 -> 0 | X32: =X31-V25 -> 0
C33: =IF(C25=0,"","총"&C25) -> 총수입 | F33: =SUM(F25:F32) -> 0 | H33: 🐻고정비 | I33: 관리비 | K33: =SUMIFS($K$62:$K$500,$I$62:$I$500,$H$33,$J$62:$J$500,I33) -> 0 | M33: 🐻식비 | N33: 식재료비 | P33: =SUMIFS($K$62:$K$500,$I$62:$I$500,$M$33,$J$62:$J$500,N33) -> 0 | R33: 🐻기타 | T33: 약국 | X33: =SUMIFS($K$62:$K$500,$I$62:$I$500,$R$33,$J$62:$J$500,T33) -> 0
F34: =F33-E25 -> 0 | I34: 대출이자 | K34: =SUMIFS($K$62:$K$500,$I$62:$I$500,$H$33,$J$62:$J$500,I34) -> 0 | N34: 회사점심 | P34: =SUMIFS($K$62:$K$500,$I$62:$I$500,$M$33,$J$62:$J$500,N34) -> 0 | T34: 병원비 | X34: =SUMIFS($K$62:$K$500,$I$62:$I$500,$R$33,$J$62:$J$500,T34) -> 0
C35: 저축 | D35: 주택청약 | F35: =SUMIFS($K$62:$K$500,$I$62:$I$500,$C$35,$J$62:$J$500,D35) -> 0 | I35: 통신비 | K35: =SUMIFS($K$62:$K$500,$I$62:$I$500,$H$33,$J$62:$J$500,I35) -> 0 | N35: 간식/카페 | P35: =SUMIFS($K$62:$K$500,$I$62:$I$500,$M$33,$J$62:$J$500,N35) -> 0 | T35: 영양제 | X35: =SUMIFS($K$62:$K$500,$I$62:$I$500,$R$33,$J$62:$J$500,T35) -> 0
D36: 우리은행 | F36: =SUMIFS($K$62:$K$500,$I$62:$I$500,$C$35,$J$62:$J$500,D36) -> 0 | I36: 보험료 | K36: =SUMIFS($K$62:$K$500,$I$62:$I$500,$H$33,$J$62:$J$500,I36) -> 0 | N36: 외식/배달 | P36: =SUMIFS($K$62:$K$500,$I$62:$I$500,$M$33,$J$62:$J$500,N36) -> 0 | T36: 교통비 | X36: =SUMIFS($K$62:$K$500,$I$62:$I$500,$R$33,$J$62:$J$500,T36) -> 0
D37: 케이뱅크 | F37: =SUMIFS($K$62:$K$500,$I$62:$I$500,$C$35,$J$62:$J$500,D37) -> 0 | I37: 곗돈 | K37: =SUMIFS($K$62:$K$500,$I$62:$I$500,$H$33,$J$62:$J$500,I37) -> 0 | N37: 기타 | P37: =SUMIFS($K$62:$K$500,$I$62:$I$500,$M$33,$J$62:$J$500,N37) -> 0 | T37: 주유비 | X37: =SUMIFS($K$62:$K$500,$I$62:$I$500,$R$33,$J$62:$J$500,T37) -> 0
D38: 연금저축 | F38: =SUMIFS($K$62:$K$500,$I$62:$I$500,$C$35,$J$62:$J$500,D38) -> 0 | K38: =SUMIFS($K$62:$K$500,$I$62:$I$500,$H$33,$J$62:$J$500,I38) -> 0 | P38: =SUMIFS($K$62:$K$500,$I$62:$I$500,$M$33,$J$62:$J$500,N38) -> 0 | T38: 기타 | X38: =SUMIFS($K$62:$K$500,$I$62:$I$500,$R$33,$J$62:$J$500,T38) -> 0
F39: =SUMIFS($K$62:$K$500,$I$62:$I$500,$C$35,$J$62:$J$500,D39) -> 0 | H39: =IF(H33=0,"","총"&H33) -> 총🐻고정비 | K39: =SUM(K33:K38) -> 0 | M39: =IF(M33=0,"","총"&M33) -> 총🐻식비 | P39: =SUM(P33:P38) -> 0 | R39: =IF(R33=0,"","총"&R33) -> 총🐻기타 | X39: =SUM(X33:X38) -> 0
F40: =SUMIFS($K$62:$K$500,$I$62:$I$500,$C$35,$J$62:$J$500,D40) -> 0 | K40: =K39-J33 -> 0 | P40: =P39-O33 -> 0 | X40: =X39-V33 -> 0
F41: =SUMIFS($K$62:$K$500,$I$62:$I$500,$C$35,$J$62:$J$500,D41) -> 0 | H41: 🍪생필품 | I41: 주방/욕실 | K41: =SUMIFS($K$62:$K$500,$I$62:$I$500,$H$41,$J$62:$J$500,I41) -> 0 | M41: 🍪여가비 | N41: 의류/잡화 | P41: =SUMIFS($K$62:$K$500,$I$62:$I$500,$M$41,$J$62:$J$500,N41) -> 0 | R41: 🍪이벤트성 | T41: 축의/부의금 | X41: =SUMIFS($K$62:$K$500,$I$62:$I$500,$R$41,$J$62:$J$500,T41) -> 0
F42: =SUMIFS($K$62:$K$500,$I$62:$I$500,$C$35,$J$62:$J$500,D42) -> 0 | I42: 소모품 | K42: =SUMIFS($K$62:$K$500,$I$62:$I$500,$H$41,$J$62:$J$500,I42) -> 0 | N42: OTT | P42: =SUMIFS($K$62:$K$500,$I$62:$I$500,$M$41,$J$62:$J$500,N42) -> 0 | T42: 생신/생일선물 | X42: =SUMIFS($K$62:$K$500,$I$62:$I$500,$R$41,$J$62:$J$500,T42) -> 0
C43: =IF(C35=0,"","총"&C35) -> 총저축 | F43: =SUM(F35:F42) -> 0 | I43: 기타 | K43: =SUMIFS($K$62:$K$500,$I$62:$I$500,$H$41,$J$62:$J$500,I43) -> 0 | N43: 문화생활 | P43: =SUMIFS($K$62:$K$500,$I$62:$I$500,$M$41,$J$62:$J$500,N43) -> 0 | T43: 명절/어버이날 | X43: =SUMIFS($K$62:$K$500,$I$62:$I$500,$R$41,$J$62:$J$500,T43) -> 0
F44: =F43-E35 -> 0 | K44: =SUMIFS($K$62:$K$500,$I$62:$I$500,$H$41,$J$62:$J$500,I44) -> 0 | N44: 자기계발 | P44: =SUMIFS($K$62:$K$500,$I$62:$I$500,$M$41,$J$62:$J$500,N44) -> 0 | T44: 여행 | X44: =SUMIFS($K$62:$K$500,$I$62:$I$500,$R$41,$J$62:$J$500,T44) -> 0
K45: =SUMIFS($K$62:$K$500,$I$62:$I$500,$H$41,$J$62:$J$500,I45) -> 0 | N45: 미용 | P45: =SUMIFS($K$62:$K$500,$I$62:$I$500,$M$41,$J$62:$J$500,N45) -> 0 | T45: 기타 | X45: =SUMIFS($K$62:$K$500,$I$62:$I$500,$R$41,$J$62:$J$500,T45) -> 0
K46: =SUMIFS($K$62:$K$500,$I$62:$I$500,$H$41,$J$62:$J$500,I46) -> 0 | N46: 기타 | P46: =SUMIFS($K$62:$K$500,$I$62:$I$500,$M$41,$J$62:$J$500,N46) -> 0 | X46: =SUMIFS($K$62:$K$500,$I$62:$I$500,$R$41,$J$62:$J$500,T46) -> 0
H47: =IF(H41=0,"","총"&H41) -> 총🍪생필품 | K47: =SUM(K41:K46) -> 0 | M47: =IF(M41=0,"","총"&M41) -> 총🍪여가비 | P47: =SUM(P41:P46) -> 0 | R47: =IF(R41=0,"","총"&R41) -> 총🍪이벤트성 | X47: =SUM(X41:X46) -> 0
K48: =K47-J41 -> 0 | P48: =P47-O41 -> 0 | X48: =X47-V41 -> 0
H49: 🐻생필품 | I49: 주방/욕실 | K49: =SUMIFS($K$62:$K$500,$I$62:$I$500,$H$49,$J$62:$J$500,I49) -> 0 | M49: 🐻여가비 | N49: 의류/잡화 | P49: =SUMIFS($K$62:$K$500,$I$62:$I$500,$M$49,$J$62:$J$500,N49) -> 0 | R49: 🐻 이벤트성 | T49: 축의/부의금 | X49: =SUMIFS($K$62:$K$500,$I$62:$I$500,$R$49,$J$62:$J$500,T49) -> 0
...

Sheet 2월
C3: 2024 | D3: 2
R8: S | S8: M | T8: T | U8: W | V8: T | W8: F | X8: S | Y8: 누적 | AB8: 대분류 | AC8: 합계
R9: =DATE($C$3,$D$3,1)-WEEKDAY(DATE($C$3,$D$3,1))+1 -> 45319 | S9: =R9 + 1 -> 45320 | T9: =S9 + 1 -> 45321 | U9: =T9 + 1 -> 45322 | V9: =U9 + 1 -> 45323 | W9: =V9 + 1 -> 45324 | X9: =W9 + 1 -> 45325 | AB9: =$H$25 -> 🍪고정비 | AC9: =$K$31 -> 0 | AD9: =_xlfn.RANK.EQ(AC9,$AB$9:$AC$20,0) + ROW(AB1)/10000 -> 1.0001 | AE9: =SMALL($AD$9:$AD$20, ROW(AB1)) -> 1.0001 | AF9: =INDEX($AB$9:$AB$20,MATCH(AE9,$AD$9:$AD$20,0)) -> 🍪고정비 | AG9: =INDEX($AC$9:$AC$20,MATCH(AE9,$AD$9:$AD$20,0)) -> 0
R10: =SUMIFS($K$62:$K$500,$H$62:$H$500,R9,$I$62:$I$500,"<>수입",$I$62:$I$500,"<>저축") -> 0 | S10: =SUMIFS($K$62:$K$500,$H$62:$H$500,S9,$I$62:$I$500,"<>수입",$I$62:$I$500,"<>저축") -> 0 | T10: =SUMIFS($K$62:$K$500,$H$62:$H$500,T9,$I$62:$I$500,"<>수입",$I$62:$I$500,"<>저축") -> 0 | U10: =SUMIFS($K$62:$K$500,$H$62:$H$500,U9,$I$62:$I$500,"<>수입",$I$62:$I$500,"<>저축") -> 0 | V10: =SUMIFS($K$62:$K$500,$H$62:$H$500,V9,$I$62:$I$500,"<>수입",$I$62:$I$500,"<>저축") -> 0 | W10: =SUMIFS($K$62:$K$500,$H$62:$H$500,W9,$I$62:$I$500,"<>수입",$I$62:$I$500,"<>저축") -> 0 | X10: =SUMIFS($K$62:$K$500,$H$62:$H$500,X9,$I$62:$I$500,"<>수입",$I$62:$I$500,"<>저축") -> 0 | Y10: =SUM(R10:X10) -> 0 | AB10: =$H$33 -> 🐻고정비 | AC10: =$K$39 -> 0 | AD10: =_xlfn.RANK.EQ(AC10,$AB$9:$AC$20,0) + ROW(AB2)/10000 -> 1.0002 | AE10: =SMALL($AD$9:$AD$20, ROW(AB2)) -> 1.0002 | AF10: =INDEX($AB$9:$AB$20,MATCH(AE10,$AD$9:$AD$20,0)) -> 🐻고정비 | AG10: =INDEX($AC$9:$AC$20,MATCH(AE10,$AD$9:$AD$20,0)) -> 0
C11: 항목 | D11: 금액 | R11: =R9 + 7 -> 45326 | S11: =S9 + 7 -> 45327 | T11: =T9 + 7 -> 45328 | U11: =U9 + 7 -> 45329 | V11: =V9 + 7 -> 45330 | W11: =W9 + 7 -> 45331 | X11: =X9 + 7 -> 45332 | AB11: =$H$41 -> 🍪생필품 | AC11: =$K$47 -> 0 | AD11: =_xlfn.RANK.EQ(AC11,$AB$9:$AC$20,0) + ROW(AB3)/10000 -> 1.0003 | AE11: =SMALL($AD$9:$AD$20, ROW(AB3)) -> 1.0003 | AF11: =INDEX($AB$9:$AB$20,MATCH(AE11,$AD$9:$AD$20,0)) -> 🍪생필품 | AG11: =INDEX($AC$9:$AC$20,MATCH(AE11,$AD$9:$AD$20,0)) -> 0
C12: 총수입 | D12: =F33 -> 0 | R12: =SUMIFS($K$62:$K$500,$H$62:$H$500,R11,$I$62:$I$500,"<>수입",$I$62:$I$500,"<>저축") -> 0 | S12: =SUMIFS($K$62:$K$500,$H$62:$H$500,S11,$I$62:$I$500,"<>수입",$I$62:$I$500,"<>저축") -> 0 | T12: =SUMIFS($K$62:$K$500,$H$62:$H$500,T11,$I$62:$I$500,"<>수입",$I$62:$I$500,"<>저축") -> 0 | U12: =SUMIFS($K$62:$K$500,$H$62:$H$500,U11,$I$62:$I$500,"<>수입",$I$62:$I$500,"<>저축") -> 0 | V12: =SUMIFS($K$62:$K$500,$H$62:$H$500,V11,$I$62:$I$500,"<>수입",$I$62:$I$500,"<>저축") -> 0 | W12: =SUMIFS($K$62:$K$500,$H$62:$H$500,W11,$I$62:$I$500,"<>수입",$I$62:$I$500,"<>저축") -> 0 | X12: =SUMIFS($K$62:$K$500,$H$62:$H$500,X11,$I$62:$I$500,"<>수입",$I$62:$I$500,"<>저축") -> 0 | Y12: =SUM(R12:X12) -> 0 | AB12: =$H$49 -> 🐻생필품 | AC12: =$K$55 -> 0 | AD12: =_xlfn.RANK.EQ(AC12,$AB$9:$AC$20,0) + ROW(AB4)/10000 -> 1.0004 | AE12: =SMALL($AD$9:$AD$20, ROW(AB4)) -> 1.0004 | AF12: =INDEX($AB$9:$AB$20,MATCH(AE12,$AD$9:$AD$20,0)) -> 🐻생필품 | AG12: =INDEX($AC$9:$AC$20,MATCH(AE12,$AD$9:$AD$20,0)) -> 0
E13: 결제수단 | F13: 금액 | R13: =R11+7 -> 45333 | S13: =S11+7 -> 45334 | T13: =T11+7 -> 45335 | U13: =U11+7 -> 45336 | V13: =V11+7 -> 45337 | W13: =W11+7 -> 45338 | X13: =X11+7 -> 45339 | AB13: =$M$25 -> 🍪식비 | AC13: =$P$31 -> 0 | AD13: =_xlfn.RANK.EQ(AC13,$AB$9:$AC$20,0) + ROW(AB5)/10000 -> 1.0005 | AE13: =SMALL($AD$9:$AD$20, ROW(AB5)) -> 1.0005 | AF13: =INDEX($AB$9:$AB$20,MATCH(AE13,$AD$9:$AD$20,0)) -> 🍪식비 | AG13: =INDEX($AC$9:$AC$20,MATCH(AE13,$AD$9:$AD$20,0)) -> 0
C14: 총지출 | D14: =SUM($K$31+$K$39+$K$47+$K$55+$P$31+$P$39+$P$47+$P$55+X31+X39+X47+X55) -> 0 | E14: 체크카드 | F14: =SUMIFS($K$62:$K$500,$L$62:$L$500,E14,$I$62:$I$500,"<>수입",$I$62:$I$500,"<>저축") -> 0 | R14: =SUMIFS($K$62:$K$500,$H$62:$H$500,R13,$I$62:$I$500,"<>수입",$I$62:$I$500,"<>저축") -> 0 | S14: =SUMIFS($K$62:$K$500,$H$62:$H$500,S13,$I$62:$I$500,"<>수입",$I$62:$I$500,"<>저축") -> 0 | T14: =SUMIFS($K$62:$K$500,$H$62:$H$500,T13,$I$62:$I$500,"<>수입",$I$62:$I$500,"<>저축") -> 0 | U14: =SUMIFS($K$62:$K$500,$H$62:$H$500,U13,$I$62:$I$500,"<>수입",$I$62:$I$500,"<>저축") -> 0 | V14: =SUMIFS($K$62:$K$500,$H$62:$H$500,V13,$I$62:$I$500,"<>수입",$I$62:$I$500,"<>저축") -> 0 | W14: =SUMIFS($K$62:$K$500,$H$62:$H$500,W13,$I$62:$I$500,"<>수입",$I$62:$I$500,"<>저축") -> 0 | X14: =SUMIFS($K$62:$K$500,$H$62:$H$500,X13,$I$62:$I$500,"<>수입",$I$62:$I$500,"<>저축") -> 0 | Y14: =SUM(R14:X14) -> 0 | AB14: =$M$33 -> 🐻식비 | AC14: =$P$39 -> 0 | AD14: =_xlfn.RANK.EQ(AC14,$AB$9:$AC$20,0) + ROW(AB6)/10000 -> 1.0006 | AE14: =SMALL($AD$9:$AD$20, ROW(AB6)) -> 1.0006 | AF14: =INDEX($AB$9:$AB$20,MATCH(AE14,$AD$9:$AD$20,0)) -> 🐻식비 | AG14: =INDEX($AC$9:$AC$20,MATCH(AE14,$AD$9:$AD$20,0)) -> 0
E15: 현금/이체 | F15: =SUMIFS($K$62:$K$500,$L$62:$L$500,E15,$I$62:$I$500,"<>수입",$I$62:$I$500,"<>저축") -> 0 | R15: =R13+7 -> 45340 | S15: =S13+7 -> 45341 | T15: =T13+7 -> 45342 | U15: =U13+7 -> 45343 | V15: =V13+7 -> 45344 | W15: =W13+7 -> 45345 | X15: =X13+7 -> 45346 | AB15: =$M$41 -> 🍪여가비 | AC15: =$P$47 -> 0 | AD15: =_xlfn.RANK.EQ(AC15,$AB$9:$AC$20,0) + ROW(AB7)/10000 -> 1.0007 | AE15: =SMALL($AD$9:$AD$20, ROW(AB7)) -> 1.0007 | AF15: =INDEX($AB$9:$AB$20,MATCH(AE15,$AD$9:$AD$20,0)) -> 🍪여가비 | AG15: =INDEX($AC$9:$AC$20,MATCH(AE15,$AD$9:$AD$20,0)) -> 0
C16: 총저축 | D16: =F43 -> 0 | E16: 현대카드 | F16: =SUMIFS($K$62:$K$500,$L$62:$L$500,E16,$I$62:$I$500,"<>수입",$I$62:$I$500,"<>저축") -> 0 | H16: 이벤트 | R16: =SUMIFS($K$62:$K$500,$H$62:$H$500,R15,$I$62:$I$500,"<>수입",$I$62:$I$500,"<>저축") -> 0 | S16: =SUMIFS($K$62:$K$500,$H$62:$H$500,S15,$I$62:$I$500,"<>수입",$I$62:$I$500,"<>저축") -> 0 | T16: =SUMIFS($K$62:$K$500,$H$62:$H$500,T15,$I$62:$I$500,"<>수입",$I$62:$I$500,"<>저축") -> 0 | U16: =SUMIFS($K$62:$K$500,$H$62:$H$500,U15,$I$62:$I$500,"<>수입",$I$62:$I$500,"<>저축") -> 0 | V16: =SUMIFS($K$62:$K$500,$H$62:$H$500,V15,$I$62:$I$500,"<>수입",$I$62:$I$500,"<>저축") -> 0 | W16: =SUMIFS($K$62:$K$500,$H$62:$H$500,W15,$I$62:$I$500,"<>수입",$I$62:$I$500,"<>저축") -> 0 | X16: =SUMIFS($K$62:$K$500,$H$62:$H$500,X15,$I$62:$I$500,"<>수입",$I$62:$I$500,"<>저축") -> 0 | Y16: =SUM(R16:X16) -> 0 | AB16: =$M$49 -> 🐻여가비 | AC16: =$P$55 -> 0 | AD16: =_xlfn.RANK.EQ(AC16,$AB$9:$AC$20,0) + ROW(AB8)/10000 -> 1.0008 | AE16: =SMALL($AD$9:$AD$20, ROW(AB8)) -> 1.0008 | AF16: =INDEX($AB$9:$AB$20,MATCH(AE16,$AD$9:$AD$20,0)) -> 🐻여가비 | AG16: =INDEX($AC$9:$AC$20,MATCH(AE16,$AD$9:$AD$20,0)) -> 0
E17: 국민카드 | F17: =SUMIFS($K$62:$K$500,$L$62:$L$500,E17,$I$62:$I$500,"<>수입",$I$62:$I$500,"<>저축") -> 0 | R17: =R15+7 -> 45347 | S17: =S15+7 -> 45348 | T17: =T15+7 -> 45349 | U17: =U15+7 -> 45350 | V17: =V15+7 -> 45351 | W17: =W15+7 -> 45352 | X17: =X15+7 -> 45353 | AB17: =$R$25 -> 🍪기타 | AC17: =$X$31 -> 0 | AD17: =_xlfn.RANK.EQ(AC17,$AB$9:$AC$20,0) + ROW(AB9)/10000 -> 1.0009 | AE17: =SMALL($AD$9:$AD$20, ROW(AB9)) -> 1.0009 | AF17: =INDEX($AB$9:$AB$20,MATCH(AE17,$AD$9:$AD$20,0)) -> 🍪기타 | AG17: =INDEX($AC$9:$AC$20,MATCH(AE17,$AD$9:$AD$20,0)) -> 0
C18: 잉여현금 | D18: =D12-D14-D16 -> 0 | E18: 현백카드 | F18: =SUMIFS($K$62:$K$500,$L$62:$L$500,E18,$I$62:$I$500,"<>수입",$I$62:$I$500,"<>저축") -> 0 | R18: =SUMIFS($K$62:$K$500,$H$62:$H$500,R17,$I$62:$I$500,"<>수입",$I$62:$I$500,"<>저축") -> 0 | S18: =SUMIFS($K$62:$K$500,$H$62:$H$500,S17,$I$62:$I$500,"<>수입",$I$62:$I$500,"<>저축") -> 0 | T18: =SUMIFS($K$62:$K$500,$H$62:$H$500,T17,$I$62:$I$500,"<>수입",$I$62:$I$500,"<>저축") -> 0 | U18: =SUMIFS($K$62:$K$500,$H$62:$H$500,U17,$I$62:$I$500,"<>수입",$I$62:$I$500,"<>저축") -> 0 | V18: =SUMIFS($K$62:$K$500,$H$62:$H$500,V17,$I$62:$I$500,"<>수입",$I$62:$I$500,"<>저축") -> 0 | W18: =SUMIFS($K$62:$K$500,$H$62:$H$500,W17,$I$62:$I$500,"<>수입",$I$62:$I$500,"<>저축") -> 0 | X18: =SUMIFS($K$62:$K$500,$H$62:$H$500,X17,$I$62:$I$500,"<>수입",$I$62:$I$500,"<>저축") -> 0 | Y18: =SUM(R18:X18) -> 0 | AB18: =$R$33 -> 🐻기타 | AC18: =$X$39 -> 0 | AD18: =_xlfn.RANK.EQ(AC18,$AB$9:$AC$20,0) + ROW(AB10)/10000 -> 1.001 | AE18: =SMALL($AD$9:$AD$20, ROW(AB10)) -> 1.001 | AF18: =INDEX($AB$9:$AB$20,MATCH(AE18,$AD$9:$AD$20,0)) -> 🐻기타 | AG18: =INDEX($AC$9:$AC$20,MATCH(AE18,$AD$9:$AD$20,0)) -> 0
C19: 총저축률 | D19: =(D16+D18)/D12 -> #DIV/0! | E19: 하나카드 | F19: =SUMIFS($K$62:$K$500,$L$62:$L$500,E19,$I$62:$I$500,"<>수입",$I$62:$I$500,"<>저축") -> 0 | R19: =R17+7 -> 45354 | S19: =S17+7 -> 45355 | T19: =T17+7 -> 45356 | U19: =U17+7 -> 45357 | V19: =V17+7 -> 45358 | W19: =W17+7 -> 45359 | X19: =X17+7 -> 45360 | AB19: =$R$41 -> 🍪이벤트성 | AC19: =$X$47 -> 0 | AD19: =_xlfn.RANK.EQ(AC19,$AB$9:$AC$20,0) + ROW(AB11)/10000 -> 1.0011 | AE19: =SMALL($AD$9:$AD$20, ROW(AB11)) -> 1.0011 | AF19: =INDEX($AB$9:$AB$20,MATCH(AE19,$AD$9:$AD$20,0)) -> 🍪이벤트성 | AG19: =INDEX($AC$9:$AC$20,MATCH(AE19,$AD$9:$AD$20,0)) -> 0
C20: 현금저축률 | D20: =D18/D12 -> #DIV/0! | E20: 총지출 | F20: =SUM($F$14:$F$19) -> 0 | R20: =SUMIFS($K$62:$K$500,$H$62:$H$500,R19,$I$62:$I$500,"<>수입",$I$62:$I$500,"<>저축") -> 0 | S20: =SUMIFS($K$62:$K$500,$H$62:$H$500,S19,$I$62:$I$500,"<>수입",$I$62:$I$500,"<>저축") -> 0 | T20: =SUMIFS($K$62:$K$500,$H$62:$H$500,T19,$I$62:$I$500,"<>수입",$I$62:$I$500,"<>저축") -> 0 | U20: =SUMIFS($K$62:$K$500,$H$62:$H$500,U19,$I$62:$I$500,"<>수입",$I$62:$I$500,"<>저축") -> 0 | V20: =SUMIFS($K$62:$K$500,$H$62:$H$500,V19,$I$62:$I$500,"<>수입",$I$62:$I$500,"<>저축") -> 0 | W20: =SUMIFS($K$62:$K$500,$H$62:$H$500,W19,$I$62:$I$500,"<>수입",$I$62:$I$500,"<>저축") -> 0 | X20: =SUMIFS($K$62:$K$500,$H$62:$H$500,X19,$I$62:$I$500,"<>수입",$I$62:$I$500,"<>저축") -> 0 | Y20: =SUM(R20:X20) -> 0 | AB20: =$R$49 -> 🐻 이벤트성 | AC20: =$X$55 -> 0 | AD20: =_xlfn.RANK.EQ(AC20,$AB$9:$AC$20,0) + ROW(AB12)/10000 -> 1.0012 | AE20: =SMALL($AD$9:$AD$20, ROW(AB12)) -> 1.0012 | AF20: =INDEX($AB$9:$AB$20,MATCH(AE20,$AD$9:$AD$20,0)) -> 🐻 이벤트성 | AG20: =INDEX($AC$9:$AC$20,MATCH(AE20,$AD$9:$AD$20,0)) -> 0
C24: 대분류 | D24: 소분류 | E24: 목표 | F24: 합계 | H24: 대분류 | I24: 소분류 | J24: 예산 | K24: 합계 | M24: 대분류 | N24: 소분류 | O24: 예산 | P24: 합계 | R24: 대분류 | T24: 소분류 | V24: 예산 | X24: 합계
C25: 수입 | D25: 🍪 월급 | F25: =SUMIFS($K$62:$K$500,$I$62:$I$500,$C$25,$J$62:$J$500,D25) -> 0 | H25: 🍪고정비 | I25: 관리비 | K25: =SUMIFS($K$62:$K$500,$I$62:$I$500,$H$25,$J$62:$J$500,I25) -> 0 | M25: 🍪식비 | N25: 식재료비 | P25: =SUMIFS($K$62:$K$500,$I$62:$I$500,$M$25,$J$62:$J$500,N25) -> 0 | R25: 🍪기타 | T25: 약국 | X25: =SUMIFS($K$62:$K$500,$I$62:$I$500,$R$25,$J$62:$J$500,T25) -> 0
D26: 🍪 부수입 | F26: =SUMIFS($K$62:$K$500,$I$62:$I$500,$C$25,$J$62:$J$500,D26) -> 0 | I26: 월세 | K26: =SUMIFS($K$62:$K$500,$I$62:$I$500,$H$25,$J$62:$J$500,I26) -> 0 | N26: 회사점심 | P26: =SUMIFS($K$62:$K$500,$I$62:$I$500,$M$25,$J$62:$J$500,N26) -> 0 | T26: 병원비 | X26: =SUMIFS($K$62:$K$500,$I$62:$I$500,$R$25,$J$62:$J$500,T26) -> 0
D27: 🐻 월급 | F27: =SUMIFS($K$62:$K$500,$I$62:$I$500,$C$25,$J$62:$J$500,D27) -> 0 | I27: 대출이자 | K27: =SUMIFS($K$62:$K$500,$I$62:$I$500,$H$25,$J$62:$J$500,I27) -> 0 | N27: 간식/카페 | P27: =SUMIFS($K$62:$K$500,$I$62:$I$500,$M$25,$J$62:$J$500,N27) -> 0 | T27: 영양제 | X27: =SUMIFS($K$62:$K$500,$I$62:$I$500,$R$25,$J$62:$J$500,T27) -> 0
D28: 🐻 부수입 | F28: =SUMIFS($K$62:$K$500,$I$62:$I$500,$C$25,$J$62:$J$500,D28) -> 0 | I28: 통신비 | K28: =SUMIFS($K$62:$K$500,$I$62:$I$500,$H$25,$J$62:$J$500,I28) -> 0 | N28: 외식/배달 | P28: =SUMIFS($K$62:$K$500,$I$62:$I$500,$M$25,$J$62:$J$500,N28) -> 0 | T28: 교통비 | X28: =SUMIFS($K$62:$K$500,$I$62:$I$500,$R$25,$J$62:$J$500,T28) -> 0
D29: 기타 | F29: =SUMIFS($K$62:$K$500,$I$62:$I$500,$C$25,$J$62:$J$500,D29) -> 0 | I29: 보험료 | K29: =SUMIFS($K$62:$K$500,$I$62:$I$500,$H$25,$J$62:$J$500,I29) -> 0 | N29: 기타 | P29: =SUMIFS($K$62:$K$500,$I$62:$I$500,$M$25,$J$62:$J$500,N29) -> 0 | T29: 주유비 | X29: =SUMIFS($K$62:$K$500,$I$62:$I$500,$R$25,$J$62:$J$500,T29) -> 0
F30: =SUMIFS($K$62:$K$500,$I$62:$I$500,$C$25,$J$62:$J$500,D30) -> 0 | I30: 곗돈 | K30: =SUMIFS($K$62:$K$500,$I$62:$I$500,$H$25,$J$62:$J$500,I30) -> 0 | P30: =SUMIFS($K$62:$K$500,$I$62:$I$500,$M$25,$J$62:$J$500,N30) -> 0 | T30: 기타 | X30: =SUMIFS($K$62:$K$500,$I$62:$I$500,$R$25,$J$62:$J$500,T30) -> 0
F31: =SUMIFS($K$62:$K$500,$I$62:$I$500,$C$25,$J$62:$J$500,D31) -> 0 | H31: =IF(H25=0,"","총"&H25) -> 총🍪고정비 | K31: =SUM(K25:K30) -> 0 | M31: =IF(M25=0,"","총"&M25) -> 총🍪식비 | P31: =SUM(P25:P30) -> 0 | R31: =IF(R25=0,"","총"&R25) -> 총🍪기타 | X31: =SUM(X25:X30) -> 0
F32: =SUMIFS($K$62:$K$500,$I$62:$I$500,$C$25,$J$62:$J$500,D32) -> 0 | K32: =K31-J25 -> 0 | P32: =P31-O25 -> 0 | X32: =X31-V25 -> 0
C33: =IF(C25=0,"","총"&C25) -> 총수입 | F33: =SUM(F25:F32) -> 0 | H33: 🐻고정비 | I33: 관리비 | K33: =SUMIFS($K$62:$K$500,$I$62:$I$500,$H$33,$J$62:$J$500,I33) -> 0 | M33: 🐻식비 | N33: 식재료비 | P33: =SUMIFS($K$62:$K$500,$I$62:$I$500,$M$33,$J$62:$J$500,N33) -> 0 | R33: 🐻기타 | T33: 약국 | X33: =SUMIFS($K$62:$K$500,$I$62:$I$500,$R$33,$J$62:$J$500,T33) -> 0
F34: =F33-E25 -> 0 | I34: 대출이자 | K34: =SUMIFS($K$62:$K$500,$I$62:$I$500,$H$33,$J$62:$J$500,I34) -> 0 | N34: 회사점심 | P34: =SUMIFS($K$62:$K$500,$I$62:$I$500,$M$33,$J$62:$J$500,N34) -> 0 | T34: 병원비 | X34: =SUMIFS($K$62:$K$500,$I$62:$I$500,$R$33,$J$62:$J$500,T34) -> 0
C35: 저축 | D35: 주택청약 | F35: =SUMIFS($K$62:$K$500,$I$62:$I$500,$C$35,$J$62:$J$500,D35) -> 0 | I35: 통신비 | K35: =SUMIFS($K$62:$K$500,$I$62:$I$500,$H$33,$J$62:$J$500,I35) -> 0 | N35: 간식/카페 | P35: =SUMIFS($K$62:$K$500,$I$62:$I$500,$M$33,$J$62:$J$500,N35) -> 0 | T35: 영양제 | X35: =SUMIFS($K$62:$K$500,$I$62:$I$500,$R$33,$J$62:$J$500,T35) -> 0
D36: 우리은행 | F36: =SUMIFS($K$62:$K$500,$I$62:$I$500,$C$35,$J$62:$J$500,D36) -> 0 | I36: 보험료 | K36: =SUMIFS($K$62:$K$500,$I$62:$I$500,$H$33,$J$62:$J$500,I36) -> 0 | N36: 외식/배달 | P36: =SUMIFS($K$62:$K$500,$I$62:$I$500,$M$33,$J$62:$J$500,N36) -> 0 | T36: 교통비 | X36: =SUMIFS($K$62:$K$500,$I$62:$I$500,$R$33,$J$62:$J$500,T36) -> 0
D37: 케이뱅크 | F37: =SUMIFS($K$62:$K$500,$I$62:$I$500,$C$35,$J$62:$J$500,D37) -> 0 | I37: 곗돈 | K37: =SUMIFS($K$62:$K$500,$I$62:$I$500,$H$33,$J$62:$J$500,I37) -> 0 | N37: 기타 | P37: =SUMIFS($K$62:$K$500,$I$62:$I$500,$M$33,$J$62:$J$500,N37) -> 0 | T37: 주유비 | X37: =SUMIFS($K$62:$K$500,$I$62:$I$500,$R$33,$J$62:$J$500,T37) -> 0
D38: 연금저축 | F38: =SUMIFS($K$62:$K$500,$I$62:$I$500,$C$35,$J$62:$J$500,D38) -> 0 | K38: =SUMIFS($K$62:$K$500,$I$62:$I$500,$H$33,$J$62:$J$500,I38) -> 0 | P38: =SUMIFS($K$62:$K$500,$I$62:$I$500,$M$33,$J$62:$J$500,N38) -> 0 | T38: 기타 | X38: =SUMIFS($K$62:$K$500,$I$62:$I$500,$R$33,$J$62:$J$500,T38) -> 0
F39: =SUMIFS($K$62:$K$500,$I$62:$I$500,$C$35,$J$62:$J$500,D39) -> 0 | H39: =IF(H33=0,"","총"&H33) -> 총🐻고정비 | K39: =SUM(K33:K38) -> 0 | M39: =IF(M33=0,"","총"&M33) -> 총🐻식비 | P39: =SUM(P33:P38) -> 0 | R39: =IF(R33=0,"","총"&R33) -> 총🐻기타 | X39: =SUM(X33:X38) -> 0
F40: =SUMIFS($K$62:$K$500,$I$62:$I$500,$C$35,$J$62:$J$500,D40) -> 0 | K40: =K39-J33 -> 0 | P40: =P39-O33 -> 0 | X40: =X39-V33 -> 0
F41: =SUMIFS($K$62:$K$500,$I$62:$I$500,$C$35,$J$62:$J$500,D41) -> 0 | H41: 🍪생필품 | I41: 주방/욕실 | K41: =SUMIFS($K$62:$K$500,$I$62:$I$500,$H$41,$J$62:$J$500,I41) -> 0 | M41: 🍪여가비 | N41: 의류/잡화 | P41: =SUMIFS($K$62:$K$500,$I$62:$I$500,$M$41,$J$62:$J$500,N41) -> 0 | R41: 🍪이벤트성 | T41: 축의/부의금 | X41: =SUMIFS($K$62:$K$500,$I$62:$I$500,$R$41,$J$62:$J$500,T41) -> 0
F42: =SUMIFS($K$62:$K$500,$I$62:$I$500,$C$35,$J$62:$J$500,D42) -> 0 | I42: 소모품 | K42: =SUMIFS($K$62:$K$500,$I$62:$I$500,$H$41,$J$62:$J$500,I42) -> 0 | N42: OTT | P42: =SUMIFS($K$62:$K$500,$I$62:$I$500,$M$41,$J$62:$J$500,N42) -> 0 | T42: 생신/생일선물 | X42: =SUMIFS($K$62:$K$500,$I$62:$I$500,$R$41,$J$62:$J$500,T42) -> 0
C43: =IF(C35=0,"","총"&C35) -> 총저축 | F43: =SUM(F35:F42) -> 0 | I43: 기타 | K43: =SUMIFS($K$62:$K$500,$I$62:$I$500,$H$41,$J$62:$J$500,I43) -> 0 | N43: 문화생활 | P43: =SUMIFS($K$62:$K$500,$I$62:$I$500,$M$41,$J$62:$J$500,N43) -> 0 | T43: 명절/어버이날 | X43: =SUMIFS($K$62:$K$500,$I$62:$I$500,$R$41,$J$62:$J$500,T43) -> 0
F44: =F43-E35 -> 0 | K44: =SUMIFS($K$62:$K$500,$I$62:$I$500,$H$41,$J$62:$J$500,I44) -> 0 | N44: 자기계발 | P44: =SUMIFS($K$62:$K$500,$I$62:$I$500,$M$41,$J$62:$J$500,N44) -> 0 | T44: 여행 | X44: =SUMIFS($K$62:$K$500,$I$62:$I$500,$R$41,$J$62:$J$500,T44) -> 0
K45: =SUMIFS($K$62:$K$500,$I$62:$I$500,$H$41,$J$62:$J$500,I45) -> 0 | N45: 미용 | P45: =SUMIFS($K$62:$K$500,$I$62:$I$500,$M$41,$J$62:$J$500,N45) -> 0 | T45: 기타 | X45: =SUMIFS($K$62:$K$500,$I$62:$I$500,$R$41,$J$62:$J$500,T45) -> 0
K46: =SUMIFS($K$62:$K$500,$I$62:$I$500,$H$41,$J$62:$J$500,I46) -> 0 | N46: 기타 | P46: =SUMIFS($K$62:$K$500,$I$62:$I$500,$M$41,$J$62:$J$500,N46) -> 0 | X46: =SUMIFS($K$62:$K$500,$I$62:$I$500,$R$41,$J$62:$J$500,T46) -> 0
H47: =IF(H41=0,"","총"&H41) -> 총🍪생필품 | K47: =SUM(K41:K46) -> 0 | M47: =IF(M41=0,"","총"&M41) -> 총🍪여가비 | P47: =SUM(P41:P46) -> 0 | R47: =IF(R41=0,"","총"&R41) -> 총🍪이벤트성 | X47: =SUM(X41:X46) -> 0
K48: =K47-J41 -> 0 | P48: =P47-O41 -> 0 | X48: =X47-V41 -> 0
H49: 🐻생필품 | I49: 주방/욕실 | K49: =SUMIFS($K$62:$K$500,$I$62:$I$500,$H$49,$J$62:$J$500,I49) -> 0 | M49: 🐻여가비 | N49: 의류/잡화 | P49: =SUMIFS($K$62:$K$500,$I$62:$I$500,$M$49,$J$62:$J$500,N49) -> 0 | R49: 🐻 이벤트성 | T49: 축의/부의금 | X49: =SUMIFS($K$62:$K$500,$I$62:$I$500,$R$49,$J$62:$J$500,T49) -> 0
...

Sheet 3월
C3: 2024 | D3: 3
R8: S | S8: M | T8: T | U8: W | V8: T | W8: F | X8: S | Y8: 누적 | AB8: 대분류 | AC8: 합계
R9: =DATE($C$3,$D$3,1)-WEEKDAY(DATE($C$3,$D$3,1))+1 -> 45347 | S9: =R9 + 1 -> 45348 | T9: =S9 + 1 -> 45349 | U9: =T9 + 1 -> 45350 | V9: =U9 + 1 -> 45351 | W9: =V9 + 1 -> 45352 | X9: =W9 + 1 -> 45353 | AB9: =$H$25 -> 🍪고정비 | AC9: =$K$31 -> 0 | AD9: =_xlfn.RANK.EQ(AC9,$AB$9:$AC$20,0) + ROW(AB1)/10000 -> 1.0001 | AE9: =SMALL($AD$9:$AD$20, ROW(AB1)) -> 1.0001 | AF9: =INDEX($AB$9:$AB$20,MATCH(AE9,$AD$9:$AD$20,0)) -> 🍪고정비 | AG9: =INDEX($AC$9:$AC$20,MATCH(AE9,$AD$9:$AD$20,0)) -> 0
R10: =SUMIFS($K$62:$K$500,$H$62:$H$500,R9,$I$62:$I$500,"<>수입",$I$62:$I$500,"<>저축") -> 0 | S10: =SUMIFS($K$62:$K$500,$H$62:$H$500,S9,$I$62:$I$500,"<>수입",$I$62:$I$500,"<>저축") -> 0 | T10: =SUMIFS($K$62:$K$500,$H$62:$H$500,T9,$I$62:$I$500,"<>수입",$I$62:$I$500,"<>저축") -> 0 | U10: =SUMIFS($K$62:$K$500,$H$62:$H$500,U9,$I$62:$I$500,"<>수입",$I$62:$I$500,"<>저축") -> 0 | V10: =SUMIFS($K$62:$K$500,$H$62:$H$500,V9,$I$62:$I$500,"<>수입",$I$62:$I$500,"<>저축") -> 0 | W10: =SUMIFS($K$62:$K$500,$H$62:$H$500,W9,$I$62:$I$500,"<>수입",$I$62:$I$500,"<>저축") -> 0 | X10: =SUMIFS($K$62:$K$500,$H$62:$H$500,X9,$I$62:$I$500,"<>수입",$I$62:$I$500,"<>저축") -> 0 | Y10: =SUM(R10:X10) -> 0 | AB10: =$H$33 -> 🐻고정비 | AC10: =$K$39 -> 0 | AD10: =_xlfn.RANK.EQ(AC10,$AB$9:$AC$20,0) + ROW(AB2)/10000 -> 1.0002 | AE10: =SMALL($AD$9:$AD$20, ROW(AB2)) -> 1.0002 | AF10: =INDEX($AB$9:$AB$20,MATCH(AE10,$AD$9:$AD$20,0)) -> 🐻고정비 | AG10: =INDEX($AC$9:$AC$20,MATCH(AE10,$AD$9:$AD$20,0)) -> 0
C11: 항목 | D11: 금액 | R11: =R9 + 7 -> 45354 | S11: =S9 + 7 -> 45355 | T11: =T9 + 7 -> 45356 | U11: =U9 + 7 -> 45357 | V11: =V9 + 7 -> 45358 | W11: =W9 + 7 -> 45359 | X11: =X9 + 7 -> 45360 | AB11: =$H$41 -> 🍪생필품 | AC11: =$K$47 -> 0 | AD11: =_xlfn.RANK.EQ(AC11,$AB$9:$AC$20,0) + ROW(AB3)/10000 -> 1.0003 | AE11: =SMALL($AD$9:$AD$20, ROW(AB3)) -> 1.0003 | AF11: =INDEX($AB$9:$AB$20,MATCH(AE11,$AD$9:$AD$20,0)) -> 🍪생필품 | AG11: =INDEX($AC$9:$AC$20,MATCH(AE11,$AD$9:$AD$20,0)) -> 0
C12: 총수입 | D12: =F33 -> 0 | R12: =SUMIFS($K$62:$K$500,$H$62:$H$500,R11,$I$62:$I$500,"<>수입",$I$62:$I$500,"<>저축") -> 0 | S12: =SUMIFS($K$62:$K$500,$H$62:$H$500,S11,$I$62:$I$500,"<>수입",$I$62:$I$500,"<>저축") -> 0 | T12: =SUMIFS($K$62:$K$500,$H$62:$H$500,T11,$I$62:$I$500,"<>수입",$I$62:$I$500,"<>저축") -> 0 | U12: =SUMIFS($K$62:$K$500,$H$62:$H$500,U11,$I$62:$I$500,"<>수입",$I$62:$I$500,"<>저축") -> 0 | V12: =SUMIFS($K$62:$K$500,$H$62:$H$500,V11,$I$62:$I$500,"<>수입",$I$62:$I$500,"<>저축") -> 0 | W12: =SUMIFS($K$62:$K$500,$H$62:$H$500,W11,$I$62:$I$500,"<>수입",$I$62:$I$500,"<>저축") -> 0 | X12: =SUMIFS($K$62:$K$500,$H$62:$H$500,X11,$I$62:$I$500,"<>수입",$I$62:$I$500,"<>저축") -> 0 | Y12: =SUM(R12:X12) -> 0 | AB12: =$H$49 -> 🐻생필품 | AC12: =$K$55 -> 0 | AD12: =_xlfn.RANK.EQ(AC12,$AB$9:$AC$20,0) + ROW(AB4)/10000 -> 1.0004 | AE12: =SMALL($AD$9:$AD$20, ROW(AB4)) -> 1.0004 | AF12: =INDEX($AB$9:$AB$20,MATCH(AE12,$AD$9:$AD$20,0)) -> 🐻생필품 | AG12: =INDEX($AC$9:$AC$20,MATCH(AE12,$AD$9:$AD$20,0)) -> 0
E13: 결제수단 | F13: 금액 | R13: =R11+7 -> 45361 | S13: =S11+7 -> 45362 | T13: =T11+7 -> 45363 | U13: =U11+7 -> 45364 | V13: =V11+7 -> 45365 | W13: =W11+7 -> 45366 | X13: =X11+7 -> 45367 | AB13: =$M$25 -> 🍪식비 | AC13: =$P$31 -> 0 | AD13: =_xlfn.RANK.EQ(AC13,$AB$9:$AC$20,0) + ROW(AB5)/10000 -> 1.0005 | AE13: =SMALL($AD$9:$AD$20, ROW(AB5)) -> 1.0005 | AF13: =INDEX($AB$9:$AB$20,MATCH(AE13,$AD$9:$AD$20,0)) -> 🍪식비 | AG13: =INDEX($AC$9:$AC$20,MATCH(AE13,$AD$9:$AD$20,0)) -> 0
C14: 총지출 | D14: =SUM($K$31+$K$39+$K$47+$K$55+$P$31+$P$39+$P$47+$P$55+X31+X39+X47+X55) -> 0 | E14: 체크카드 | F14: =SUMIFS($K$62:$K$500,$L$62:$L$500,E14,$I$62:$I$500,"<>수입",$I$62:$I$500,"<>저축") -> 0 | R14: =SUMIFS($K$62:$K$500,$H$62:$H$500,R13,$I$62:$I$500,"<>수입",$I$62:$I$500,"<>저축") -> 0 | S14: =SUMIFS($K$62:$K$500,$H$62:$H$500,S13,$I$62:$I$500,"<>수입",$I$62:$I$500,"<>저축") -> 0 | T14: =SUMIFS($K$62:$K$500,$H$62:$H$500,T13,$I$62:$I$500,"<>수입",$I$62:$I$500,"<>저축") -> 0 | U14: =SUMIFS($K$62:$K$500,$H$62:$H$500,U13,$I$62:$I$500,"<>수입",$I$62:$I$500,"<>저축") -> 0 | V14: =SUMIFS($K$62:$K$500,$H$62:$H$500,V13,$I$62:$I$500,"<>수입",$I$62:$I$500,"<>저축") -> 0 | W14: =SUMIFS($K$62:$K$500,$H$62:$H$500,W13,$I$62:$I$500,"<>수입",$I$62:$I$500,"<>저축") -> 0 | X14: =SUMIFS($K$62:$K$500,$H$62:$H$500,X13,$I$62:$I$500,"<>수입",$I$62:$I$500,"<>저축") -> 0 | Y14: =SUM(R14:X14) -> 0 | AB14: =$M$33 -> 🐻식비 | AC14: =$P$39 -> 0 | AD14: =_xlfn.RANK.EQ(AC14,$AB$9:$AC$20,0) + ROW(AB6)/10000 -> 1.0006 | AE14: =SMALL($AD$9:$AD$20, ROW(AB6)) -> 1.0006 | AF14: =INDEX($AB$9:$AB$20,MATCH(AE14,$AD$9:$AD$20,0)) -> 🐻식비 | AG14: =INDEX($AC$9:$AC$20,MATCH(AE14,$AD$9:$AD$20,0)) -> 0
E15: 현금/이체 | F15: =SUMIFS($K$62:$K$500,$L$62:$L$500,E15,$I$62:$I$500,"<>수입",$I$62:$I$500,"<>저축") -> 0 | R15: =R13+7 -> 45368 | S15: =S13+7 -> 45369 | T15: =T13+7 -> 45370 | U15: =U13+7 -> 45371 | V15: =V13+7 -> 45372 | W15: =W13+7 -> 45373 | X15: =X13+7 -> 45374 | AB15: =$M$41 -> 🍪여가비 | AC15: =$P$47 -> 0 | AD15: =_xlfn.RANK.EQ(AC15,$AB$9:$AC$20,0) + ROW(AB7)/10000 -> 1.0007 | AE15: =SMALL($AD$9:$AD$20, ROW(AB7)) -> 1.0007 | AF15: =INDEX($AB$9:$AB$20,MATCH(AE15,$AD$9:$AD$20,0)) -> 🍪여가비 | AG15: =INDEX($AC$9:$AC$20,MATCH(AE15,$AD$9:$AD$20,0)) -> 0
C16: 총저축 | D16: =F43 -> 0 | E16: 현대카드 | F16: =SUMIFS($K$62:$K$500,$L$62:$L$500,E16,$I$62:$I$500,"<>수입",$I$62:$I$500,"<>저축") -> 0 | H16: 이벤트 | R16: =SUMIFS($K$62:$K$500,$H$62:$H$500,R15,$I$62:$I$500,"<>수입",$I$62:$I$500,"<>저축") -> 0 | S16: =SUMIFS($K$62:$K$500,$H$62:$H$500,S15,$I$62:$I$500,"<>수입",$I$62:$I$500,"<>저축") -> 0 | T16: =SUMIFS($K$62:$K$500,$H$62:$H$500,T15,$I$62:$I$500,"<>수입",$I$62:$I$500,"<>저축") -> 0 | U16: =SUMIFS($K$62:$K$500,$H$62:$H$500,U15,$I$62:$I$500,"<>수입",$I$62:$I$500,"<>저축") -> 0 | V16: =SUMIFS($K$62:$K$500,$H$62:$H$500,V15,$I$62:$I$500,"<>수입",$I$62:$I$500,"<>저축") -> 0 | W16: =SUMIFS($K$62:$K$500,$H$62:$H$500,W15,$I$62:$I$500,"<>수입",$I$62:$I$500,"<>저축") -> 0 | X16: =SUMIFS($K$62:$K$500,$H$62:$H$500,X15,$I$62:$I$500,"<>수입",$I$62:$I$500,"<>저축") -> 0 | Y16: =SUM(R16:X16) -> 0 | AB16: =$M$49 -> 🐻여가비 | AC16: =$P$55 -> 0 | AD16: =_xlfn.RANK.EQ(AC16,$AB$9:$AC$20,0) + ROW(AB8)/10000 -> 1.0008 | AE16: =SMALL($AD$9:$AD$20, ROW(AB8)) -> 1.0008 | AF16: =INDEX($AB$9:$AB$20,MATCH(AE16,$AD$9:$AD$20,0)) -> 🐻여가비 | AG16: =INDEX($AC$9:$AC$20,MATCH(AE16,$AD$9:$AD$20,0)) -> 0
E17: 국민카드 | F17: =SUMIFS($K$62:$K$500,$L$62:$L$500,E17,$I$62:$I$500,"<>수입",$I$62:$I$500,"<>저축") -> 0 | R17: =R15+7 -> 45375 | S17: =S15+7 -> 45376 | T17: =T15+7 -> 45377 | U17: =U15+7 -> 45378 | V17: =V15+7 -> 45379 | W17: =W15+7 -> 45380 | X17: =X15+7 -> 45381 | AB17: =$R$25 -> 🍪기타 | AC17: =$X$31 -> 0 | AD17: =_xlfn.RANK.EQ(AC17,$AB$9:$AC$20,0) + ROW(AB9)/10000 -> 1.0009 | AE17: =SMALL($AD$9:$AD$20, ROW(AB9)) -> 1.0009 | AF17: =INDEX($AB$9:$AB$20,MATCH(AE17,$AD$9:$AD$20,0)) -> 🍪기타 | AG17: =INDEX($AC$9:$AC$20,MATCH(AE17,$AD$9:$AD$20,0)) -> 0
C18: 잉여현금 | D18: =D12-D14-D16 -> 0 | E18: 현백카드 | F18: =SUMIFS($K$62:$K$500,$L$62:$L$500,E18,$I$62:$I$500,"<>수입",$I$62:$I$500,"<>저축") -> 0 | R18: =SUMIFS($K$62:$K$500,$H$62:$H$500,R17,$I$62:$I$500,"<>수입",$I$62:$I$500,"<>저축") -> 0 | S18: =SUMIFS($K$62:$K$500,$H$62:$H$500,S17,$I$62:$I$500,"<>수입",$I$62:$I$500,"<>저축") -> 0 | T18: =SUMIFS($K$62:$K$500,$H$62:$H$500,T17,$I$62:$I$500,"<>수입",$I$62:$I$500,"<>저축") -> 0 | U18: =SUMIFS($K$62:$K$500,$H$62:$H$500,U17,$I$62:$I$500,"<>수입",$I$62:$I$500,"<>저축") -> 0 | V18: =SUMIFS($K$62:$K$500,$H$62:$H$500,V17,$I$62:$I$500,"<>수입",$I$62:$I$500,"<>저축") -> 0 | W18: =SUMIFS($K$62:$K$500,$H$62:$H$500,W17,$I$62:$I$500,"<>수입",$I$62:$I$500,"<>저축") -> 0 | X18: =SUMIFS($K$62:$K$500,$H$62:$H$500,X17,$I$62:$I$500,"<>수입",$I$62:$I$500,"<>저축") -> 0 | Y18: =SUM(R18:X18) -> 0 | AB18: =$R$33 -> 🐻기타 | AC18: =$X$39 -> 0 | AD18: =_xlfn.RANK.EQ(AC18,$AB$9:$AC$20,0) + ROW(AB10)/10000 -> 1.001 | AE18: =SMALL($AD$9:$AD$20, ROW(AB10)) -> 1.001 | AF18: =INDEX($AB$9:$AB$20,MATCH(AE18,$AD$9:$AD$20,0)) -> 🐻기타 | AG18: =INDEX($AC$9:$AC$20,MATCH(AE18,$AD$9:$AD$20,0)) -> 0
