Workbook
Name 대분류: '설정시트'!$C$7:$C$20
Name 결제수단: '설정시트'!$D$23:$J$23

Sheet 설정시트
C3: 연도 | D3: 2025
C6: 대분류 | D6: 소분류
C7: 수입 | D7: 🍪 월급 | E7: 🍪 부수입 | F7: 🐻 월급 | G7: 🐻 부수입 | H7: 기타
C8: 저축 | D8: 주택청약 | E8: 우리은행 | F8: 케이뱅크 | G8: 연금저축
C9: 🍪고정비 | D9: 관리비 | E9: 월세 | F9: 대출이자 | G9: 통신비 | H9: 보험료 | J9: 곗돈
C10: 🐻고정비 | D10: 관리비 | E10: 대출이자 | F10: 통신비 | G10: 보험료 | H10: 곗돈
C11: 🍪생필품 | D11: 주방/욕실 | E11: 소모품 | F11: 기타
C12: 🐻생필품 | D12: 주방/욕실 | E12: 소모품 | F12: 기타
C13: 🍪식비 | D13: 식재료비 | E13: 회사점심 | F13: 간식/카페 | G13: 외식/배달 | H13: 기타
C14: 🐻식비 | D14: 식재료비 | E14: 회사점심 | F14: 간식/카페 | G14: 외식/배달 | H14: 기타
C15: 🍪여가비 | D15: 의류/잡화 | E15: OTT | F15: 문화생활 | G15: 자기계발 | H15: 미용 | J15: 기타
C16: 🐻여가비 | D16: 의류/잡화 | E16: OTT | F16: 문화생활 | G16: 자기계발 | H16: 미용 | J16: 기타
C17: 🍪기타 | D17: 약국 | E17: 병원비 | F17: 영양제 | G17: 교통비 | H17: 주유비 | J17: 기타
C18: 🐻기타 | D18: 약국 | E18: 병원비 | F18: 영양제 | G18: 교통비 | H18: 주유비 | J18: 기타
C19: 🍪이벤트성 | D19: 축의/부의금 | E19: 생신/생일선물 | F19: 명절/어버이날 | G19: 여행 | H19: 기타 | I19: 출산
C20: 🐻 이벤트성 | D20: 축의/부의금 | E20: 생신/생일선물 | F20: 명절/어버이날 | G20: 여행 | H20: 기타 | I20: 출산
C23: 결제수단 | D23: 🍪체크카드(현영) | E23: 🍪현금/이체 | F23: 🍪전통시장(제로페이) | G23: 🍪현대카드 | H23: 🍪국민카드 | I23: 🍪기업카드 | J23: 🍪하나카드 | K23: 🐻체크카드(현영) | L23: 🐻현금/이체 | M23: 🐻전통시장(제로페이) | N23: 🐻하나카드 | O23: 🐻현백카드 | P23: 🐻국민카드

Sheet 연간시트
C6: 2025 | F6: 수입 | J6: 저축/현금 | N6: 지출
F8: =W52 -> 96087011 | J8: =X52 -> 1931734 | N8: =Y52 -> 94155277
V13: 지출 | W13: 합계
V14: =$C$81 -> 총🍪고정비 | W14: =$E$81 -> 5320373 | X14: =_xlfn.RANK.EQ(W14,$W$14:$W$25,0) + ROW(AE1)/10000 -> 5.0001 | Y14: =SMALL($X$14:$X$25, ROW(AE1)) -> 1.0011 | Z14: =INDEX($V$14:$V$25,MATCH(Y14,$X$14:$X$25,0)) -> 총🍪이벤트성 | AA14: =INDEX($W$14:$W$25,MATCH(Y14,$X$14:$X$25,0)) -> 45890106
V15: =$C$88 -> 총🐻고정비 | W15: =$E$88 -> 5740616 | X15: =_xlfn.RANK.EQ(W15,$W$14:$W$25,0) + ROW(AE2)/10000 -> 4.0002 | Y15: =SMALL($X$14:$X$25, ROW(AE2)) -> 2.0012 | Z15: =INDEX($V$14:$V$25,MATCH(Y15,$X$14:$X$25,0)) -> 총🐻 이벤트성 | AA15: =INDEX($W$14:$W$25,MATCH(Y15,$X$14:$X$25,0)) -> 10032724
V16: =$C$95 -> 총🍪생필품 | W16: =$E$95 -> 1976775 | X16: =_xlfn.RANK.EQ(W16,$W$14:$W$25,0) + ROW(AE3)/10000 -> 12.0003 | Y16: =SMALL($X$14:$X$25, ROW(AE3)) -> 3.0005 | Z16: =INDEX($V$14:$V$25,MATCH(Y16,$X$14:$X$25,0)) -> 총🍪식비 | AA16: =INDEX($W$14:$W$25,MATCH(Y16,$X$14:$X$25,0)) -> 5858619
V17: =$C$102 -> 총🐻생필품 | W17: =$E$102 -> 2924998 | X17: =_xlfn.RANK.EQ(W17,$W$14:$W$25,0) + ROW(AE4)/10000 -> 10.0004 | Y17: =SMALL($X$14:$X$25, ROW(AE4)) -> 4.0002 | Z17: =INDEX($V$14:$V$25,MATCH(Y17,$X$14:$X$25,0)) -> 총🐻고정비 | AA17: =INDEX($W$14:$W$25,MATCH(Y17,$X$14:$X$25,0)) -> 5740616
V18: =$C$109 -> 총🍪식비 | W18: =$E$109 -> 5858619 | X18: =_xlfn.RANK.EQ(W18,$W$14:$W$25,0) + ROW(AE5)/10000 -> 3.0005 | Y18: =SMALL($X$14:$X$25, ROW(AE5)) -> 5.0001 | Z18: =INDEX($V$14:$V$25,MATCH(Y18,$X$14:$X$25,0)) -> 총🍪고정비 | AA18: =INDEX($W$14:$W$25,MATCH(Y18,$X$14:$X$25,0)) -> 5320373
V19: =$C$116 -> 총🐻식비 | W19: =$E$116 -> 3620716 | X19: =_xlfn.RANK.EQ(W19,$W$14:$W$25,0) + ROW(AE6)/10000 -> 7.0006 | Y19: =SMALL($X$14:$X$25, ROW(AE6)) -> 6.001 | Z19: =INDEX($V$14:$V$25,MATCH(Y19,$X$14:$X$25,0)) -> 총🐻기타 | AA19: =INDEX($W$14:$W$25,MATCH(Y19,$X$14:$X$25,0)) -> 3646390
V20: =$C$123 -> 총🍪여가비 | W20: =$E$123 -> 3414407 | X20: =_xlfn.RANK.EQ(W20,$W$14:$W$25,0) + ROW(AE7)/10000 -> 8.0007 | Y20: =SMALL($X$14:$X$25, ROW(AE7)) -> 7.0006 | Z20: =INDEX($V$14:$V$25,MATCH(Y20,$X$14:$X$25,0)) -> 총🐻식비 | AA20: =INDEX($W$14:$W$25,MATCH(Y20,$X$14:$X$25,0)) -> 3620716
V21: =$C$130 -> 총🐻여가비 | W21: =$E$130 -> 2758802 | X21: =_xlfn.RANK.EQ(W21,$W$14:$W$25,0) + ROW(AE8)/10000 -> 11.0008 | Y21: =SMALL($X$14:$X$25, ROW(AE8)) -> 8.0007 | Z21: =INDEX($V$14:$V$25,MATCH(Y21,$X$14:$X$25,0)) -> 총🍪여가비 | AA21: =INDEX($W$14:$W$25,MATCH(Y21,$X$14:$X$25,0)) -> 3414407
V22: =$C$137 -> 총🍪기타 | W22: =$E$137 -> 2970751 | X22: =_xlfn.RANK.EQ(W22,$W$14:$W$25,0) + ROW(AE9)/10000 -> 9.0009 | Y22: =SMALL($X$14:$X$25, ROW(AE9)) -> 9.0009 | Z22: =INDEX($V$14:$V$25,MATCH(Y22,$X$14:$X$25,0)) -> 총🍪기타 | AA22: =INDEX($W$14:$W$25,MATCH(Y22,$X$14:$X$25,0)) -> 2970751
V23: =$C$144 -> 총🐻기타 | W23: =$E$144 -> 3646390 | X23: =_xlfn.RANK.EQ(W23,$W$14:$W$25,0) + ROW(AE10)/10000 -> 6.001 | Y23: =SMALL($X$14:$X$25, ROW(AE10)) -> 10.0004 | Z23: =INDEX($V$14:$V$25,MATCH(Y23,$X$14:$X$25,0)) -> 총🐻생필품 | AA23: =INDEX($W$14:$W$25,MATCH(Y23,$X$14:$X$25,0)) -> 2924998
V24: =$C$151 -> 총🍪이벤트성 | W24: =$E$151 -> 45890106 | X24: =_xlfn.RANK.EQ(W24,$W$14:$W$25,0) + ROW(AE11)/10000 -> 1.0011 | Y24: =SMALL($X$14:$X$25, ROW(AE11)) -> 11.0008 | Z24: =INDEX($V$14:$V$25,MATCH(Y24,$X$14:$X$25,0)) -> 총🐻여가비 | AA24: =INDEX($W$14:$W$25,MATCH(Y24,$X$14:$X$25,0)) -> 2758802
V25: =$C$158 -> 총🐻 이벤트성 | W25: =$E$158 -> 10032724 | X25: =_xlfn.RANK.EQ(W25,$W$14:$W$25,0) + ROW(AE12)/10000 -> 2.0012 | Y25: =SMALL($X$14:$X$25, ROW(AE12)) -> 12.0003 | Z25: =INDEX($V$14:$V$25,MATCH(Y25,$X$14:$X$25,0)) -> 총🍪생필품 | AA25: =INDEX($W$14:$W$25,MATCH(Y25,$X$14:$X$25,0)) -> 1976775
V29: 결제수단 | W29: 합계
V30: ='1월'!$E$14 -> 🍪기업카드 | W30: ='1월'!$F14+'2월'!$F14+'3월'!$F14+'4월'!$F14+'5월'!$F14+'6월'!$F14+'7월'!$F14+'8월'!$F14+'9월'!$F14+'10월'!$F14+'11월'!$F14+'12월'!$F14 -> #REF! | X30: =_xlfn.RANK.EQ(W30,$W$30:$W$35,0) + ROW(AE1)/10000 -> #REF! | Y30: =SMALL($X$30:$X$35, ROW(AE1)) -> #REF! | Z30: =INDEX($V$30:$V$35,MATCH(Y30,$X$30:$X$35,0)) -> #REF! | AA30: =INDEX($W$30:$W$35,MATCH(Y30,$X$30:$X$35,0)) -> #REF!
V31: ='1월'!$E$15 -> 🍪하나카드 | W31: ='1월'!$F15+'2월'!$F15+'3월'!$F15+'4월'!$F15+'5월'!$F15+'6월'!$F15+'7월'!$F15+'8월'!$F15+'9월'!$F15+'10월'!$F15+'11월'!$F15+'12월'!$F15 -> #REF! | X31: =_xlfn.RANK.EQ(W31,$W$30:$W$35,0) + ROW(AE2)/10000 -> #REF! | Y31: =SMALL($X$30:$X$35, ROW(AE2)) -> #REF! | Z31: =INDEX($V$30:$V$35,MATCH(Y31,$X$30:$X$35,0)) -> #REF! | AA31: =INDEX($W$30:$W$35,MATCH(Y31,$X$30:$X$35,0)) -> #REF!
V32: ='1월'!$E$16 -> 🐻체크카드(현영) | W32: ='1월'!$F16+'2월'!$F16+'3월'!$F16+'4월'!$F16+'5월'!$F16+'6월'!$F16+'7월'!$F16+'8월'!$F16+'9월'!$F16+'10월'!$F16+'11월'!$F16+'12월'!$F16 -> #REF! | X32: =_xlfn.RANK.EQ(W32,$W$30:$W$35,0) + ROW(AE3)/10000 -> #REF! | Y32: =SMALL($X$30:$X$35, ROW(AE3)) -> #REF! | Z32: =INDEX($V$30:$V$35,MATCH(Y32,$X$30:$X$35,0)) -> #REF! | AA32: =INDEX($W$30:$W$35,MATCH(Y32,$X$30:$X$35,0)) -> #REF!
V33: ='1월'!$E$17 -> 🐻현금/이체 | W33: ='1월'!$F17+'2월'!$F17+'3월'!$F17+'4월'!$F17+'5월'!$F17+'6월'!$F17+'7월'!$F17+'8월'!$F17+'9월'!$F17+'10월'!$F17+'11월'!$F17+'12월'!$F17 -> #REF! | X33: =_xlfn.RANK.EQ(W33,$W$30:$W$35,0) + ROW(AE4)/10000 -> #REF! | Y33: =SMALL($X$30:$X$35, ROW(AE4)) -> #REF! | Z33: =INDEX($V$30:$V$35,MATCH(Y33,$X$30:$X$35,0)) -> #REF! | AA33: =INDEX($W$30:$W$35,MATCH(Y33,$X$30:$X$35,0)) -> #REF!
V34: ='1월'!$E$18 -> 🐻전통시장(제로페이) | W34: ='1월'!$F18+'2월'!$F18+'3월'!$F18+'4월'!$F18+'5월'!$F18+'6월'!$F18+'7월'!$F18+'8월'!$F18+'9월'!$F18+'10월'!$F18+'11월'!$F18+'12월'!$F18 -> #REF! | X34: =_xlfn.RANK.EQ(W34,$W$30:$W$35,0) + ROW(AE5)/10000 -> #REF! | Y34: =SMALL($X$30:$X$35, ROW(AE5)) -> #REF! | Z34: =INDEX($V$30:$V$35,MATCH(Y34,$X$30:$X$35,0)) -> #REF! | AA34: =INDEX($W$30:$W$35,MATCH(Y34,$X$30:$X$35,0)) -> #REF!
V35: ='1월'!$E$19 -> 🐻하나카드 | W35: ='1월'!$F19+'2월'!$F19+'3월'!$F19+'4월'!$F19+'5월'!$F19+'6월'!$F19+'7월'!$F19+'8월'!$F19+'9월'!$F19+'10월'!$F19+'11월'!$F19+'12월'!$F19 -> #REF! | X35: =_xlfn.RANK.EQ(W35,$W$30:$W$35,0) + ROW(AE6)/10000 -> #REF! | Y35: =SMALL($X$30:$X$35, ROW(AE6)) -> #REF! | Z35: =INDEX($V$30:$V$35,MATCH(Y35,$X$30:$X$35,0)) -> #REF! | AA35: =INDEX($W$30:$W$35,MATCH(Y35,$X$30:$X$35,0)) -> #REF!
W39: 수입 | X39: 저축/현금 | Y39: 지출 | Z39: 저축률 | AB39: 수입 | AC39: 합계
V40: 1월 | W40: =F64 -> 10192950 | X40: =SUM(F73:F74) -> 2319974 | Y40: =SUM(F81,F88,F95,F102,F109,F116,F123,F130,F137,F144,F151,F158) -> 7872976 | Z40: =X40/W40 -> 0.22760575 | AB40: =D56 -> 🍪 월급 | AC40: =E56 -> 26352200 | AD40: =_xlfn.RANK.EQ(AC40,$AC$40:$AC$47,0) + ROW(AE1)/10000 -> 2.0001 | AE40: =SMALL($AD$40:$AD$47, ROW(AE1)) -> 1.0003 | AF40: =INDEX($AB$40:$AB$47,MATCH(AE40,$AD$40:$AD$47,0)) -> 🐻 월급 | AG40: =INDEX($AC$40:$AC$47,MATCH(AE40,$AD$40:$AD$47,0)) -> 40036190
V41: 2월 | W41: =G64 -> 5488395 | X41: =SUM(G73:G74) -> -43556626 | Y41: =SUM(G81,G88,G95,G102,G109,G116,G123,G130,G137,G144,G151,G158) -> 49045021 | Z41: =X41/W41 -> -7.9361318 | AB41: =D57 -> 🍪 부수입 | AC41: =E57 -> 1217670 | AD41: =_xlfn.RANK.EQ(AC41,$AC$40:$AC$47,0) + ROW(AE2)/10000 -> 5.0002 | AE41: =SMALL($AD$40:$AD$47, ROW(AE2)) -> 2.0001 | AF41: =INDEX($AB$40:$AB$47,MATCH(AE41,$AD$40:$AD$47,0)) -> 🍪 월급 | AG41: =INDEX($AC$40:$AC$47,MATCH(AE41,$AD$40:$AD$47,0)) -> 26352200
V42: 3월 | W42: =H64 -> 14040178 | X42: =SUM(H73:H74) -> 9168382 | Y42: =SUM(H81,H88,H95,H102,H109,H116,H123,H130,H137,H144,H151,H158) -> 4871796 | Z42: =X42/W42 -> 0.65301038 | AB42: =D58 -> 🐻 월급 | AC42: =E58 -> 40036190 | AD42: =_xlfn.RANK.EQ(AC42,$AC$40:$AC$47,0) + ROW(AE3)/10000 -> 1.0003 | AE42: =SMALL($AD$40:$AD$47, ROW(AE3)) -> 3.0005 | AF42: =INDEX($AB$40:$AB$47,MATCH(AE42,$AD$40:$AD$47,0)) -> 기타 | AG42: =INDEX($AC$40:$AC$47,MATCH(AE42,$AD$40:$AD$47,0)) -> 25870051
V43: 4월 | W43: =I64 -> 9492620 | X43: =SUM(I73:I74) -> 4982607 | Y43: =SUM(I81,I88,I95,I102,I109,I116,I123,I130,I137,I144,I151,I158) -> 4510013 | Z43: =X43/W43 -> 0.52489271 | AB43: =D59 -> 🐻 부수입 | AC43: =E59 -> 2610900 | AD43: =_xlfn.RANK.EQ(AC43,$AC$40:$AC$47,0) + ROW(AE4)/10000 -> 4.0004 | AE43: =SMALL($AD$40:$AD$47, ROW(AE4)) -> 4.0004 | AF43: =INDEX($AB$40:$AB$47,MATCH(AE43,$AD$40:$AD$47,0)) -> 🐻 부수입 | AG43: =INDEX($AC$40:$AC$47,MATCH(AE43,$AD$40:$AD$47,0)) -> 2610900
V44: 5월 | W44: =J64 -> 8430830 | X44: =SUM(J73:J74) -> 4159339 | Y44: =SUM(J81,J88,J95,J102,J109,J116,J123,J130,J137,J144,J151,J158) -> 4271491 | Z44: =X44/W44 -> 0.4933487 | AB44: =D60 -> 기타 | AC44: =E60 -> 25870051 | AD44: =_xlfn.RANK.EQ(AC44,$AC$40:$AC$47,0) + ROW(AE5)/10000 -> 3.0005 | AE44: =SMALL($AD$40:$AD$47, ROW(AE5)) -> 5.0002 | AF44: =INDEX($AB$40:$AB$47,MATCH(AE44,$AD$40:$AD$47,0)) -> 🍪 부수입 | AG44: =INDEX($AC$40:$AC$47,MATCH(AE44,$AD$40:$AD$47,0)) -> 1217670
V45: 6월 | W45: =K64 -> 8399150 | X45: =SUM(K73:K74) -> 4609454 | Y45: =SUM(K81,K88,K95,K102,K109,K116,K123,K130,K137,K144,K151,K158) -> 3789696 | Z45: =X45/W45 -> 0.54880006 | AB45: =D61 | AC45: =E61 -> 0 | AD45: =_xlfn.RANK.EQ(AC45,$AC$40:$AC$47,0) + ROW(AE6)/10000 -> 6.0006 | AE45: =SMALL($AD$40:$AD$47, ROW(AE6)) -> 6.0006 | AF45: =INDEX($AB$40:$AB$47,MATCH(AE45,$AD$40:$AD$47,0)) | AG45: =INDEX($AC$40:$AC$47,MATCH(AE45,$AD$40:$AD$47,0)) -> 0
V46: 7월 | W46: =L64 -> 4699920 | X46: =SUM(L73:L74) -> 1225600 | Y46: =SUM(L81,L88,L95,L102,L109,L116,L123,L130,L137,L144,L151,L158) -> 3474320 | Z46: =X46/W46 -> 0.2607704 | AB46: =D62 | AC46: =E62 -> 0 | AD46: =_xlfn.RANK.EQ(AC46,$AC$40:$AC$47,0) + ROW(AE7)/10000 -> 6.0007 | AE46: =SMALL($AD$40:$AD$47, ROW(AE7)) -> 6.0007 | AF46: =INDEX($AB$40:$AB$47,MATCH(AE46,$AD$40:$AD$47,0)) | AG46: =INDEX($AC$40:$AC$47,MATCH(AE46,$AD$40:$AD$47,0)) -> 0
V47: 8월 | W47: =M64 -> 4619920 | X47: =SUM(M73:M74) -> 1972731 | Y47: =SUM(M81,M88,M95,M102,M109,M116,M123,M130,M137,M144,M151,M158) -> 2647189 | Z47: =X47/W47 -> 0.42700545 | AB47: =D63 | AC47: =E63 -> 0 | AD47: =_xlfn.RANK.EQ(AC47,$AC$40:$AC$47,0) + ROW(AE8)/10000 -> 6.0008 | AE47: =SMALL($AD$40:$AD$47, ROW(AE8)) -> 6.0008 | AF47: =INDEX($AB$40:$AB$47,MATCH(AE47,$AD$40:$AD$47,0)) | AG47: =INDEX($AC$40:$AC$47,MATCH(AE47,$AD$40:$AD$47,0)) -> 0
V48: 9월 | W48: =N64 -> 5389550 | X48: =SUM(N73:N74) -> 2374710 | Y48: =SUM(N81,N88,N95,N102,N109,N116,N123,N130,N137,N144,N151,N158) -> 3014840 | Z48: =X48/W48 -> 0.44061378
V49: 10월 | W49: =O64 -> 9914708 | X49: =SUM(O73:O74) -> 5672610 | Y49: =SUM(O81,O88,O95,O102,O109,O116,O123,O130,O137,O144,O151,O158) -> 4242098 | Z49: =X49/W49 -> 0.5721409
V50: 11월 | W50: =P64 -> 15418790 | X50: =SUM(P73:P74) -> 9002953 | Y50: =SUM(P81,P88,P95,P102,P109,P116,P123,P130,P137,P144,P151,P158) -> 6415837 | Z50: =X50/W50 -> 0.58389491
V51: 12월 | W51: =Q64 -> 0 | X51: =SUM(Q73:Q74) -> 0 | Y51: =SUM(Q81,Q88,Q95,Q102,Q109,Q116,Q123,Q130,Q137,Q144,Q151,Q158) -> 0 | Z51: =X51/W51 -> #DIV/0!
W52: =SUM(W40:W51) -> 96087011 | X52: =SUM(X40:X51) -> 1931734 | Y52: =SUM(Y40:Y51) -> 94155277
C55: 대분류 | D55: 소분류 | E55: 합계 | F55: 1월 | G55: 2월 | H55: 3월 | I55: 4월 | J55: 5월 | K55: 6월 | L55: 7월 | M55: 8월 | N55: 9월 | O55: 10월 | P55: 11월 | Q55: 12월 | R55: 평균
C56: 수입 | D56: 🍪 월급 | E56: =SUM(F56:Q56) -> 26352200 | F56: {=INDIRECT("1월!$F$25")} -> 3257030 | G56: {=INDIRECT("2월!$F$25")} -> 3257030 | H56: {=INDIRECT("3월!$F$25")} -> 3297040 | I56: {=INDIRECT("4월!$F$25")} -> 3306190 | J56: {=INDIRECT("5월!$F$25")} -> 3305170 | K56: {=INDIRECT("6월!$F$25")} -> 3304700 | L56: {=INDIRECT("7월!$F$25")} -> 0 | M56: {=INDIRECT("8월!$F$25")} -> 0 | N56: {=INDIRECT("9월!$F$25")} -> 0 | O56: {=INDIRECT("10월!$F$25")} -> 3312520 | P56: {=INDIRECT("11월!$F$25")} -> 3312520 | Q56: {=INDIRECT("12월!$F$25")} -> 0 | R56: =IFERROR(SUM(F56:Q56)/W$69,"") -> 2395654.5 | W56: 작성여부
D57: 🍪 부수입 | E57: =SUM(F57:Q57) -> 1217670 | F57: {=INDIRECT("1월!$F$26")} -> 345000 | G57: {=INDIRECT("2월!$F$26")} -> 872670 | H57: {=INDIRECT("3월!$F$26")} -> 0 | I57: {=INDIRECT("4월!$F$26")} -> 0 | J57: {=INDIRECT("5월!$F$26")} -> 0 | K57: {=INDIRECT("6월!$F$26")} -> 0 | L57: {=INDIRECT("7월!$F$26")} -> 0 | M57: {=INDIRECT("8월!$F$26")} -> 0 | N57: {=INDIRECT("9월!$F$26")} -> 0 | O57: {=INDIRECT("10월!$F$26")} -> 0 | P57: {=INDIRECT("11월!$F$26")} -> 0 | Q57: {=INDIRECT("12월!$F$26")} -> 0 | R57: =IFERROR(SUM(F57:Q57)/W$69,"") -> 110697.27 | V57: 1월 | W57: =IF(COUNTIF(F56:F158, "<>0") > 0, 1, 0) -> 1
D58: 🐻 월급 | E58: =SUM(F58:Q58) -> 40036190 | F58: {=INDIRECT("1월!$F$27")} -> 4310870 | G58: {=INDIRECT("2월!$F$27")} -> 0 | H58: {=INDIRECT("3월!$F$27")} -> 0 | I58: {=INDIRECT("4월!$F$27")} -> 4754880 | J58: {=INDIRECT("5월!$F$27")} -> 4570920 | K58: {=INDIRECT("6월!$F$27")} -> 4399920 | L58: {=INDIRECT("7월!$F$27")} -> 4399920 | M58: {=INDIRECT("8월!$F$27")} -> 4399920 | N58: {=INDIRECT("9월!$F$27")} -> 4399920 | O58: {=INDIRECT("10월!$F$27")} -> 4399920 | P58: {=INDIRECT("11월!$F$27")} -> 4399920 | Q58: {=INDIRECT("12월!$F$27")} -> 0 | R58: =IFERROR(SUM(F58:Q58)/W$69,"") -> 3639653.6 | V58: 2월 | W58: =IF(COUNTIF(G56:G158, "<>0") > 0, 1, 0) -> 1
...

Sheet 자산관리
C22: 대분류 | D22: 소분류 | E22: 1월 | F22: 2월 | G22: 3월 | H22: 4월 | I22: 5월 | J22: 6월 | K22: 7월 | L22: 8월 | M22: 9월 | N22: 10월 | O22: 11월 | P22: 12월
C23: 부채 | D23: 전세대출 | E23: 60000000 | F23: 60000000 | G23: 60000000 | H23: 60000000 | I23: 60000000 | J23: 60000000 | K23: 60000000 | L23: 60000000 | M23: 60000000 | N23: 60000000 | O23: 60000000 | P23: 60000000
C29: 부채 합계 | E29: =SUM(E23:E28) -> 60000000 | F29: =SUM(F23:F28) -> 60000000 | G29: =SUM(G23:G28) -> 60000000 | H29: =SUM(H23:H28) -> 60000000 | I29: =SUM(I23:I28) -> 60000000 | J29: =SUM(J23:J28) -> 60000000 | K29: =SUM(K23:K28) -> 60000000 | L29: =SUM(L23:L28) -> 60000000 | ... P29: =SUM(P23:P28) -> 60000000
C30: 비유동자산 | E30: -
D31: SK뷰-전세보증금 | E31: 500000000 | F31: 500000000 | G31: 500000000 | H31: 500000000 | I31: 500000000 | J31: 500000000 | K31: 500000000 | L31: 500000000 | M31: 500000000 | N31: 500000000 | O31: 500000000 | P31: 500000000
D32: 🐻주택청약 | E32: 10260010 | F32: 10260010 | G32: 10260010 | H32: 10260010 | I32: 10260010 | J32: 10260010 | K32: 10260010 | L32: 10260010 | M32: 10260010 | N32: 10260010 | O32: 10260010 | P32: 10260010
D33: 🍪주택청약 | E33: 3020000 | F33: 3020000 | G33: 3020000 | H33: 3020000 | I33: 3020000 | J33: 3020000 | K33: 3020000 | L33: 3020000 | M33: 3020000 | N33: 3020000 | O33: 3020000 | P33: 3020000
C37: 비유동자산 합계 | E37: =SUM(E30:E36) -> 513280010 | F37: =SUM(F30:F36) -> 513280010 | G37: =SUM(G30:G36) -> 513280010 | H37: =SUM(H30:H36) -> 513280010 | I37: =SUM(I30:I36) -> 513280010 | J37: =SUM(J30:J36) -> 513280010 | K37: =SUM(K30:K36) -> 513280010 | L37: =SUM(L30:L36) -> 513280010 | ... P37: =SUM(P30:P36) -> 513280010
C38: 유동자산 (투자) | D38: 🐻주식 | H38: 2921257 | I38: 2921257 | J38: 3768946 | K38: 3558877 | N38: 5096711
D39: 🐻연금저축 한투 | H39: 7821622 | I39: 7821622 | J39: 9116774 | K39: 10117282 | N39: 10940296
D40: 🐻연금저축 KB | H40: 435275 | I40: 435275 | J40: 0
D41: 🐻퇴직연금 | H41: 7422813 | I41: 7422813 | J41: 8167790 | K41: 8117996 | N41: 9192926
D42: 🐻ISA | H42: 213330 | I42: 213330 | J42: 277513 | K42: 310541 | N42: 319061
D43: 🍪주식 | E43: - | G43: -
D44: 🍪연금저축
C45: 유동자산(투자) 합계 | E45: =SUM(E38:E44) -> 0 | F45: =SUM(F38:F44) -> 0 | G45: =SUM(G38:G44) -> 0 | H45: =SUM(H38:H44) -> 18814297 | I45: =SUM(I38:I44) -> 18814297 | J45: =SUM(J38:J44) -> 21331023 | K45: =SUM(K38:K44) -> 22104696 | L45: =SUM(L38:L44) -> 0 | ... P45: =SUM(P38:P44) -> 0
D46: 🐻우리은행적금 | E46: - | G46: 0
D47: 🐻K뱅크-예금 | E47: 0- | G47: 0
D48: 🐻K뱅크-생활통장 | E48: 3000000 | F48: 3000000 | G48: 2500000 | H48: 3000000 | I48: 3000000 | J48: -
D49: 🐻K뱅크-파킹 | E49: 1800000 | F49: 1300000 | G49: 0 | H49: 1500000 | I49: 3500000 | J49: 0
D50: 🍪우리은행적금 | E50: 6000000 | F50: 0 | G50: -
D51: 🍪K뱅크-예금 | E51: 0
D52: 🍪K뱅크-생활통장 | E52: 3000000 | F52: 3000000 | G52: 3000000 | H52: 3000000 | I52: 3000000 | J52: 3000000 | K52: 3000000 | L52: 3000000 | M52: 3000000 | N52: 3000000 | O52: 3000000
D53: 🍪K뱅크-파킹 | E53: 39000000 | F53: 0 | G53: 12000000 | H53: 12000000 | I53: 17000000 | J53: 17000000 | K53: 20500000 | L53: 20500000 | M53: 20500000 | N53: 21000000 | O53: 31500000
C54: 유동자산(현금) 합계 | E54: =SUM(E46:E53) -> 52800000 | F54: =SUM(F46:F53) -> 7300000 | G54: =SUM(G46:G53) -> 17500000 | H54: =SUM(H46:H53) -> 19500000 | I54: =SUM(I46:I53) -> 26500000 | J54: =SUM(J46:J53) -> 20000000 | K54: =SUM(K46:K53) -> 23500000 | L54: =SUM(L46:L53) -> 23500000 | ... P54: =SUM(P46:P53) -> 0
C55: 순자산 | E55: =E54+E37-E29 -> 506080010 | F55: =F54+F37-F29 -> 460580010 | G55: =G54+G37-G29 -> 470780010 | H55: =H54+H37-H29 -> 472780010 | I55: =I54+I37-I29 -> 479780010 | J55: =J54+J37-J29 -> 473280010 | K55: =K54+K37-K29 -> 476780010 | L55: =L54+L37-L29 -> 476780010 | ... P55: =P54+P37-P29 -> 453280010
C56: 증감액 | F56: =IF(F55=0, "",F55-E55) -> -45500000 | G56: =IF(G55=0, "",G55-F55) -> 10200000 | H56: =IF(H55=0, "",H55-G55) -> 2000000 | I56: =IF(I55=0, "",I55-H55) -> 7000000 | J56: =IF(J55=0, "",J55-I55) -> -6500000 | K56: =IF(K55=0, "",K55-J55) -> 3500000 | L56: =IF(L55=0, "",L55-K55) -> 0 | M56: =IF(M55=0, "",M55-L55) -> 0 | ... P56: =IF(P55=0, "",P55-O55) -> -34500000
C57: 주식칸도 만들어봄♥
G59: 총액 | H59: 간이대지급금 | I59: 미정산
F60: 퇴직금 임금체불(3개월) | G60: =25105020+4850000*3 -> 39655020 | H60: 10000000 | I60: =G60-H60 -> 29655020
G61: 총액 | H61: 정산 | I61: 미정산
F62: 조현철 | G62: 7500000 | H62: =220000+120000+130000+200000+140000 -> 810000 | I62: =G62-H62 -> 6690000

Sheet 연말정산
B4: 월 | C4: 체크카드(현금영수증) | D4: 전통시장(제로페이) | E4: 신용카드 | G4: 월 | H4: 체크카드(현금영수증) | I4: 전통시장(제로페이) | J4: 신용카드
B5: 1월 | C5: {=INDIRECT("1월!$F$9")} -> 1550000 | D5: {=INDIRECT("1월!$F$11")} -> 21394 | E5: {=SUM(INDIRECT("1월!F12:F14"))} -> 2101178 | G5: 1월 | H5: {=INDIRECT("1월!$F$15")} -> 0 | I5: {=INDIRECT("1월!$F$17")} -> 2346620 | J5: {=SUM(INDIRECT("1월!F18:F19"))} -> 930716
B6: 2월 | C6: {=INDIRECT("2월!$F$9")} -> 0 | D6: {=INDIRECT("2월!$F$11")} -> 0 | E6: {=SUM(INDIRECT("2월!F12:F14"))} -> 2648680 | G6: 2월 | H6: {=INDIRECT("2월!$F$15")} -> 0 | I6: {=INDIRECT("2월!$F$17")} -> 627500 | J6: {=SUM(INDIRECT("2월!F18:F19"))} -> 1298385
B7: 3월 | C7: {=INDIRECT("3월!$F$9")} -> 0 | D7: {=INDIRECT("3월!$F$11")} -> 0 | E7: {=SUM(INDIRECT("3월!F12:F14"))} -> 2978503 | G7: 3월 | H7: {=INDIRECT("3월!$F$15")} -> 210000 | I7: {=INDIRECT("3월!$F$17")} -> 302680 | J7: {=SUM(INDIRECT("3월!F18:F19"))} -> 1213042
B8: 4월 | C8: {=INDIRECT("4월!$F$9")} -> 0 | D8: {=INDIRECT("4월!$F$11")} -> 0 | E8: {=SUM(INDIRECT("4월!F12:F14"))} -> 624394 | G8: 4월 | H8: {=INDIRECT("4월!$F$15")} -> 0 | I8: {=INDIRECT("4월!$F$17")} -> 189000 | J8: {=SUM(INDIRECT("4월!F18:F19"))} -> 1966526
B9: 5월 | C9: {=INDIRECT("5월!$F$9")} -> 0 | D9: {=INDIRECT("5월!$F$11")} -> 0 | E9: {=SUM(INDIRECT("5월!F12:F14"))} -> 576689 | G9: 5월 | H9: {=INDIRECT("5월!$F$15")} -> 0 | I9: {=INDIRECT("5월!$F$17")} -> 170000 | J9: {=SUM(INDIRECT("5월!F18:F19"))} -> 2682031
B10: 6월 | C10: {=INDIRECT("6월!$F$9")} -> 0 | D10: {=INDIRECT("6월!$F$11")} -> 0 | E10: {=SUM(INDIRECT("6월!F12:F14"))} -> 1630779 | G10: 6월 | H10: {=INDIRECT("6월!$F$15")} -> 0 | I10: {=INDIRECT("6월!$F$17")} -> 214000 | J10: {=SUM(INDIRECT("6월!F18:F19"))} -> 1727827
B11: 7월 | C11: {=INDIRECT("7월!$F$9")} -> 0 | D11: {=INDIRECT("7월!$F$11")} -> 0 | E11: {=SUM(INDIRECT("7월!F12:F14"))} -> 968900 | G11: 7월 | H11: {=INDIRECT("7월!$F$15")} -> 0 | I11: {=INDIRECT("7월!$F$17")} -> 133010 | J11: {=SUM(INDIRECT("7월!F18:F19"))} -> 1972310
B12: 8월 | C12: {=INDIRECT("8월!$F$9")} -> 0 | D12: {=INDIRECT("8월!$F$11")} -> 0 | E12: {=SUM(INDIRECT("8월!F12:F14"))} -> 0 | G12: 8월 | H12: {=INDIRECT("8월!$F$15")} -> 0 | I12: {=INDIRECT("8월!$F$17")} -> 183000 | J12: {=SUM(INDIRECT("8월!F18:F19"))} -> 2242557
B13: 9월 | C13: {=INDIRECT("9월!$F$9")} -> 0 | D13: {=INDIRECT("9월!$F$11")} -> 0 | E13: {=SUM(INDIRECT("9월!F12:F14"))} -> 0 | G13: 9월 | H13: {=INDIRECT("9월!$F$15")} -> 0 | I13: {=INDIRECT("9월!$F$17")} -> 246170 | J13: {=SUM(INDIRECT("9월!F18:F19"))} -> 2735390
B14: 10월 | C14: {=INDIRECT("10월!$F$9")} -> 0 | D14: {=INDIRECT("10월!$F$11")} -> 0 | E14: {=SUM(INDIRECT("10월!F12:F14"))} -> 248890 | G14: 10월 | H14: {=INDIRECT("10월!$F$15")} -> 962778 | I14: {=INDIRECT("10월!$F$17")} -> 226800 | J14: {=SUM(INDIRECT("10월!F18:F19"))} -> 2252750
B15: 11월 | C15: {=INDIRECT("11월!$F$9")} -> 0 | D15: {=INDIRECT("11월!$F$11")} -> 0 | E15: {=SUM(INDIRECT("11월!F12:F14"))} -> 100490 | G15: 11월 | H15: {=INDIRECT("11월!$F$15")} -> 1250845 | I15: {=INDIRECT("11월!$F$17")} -> 180000 | J15: {=SUM(INDIRECT("11월!F18:F19"))} -> 3923398
B16: 12월 | C16: {=INDIRECT("12월!$F$9")} -> 0 | D16: {=INDIRECT("12월!$F$11")} -> 0 | E16: {=SUM(INDIRECT("12월!F12:F14"))} -> 0 | G16: 12월 | H16: {=INDIRECT("12월!$F$15")} -> 0 | I16: {=INDIRECT("12월!$F$17")} -> 0 | J16: {=SUM(INDIRECT("12월!F18:F19"))} -> 0
B17: 합계 | C17: =SUM(C5:C16) -> 1550000 | D17: =SUM(D5:D16) -> 21394 | E17: =SUM(E5:E16) -> 11878503 | G17: 합계 | H17: =SUM(H5:H16) -> 2423623 | I17: =SUM(I5:I16) -> 4818780 | J17: =SUM(J5:J16) -> 22944932

Sheet 1월
C3: 2025 | D3: 1
E8: 결제수단 | F8: 금액 | R8: S | S8: M | T8: T | U8: W | V8: T | W8: F | X8: S | Y8: 누적 | AB8: 대분류 | AC8: 합계
E9: 🍪체크카드(현영) | F9: =SUMIFS($K$62:$K$500,$L$62:$L$500,E9,$I$62:$I$500,"<>수입",$I$62:$I$500,"<>저축") -> 1550000 | R9: =DATE($C$3,$D$3,1)-WEEKDAY(DATE($C$3,$D$3,1))+1 -> 45655 | S9: =R9 + 1 -> 45656 | T9: =S9 + 1 -> 45657 | U9: =T9 + 1 -> 45658 | V9: =U9 + 1 -> 45659 | W9: =V9 + 1 -> 45660 | X9: =W9 + 1 -> 45661 | AB9: =$H$25 -> 🍪고정비 | AC9: =$K$31 -> 297392 | AD9: =_xlfn.RANK.EQ(AC9,$AB$9:$AC$20,0) + ROW(AB1)/10000 -> 6.0001 | AE9: =SMALL($AD$9:$AD$20, ROW(AB1)) -> 1.0012 | AF9: =INDEX($AB$9:$AB$20,MATCH(AE9,$AD$9:$AD$20,0)) -> 🐻 이벤트성 | AG9: =INDEX($AC$9:$AC$20,MATCH(AE9,$AD$9:$AD$20,0)) -> 2438940
E10: 🍪현금/이체 | F10: =SUMIFS($K$62:$K$500,$L$62:$L$500,E10,$I$62:$I$500,"<>수입",$I$62:$I$500,"<>저축") -> 1734978 | R10: =SUMIFS($K$62:$K$500,$H$62:$H$500,R9,$I$62:$I$500,"<>수입",$I$62:$I$500,"<>저축") -> 0 | S10: =SUMIFS($K$62:$K$500,$H$62:$H$500,S9,$I$62:$I$500,"<>수입",$I$62:$I$500,"<>저축") -> 0 | T10: =SUMIFS($K$62:$K$500,$H$62:$H$500,T9,$I$62:$I$500,"<>수입",$I$62:$I$500,"<>저축") -> 0 | U10: =SUMIFS($K$62:$K$500,$H$62:$H$500,U9,$I$62:$I$500,"<>수입",$I$62:$I$500,"<>저축") -> 53400 | V10: =SUMIFS($K$62:$K$500,$H$62:$H$500,V9,$I$62:$I$500,"<>수입",$I$62:$I$500,"<>저축") -> 106100 | W10: =SUMIFS($K$62:$K$500,$H$62:$H$500,W9,$I$62:$I$500,"<>수입",$I$62:$I$500,"<>저축") -> 126000 | X10: =SUMIFS($K$62:$K$500,$H$62:$H$500,X9,$I$62:$I$500,"<>수입",$I$62:$I$500,"<>저축") -> 16666 | Y10: =SUM(R10:X10) -> 302166 | AB10: =$H$33 -> 🐻고정비 | AC10: =$K$39 -> 212060 | AD10: =_xlfn.RANK.EQ(AC10,$AB$9:$AC$20,0) + ROW(AB2)/10000 -> 9.0002 | AE10: =SMALL($AD$9:$AD$20, ROW(AB2)) -> 2.0011 | AF10: =INDEX($AB$9:$AB$20,MATCH(AE10,$AD$9:$AD$20,0)) -> 🍪이벤트성 | AG10: =INDEX($AC$9:$AC$20,MATCH(AE10,$AD$9:$AD$20,0)) -> 2378146
C11: 항목 | D11: 금액 | E11: 🍪전통시장(제로페이) | F11: =SUMIFS($K$62:$K$500,$L$62:$L$500,E11,$I$62:$I$500,"<>수입",$I$62:$I$500,"<>저축") -> 21394 | R11: =R9 + 7 -> 45662 | S11: =S9 + 7 -> 45663 | T11: =T9 + 7 -> 45664 | U11: =U9 + 7 -> 45665 | V11: =V9 + 7 -> 45666 | W11: =W9 + 7 -> 45667 | X11: =X9 + 7 -> 45668 | AB11: =$H$41 -> 🍪생필품 | AC11: =$K$47 -> 456010 | AD11: =_xlfn.RANK.EQ(AC11,$AB$9:$AC$20,0) + ROW(AB3)/10000 -> 4.0003 | AE11: =SMALL($AD$9:$AD$20, ROW(AB3)) -> 3.0005 | AF11: =INDEX($AB$9:$AB$20,MATCH(AE11,$AD$9:$AD$20,0)) -> 🍪식비 | AG11: =INDEX($AC$9:$AC$20,MATCH(AE11,$AD$9:$AD$20,0)) -> 873552
C12: 총수입 | D12: =F33 -> 10192950 | E12: 🍪현대카드 | F12: =SUMIFS($K$62:$K$500,$L$62:$L$500,E12,$I$62:$I$500,"<>수입",$I$62:$I$500,"<>저축") -> 1524956 | R12: =SUMIFS($K$62:$K$500,$H$62:$H$500,R11,$I$62:$I$500,"<>수입",$I$62:$I$500,"<>저축") -> 83000 | S12: =SUMIFS($K$62:$K$500,$H$62:$H$500,S11,$I$62:$I$500,"<>수입",$I$62:$I$500,"<>저축") -> 97250 | T12: =SUMIFS($K$62:$K$500,$H$62:$H$500,T11,$I$62:$I$500,"<>수입",$I$62:$I$500,"<>저축") -> 74726 | U12: =SUMIFS($K$62:$K$500,$H$62:$H$500,U11,$I$62:$I$500,"<>수입",$I$62:$I$500,"<>저축") -> 183800 | V12: =SUMIFS($K$62:$K$500,$H$62:$H$500,V11,$I$62:$I$500,"<>수입",$I$62:$I$500,"<>저축") -> 147970 | W12: =SUMIFS($K$62:$K$500,$H$62:$H$500,W11,$I$62:$I$500,"<>수입",$I$62:$I$500,"<>저축") -> 989300 | X12: =SUMIFS($K$62:$K$500,$H$62:$H$500,X11,$I$62:$I$500,"<>수입",$I$62:$I$500,"<>저축") -> 167780 | Y12: =SUM(R12:X12) -> 1743826 | AB12: =$H$49 -> 🐻생필품 | AC12: =$K$55 -> 345480 | AD12: =_xlfn.RANK.EQ(AC12,$AB$9:$AC$20,0) + ROW(AB4)/10000 -> 5.0004 | AE12: =SMALL($AD$9:$AD$20, ROW(AB4)) -> 4.0003 | AF12: =INDEX($AB$9:$AB$20,MATCH(AE12,$AD$9:$AD$20,0)) -> 🍪생필품 | AG12: =INDEX($AC$9:$AC$20,MATCH(AE12,$AD$9:$AD$20,0)) -> 456010
E13: 🍪국민카드 | F13: =SUMIFS($K$62:$K$500,$L$62:$L$500,E13,$I$62:$I$500,"<>수입",$I$62:$I$500,"<>저축") -> 576222 | R13: =R11+7 -> 45669 | S13: =S11+7 -> 45670 | T13: =T11+7 -> 45671 | U13: =U11+7 -> 45672 | V13: =V11+7 -> 45673 | W13: =W11+7 -> 45674 | X13: =X11+7 -> 45675 | AB13: =$M$25 -> 🍪식비 | AC13: =$P$31 -> 873552 | AD13: =_xlfn.RANK.EQ(AC13,$AB$9:$AC$20,0) + ROW(AB5)/10000 -> 3.0005 | AE13: =SMALL($AD$9:$AD$20, ROW(AB5)) -> 5.0004 | AF13: =INDEX($AB$9:$AB$20,MATCH(AE13,$AD$9:$AD$20,0)) -> 🐻생필품 | AG13: =INDEX($AC$9:$AC$20,MATCH(AE13,$AD$9:$AD$20,0)) -> 345480
C14: 총지출 | D14: =SUM($K$31+$K$39+$K$47+$K$55+$P$31+$P$39+$P$47+$P$55+X31+X39+X47+X55) -> 7872976 | E14: 🍪기업카드 | F14: =SUMIFS($K$62:$K$500,$L$62:$L$500,E14,$I$62:$I$500,"<>수입",$I$62:$I$500,"<>저축") -> 0 | R14: =SUMIFS($K$62:$K$500,$H$62:$H$500,R13,$I$62:$I$500,"<>수입",$I$62:$I$500,"<>저축") -> 355800 | S14: =SUMIFS($K$62:$K$500,$H$62:$H$500,S13,$I$62:$I$500,"<>수입",$I$62:$I$500,"<>저축") -> 9000 | T14: =SUMIFS($K$62:$K$500,$H$62:$H$500,T13,$I$62:$I$500,"<>수입",$I$62:$I$500,"<>저축") -> 139920 | U14: =SUMIFS($K$62:$K$500,$H$62:$H$500,U13,$I$62:$I$500,"<>수입",$I$62:$I$500,"<>저축") -> 3729220 | V14: =SUMIFS($K$62:$K$500,$H$62:$H$500,V13,$I$62:$I$500,"<>수입",$I$62:$I$500,"<>저축") -> 132002 | W14: =SUMIFS($K$62:$K$500,$H$62:$H$500,W13,$I$62:$I$500,"<>수입",$I$62:$I$500,"<>저축") -> 290270 | X14: =SUMIFS($K$62:$K$500,$H$62:$H$500,X13,$I$62:$I$500,"<>수입",$I$62:$I$500,"<>저축") -> 69750 | Y14: =SUM(R14:X14) -> 4725962 | AB14: =$M$33 -> 🐻식비 | AC14: =$P$39 -> 224700 | AD14: =_xlfn.RANK.EQ(AC14,$AB$9:$AC$20,0) + ROW(AB6)/10000 -> 8.0006 | AE14: =SMALL($AD$9:$AD$20, ROW(AB6)) -> 6.0001 | AF14: =INDEX($AB$9:$AB$20,MATCH(AE14,$AD$9:$AD$20,0)) -> 🍪고정비 | AG14: =INDEX($AC$9:$AC$20,MATCH(AE14,$AD$9:$AD$20,0)) -> 297392
E15: 🍪하나카드 | F15: =SUMIFS($K$62:$K$500,$L$62:$L$500,E15,$I$62:$I$500,"<>수입",$I$62:$I$500,"<>저축") -> 0 | R15: =R13+7 -> 45676 | S15: =S13+7 -> 45677 | T15: =T13+7 -> 45678 | U15: =U13+7 -> 45679 | V15: =V13+7 -> 45680 | W15: =W13+7 -> 45681 | X15: =X13+7 -> 45682 | AB15: =$M$41 -> 🍪여가비 | AC15: =$P$47 -> 292090 | AD15: =_xlfn.RANK.EQ(AC15,$AB$9:$AC$20,0) + ROW(AB7)/10000 -> 7.0007 | AE15: =SMALL($AD$9:$AD$20, ROW(AB7)) -> 7.0007 | AF15: =INDEX($AB$9:$AB$20,MATCH(AE15,$AD$9:$AD$20,0)) -> 🍪여가비 | AG15: =INDEX($AC$9:$AC$20,MATCH(AE15,$AD$9:$AD$20,0)) -> 292090
C16: 총저축 | D16: =F43 -> 3200000 | E16: 🐻체크카드(현영) | F16: =SUMIFS($K$62:$K$500,$L$62:$L$500,E16,$I$62:$I$500,"<>수입",$I$62:$I$500,"<>저축") -> 131890 | H16: 이벤트 | R16: =SUMIFS($K$62:$K$500,$H$62:$H$500,R15,$I$62:$I$500,"<>수입",$I$62:$I$500,"<>저축") -> 308740 | S16: =SUMIFS($K$62:$K$500,$H$62:$H$500,S15,$I$62:$I$500,"<>수입",$I$62:$I$500,"<>저축") -> 118800 | T16: =SUMIFS($K$62:$K$500,$H$62:$H$500,T15,$I$62:$I$500,"<>수입",$I$62:$I$500,"<>저축") -> 12000 | U16: =SUMIFS($K$62:$K$500,$H$62:$H$500,U15,$I$62:$I$500,"<>수입",$I$62:$I$500,"<>저축") -> 156420 | V16: =SUMIFS($K$62:$K$500,$H$62:$H$500,V15,$I$62:$I$500,"<>수입",$I$62:$I$500,"<>저축") -> 119300 | W16: =SUMIFS($K$62:$K$500,$H$62:$H$500,W15,$I$62:$I$500,"<>수입",$I$62:$I$500,"<>저축") -> 197832 | X16: =SUMIFS($K$62:$K$500,$H$62:$H$500,X15,$I$62:$I$500,"<>수입",$I$62:$I$500,"<>저축") -> 114900 | Y16: =SUM(R16:X16) -> 1027992 | AB16: =$M$49 -> 🐻여가비 | AC16: =$P$55 -> 54336 | AD16: =_xlfn.RANK.EQ(AC16,$AB$9:$AC$20,0) + ROW(AB8)/10000 -> 12.0008 | AE16: =SMALL($AD$9:$AD$20, ROW(AB8)) -> 8.0006 | AF16: =INDEX($AB$9:$AB$20,MATCH(AE16,$AD$9:$AD$20,0)) -> 🐻식비 | AG16: =INDEX($AC$9:$AC$20,MATCH(AE16,$AD$9:$AD$20,0)) -> 224700
E17: 🐻현금/이체 | F17: =SUMIFS($K$62:$K$500,$L$62:$L$500,E17,$I$62:$I$500,"<>수입",$I$62:$I$500,"<>저축") -> 2346620 | R17: =R15+7 -> 45683 | S17: =S15+7 -> 45684 | T17: =T15+7 -> 45685 | U17: =U15+7 -> 45686 | V17: =V15+7 -> 45687 | W17: =W15+7 -> 45688 | X17: =X15+7 -> 45689 | AB17: =$R$25 -> 🍪기타 | AC17: =$X$31 -> 188260 | AD17: =_xlfn.RANK.EQ(AC17,$AB$9:$AC$20,0) + ROW(AB9)/10000 -> 10.0009 | AE17: =SMALL($AD$9:$AD$20, ROW(AB9)) -> 9.0002 | AF17: =INDEX($AB$9:$AB$20,MATCH(AE17,$AD$9:$AD$20,0)) -> 🐻고정비 | AG17: =INDEX($AC$9:$AC$20,MATCH(AE17,$AD$9:$AD$20,0)) -> 212060
C18: 잉여현금 | D18: =D12-D14-D16 -> -880026 | E18: 🐻전통시장(제로페이) | F18: =SUMIFS($K$62:$K$500,$L$62:$L$500,E18,$I$62:$I$500,"<>수입",$I$62:$I$500,"<>저축") -> 26500 | R18: =SUMIFS($K$62:$K$500,$H$62:$H$500,R17,$I$62:$I$500,"<>수입",$I$62:$I$500,"<>저축") -> 20500 | S18: =SUMIFS($K$62:$K$500,$H$62:$H$500,S17,$I$62:$I$500,"<>수입",$I$62:$I$500,"<>저축") -> 160352 | T18: =SUMIFS($K$62:$K$500,$H$62:$H$500,T17,$I$62:$I$500,"<>수입",$I$62:$I$500,"<>저축") -> 557894 | U18: =SUMIFS($K$62:$K$500,$H$62:$H$500,U17,$I$62:$I$500,"<>수입",$I$62:$I$500,"<>저축") -> 79084 | V18: =SUMIFS($K$62:$K$500,$H$62:$H$500,V17,$I$62:$I$500,"<>수입",$I$62:$I$500,"<>저축") -> 86650 | W18: =SUMIFS($K$62:$K$500,$H$62:$H$500,W17,$I$62:$I$500,"<>수입",$I$62:$I$500,"<>저축") -> 135650 | X18: =SUMIFS($K$62:$K$500,$H$62:$H$500,X17,$I$62:$I$500,"<>수입",$I$62:$I$500,"<>저축") -> 0 | Y18: =SUM(R18:X18) -> 1040130 | AB18: =$R$33 -> 🐻기타 | AC18: =$X$39 -> 112010 | AD18: =_xlfn.RANK.EQ(AC18,$AB$9:$AC$20,0) + ROW(AB10)/10000 -> 11.001 | AE18: =SMALL($AD$9:$AD$20, ROW(AB10)) -> 10.0009 | AF18: =INDEX($AB$9:$AB$20,MATCH(AE18,$AD$9:$AD$20,0)) -> 🍪기타 | AG18: =INDEX($AC$9:$AC$20,MATCH(AE18,$AD$9:$AD$20,0)) -> 188260
C19: 총저축률 | D19: =(D16+D18)/D12 -> 0.22760575 | E19: 🐻하나카드 | F19: =SUMIFS($K$62:$K$500,$L$62:$L$500,E19,$I$62:$I$500,"<>수입",$I$62:$I$500,"<>저축") -> 904216 | R19: =R17+7 -> 45690 | S19: =S17+7 -> 45691 | T19: =T17+7 -> 45692 | U19: =U17+7 -> 45693 | V19: =V17+7 -> 45694 | W19: =W17+7 -> 45695 | X19: =X17+7 -> 45696 | AB19: =$R$41 -> 🍪이벤트성 | AC19: =$X$47 -> 2378146 | AD19: =_xlfn.RANK.EQ(AC19,$AB$9:$AC$20,0) + ROW(AB11)/10000 -> 2.0011 | AE19: =SMALL($AD$9:$AD$20, ROW(AB11)) -> 11.001 | AF19: =INDEX($AB$9:$AB$20,MATCH(AE19,$AD$9:$AD$20,0)) -> 🐻기타 | AG19: =INDEX($AC$9:$AC$20,MATCH(AE19,$AD$9:$AD$20,0)) -> 112010
C20: 현금저축률 | D20: =D18/D12 -> -0.086336733 | E20: 🐻현백카드 | F20: =SUM($F$14:$F$19) -> 3409226 | R20: =SUMIFS($K$62:$K$500,$H$62:$H$500,R19,$I$62:$I$500,"<>수입",$I$62:$I$500,"<>저축") -> 0 | S20: =SUMIFS($K$62:$K$500,$H$62:$H$500,S19,$I$62:$I$500,"<>수입",$I$62:$I$500,"<>저축") -> 0 | T20: =SUMIFS($K$62:$K$500,$H$62:$H$500,T19,$I$62:$I$500,"<>수입",$I$62:$I$500,"<>저축") -> 0 | U20: =SUMIFS($K$62:$K$500,$H$62:$H$500,U19,$I$62:$I$500,"<>수입",$I$62:$I$500,"<>저축") -> 0 | V20: =SUMIFS($K$62:$K$500,$H$62:$H$500,V19,$I$62:$I$500,"<>수입",$I$62:$I$500,"<>저축") -> 0 | W20: =SUMIFS($K$62:$K$500,$H$62:$H$500,W19,$I$62:$I$500,"<>수입",$I$62:$I$500,"<>저축") -> 0 | X20: =SUMIFS($K$62:$K$500,$H$62:$H$500,X19,$I$62:$I$500,"<>수입",$I$62:$I$500,"<>저축") -> 0 | Y20: =SUM(R20:X20) -> 0 | AB20: =$R$49 -> 🐻 이벤트성 | AC20: =$X$55 -> 2438940 | AD20: =_xlfn.RANK.EQ(AC20,$AB$9:$AC$20,0) + ROW(AB12)/10000 -> 1.0012 | AE20: =SMALL($AD$9:$AD$20, ROW(AB12)) -> 12.0008 | AF20: =INDEX($AB$9:$AB$20,MATCH(AE20,$AD$9:$AD$20,0)) -> 🐻여가비 | AG20: =INDEX($AC$9:$AC$20,MATCH(AE20,$AD$9:$AD$20,0)) -> 54336
E21: 🐻국민카드
C24: 대분류 | D24: 소분류 | E24: 목표 | F24: 합계 | H24: 대분류 | I24: 소분류 | J24: 예산 | K24: 합계 | M24: 대분류 | N24: 소분류 | O24: 예산 | P24: 합계 | R24: 대분류 | T24: 소분류 | V24: 예산 | X24: 합계
C25: 수입 | D25: 🍪 월급 | F25: =SUMIFS($K$62:$K$500,$I$62:$I$500,$C$25,$J$62:$J$500,D25) -> 3257030 | H25: 🍪고정비 | I25: 관리비 | K25: =SUMIFS($K$62:$K$500,$I$62:$I$500,$H$25,$J$62:$J$500,I25) -> 0 | M25: 🍪식비 | N25: 식재료비 | P25: =SUMIFS($K$62:$K$500,$I$62:$I$500,$M$25,$J$62:$J$500,N25) -> 437790 | R25: 🍪기타 | T25: 약국 | X25: =SUMIFS($K$62:$K$500,$I$62:$I$500,$R$25,$J$62:$J$500,T25) -> 0
D26: 🍪 부수입 | F26: =SUMIFS($K$62:$K$500,$I$62:$I$500,$C$25,$J$62:$J$500,D26) -> 345000 | I26: 월세 | K26: =SUMIFS($K$62:$K$500,$I$62:$I$500,$H$25,$J$62:$J$500,I26) -> 0 | N26: 회사점심 | P26: =SUMIFS($K$62:$K$500,$I$62:$I$500,$M$25,$J$62:$J$500,N26) -> 46600 | T26: 병원비 | X26: =SUMIFS($K$62:$K$500,$I$62:$I$500,$R$25,$J$62:$J$500,T26) -> 120010
D27: 🐻 월급 | F27: =SUMIFS($K$62:$K$500,$I$62:$I$500,$C$25,$J$62:$J$500,D27) -> 4310870 | I27: 대출이자 | K27: =SUMIFS($K$62:$K$500,$I$62:$I$500,$H$25,$J$62:$J$500,I27) -> 177832 | N27: 간식/카페 | P27: =SUMIFS($K$62:$K$500,$I$62:$I$500,$M$25,$J$62:$J$500,N27) -> 61400 | T27: 영양제 | X27: =SUMIFS($K$62:$K$500,$I$62:$I$500,$R$25,$J$62:$J$500,T27) -> 0
D28: 🐻 부수입 | F28: =SUMIFS($K$62:$K$500,$I$62:$I$500,$C$25,$J$62:$J$500,D28) -> 0 | I28: 통신비 | K28: =SUMIFS($K$62:$K$500,$I$62:$I$500,$H$25,$J$62:$J$500,I28) -> 119560 | N28: 외식/배달 | P28: =SUMIFS($K$62:$K$500,$I$62:$I$500,$M$25,$J$62:$J$500,N28) -> 327762 | T28: 교통비 | X28: =SUMIFS($K$62:$K$500,$I$62:$I$500,$R$25,$J$62:$J$500,T28) -> 18250
D29: 기타 | F29: =SUMIFS($K$62:$K$500,$I$62:$I$500,$C$25,$J$62:$J$500,D29) -> 2280050 | I29: 보험료 | K29: =SUMIFS($K$62:$K$500,$I$62:$I$500,$H$25,$J$62:$J$500,I29) -> 0 | N29: 기타 | P29: =SUMIFS($K$62:$K$500,$I$62:$I$500,$M$25,$J$62:$J$500,N29) -> 0 | T29: 주유비 | X29: =SUMIFS($K$62:$K$500,$I$62:$I$500,$R$25,$J$62:$J$500,T29) -> 50000
F30: =SUMIFS($K$62:$K$500,$I$62:$I$500,$C$25,$J$62:$J$500,D30) -> 0 | K30: =SUMIFS($K$62:$K$500,$I$62:$I$500,$H$25,$J$62:$J$500,I30) -> 0 | P30: =SUMIFS($K$62:$K$500,$I$62:$I$500,$M$25,$J$62:$J$500,N30) -> 0 | X30: =SUMIFS($K$62:$K$500,$I$62:$I$500,$R$25,$J$62:$J$500,T30) -> 0
F31: =SUMIFS($K$62:$K$500,$I$62:$I$500,$C$25,$J$62:$J$500,D31) -> 0 | H31: =IF(H25=0,"","총"&H25) -> 총🍪고정비 | K31: =SUM(K25:K30) -> 297392 | M31: =IF(M25=0,"","총"&M25) -> 총🍪식비 | P31: =SUM(P25:P30) -> 873552 | R31: =IF(R25=0,"","총"&R25) -> 총🍪기타 | X31: =SUM(X25:X30) -> 188260
F32: =SUMIFS($K$62:$K$500,$I$62:$I$500,$C$25,$J$62:$J$500,D32) -> 0 | K32: =K31-J25 -> 297392 | P32: =P31-O25 -> 873552 | X32: =X31-V25 -> 188260
C33: =IF(C25=0,"","총"&C25) -> 총수입 | F33: =SUM(F25:F32) -> 10192950 | H33: 🐻고정비 | I33: 관리비 | K33: =SUMIFS($K$62:$K$500,$I$62:$I$500,$H$33,$J$62:$J$500,I33) -> 0 | M33: 🐻식비 | N33: 식재료비 | P33: =SUMIFS($K$62:$K$500,$I$62:$I$500,$M$33,$J$62:$J$500,N33) -> 20000 | R33: 🐻기타 | T33: 약국 | X33: =SUMIFS($K$62:$K$500,$I$62:$I$500,$R$33,$J$62:$J$500,T33) -> 0
F34: =F33-E25 -> 10192950 | I34: 대출이자 | K34: =SUMIFS($K$62:$K$500,$I$62:$I$500,$H$33,$J$62:$J$500,I34) -> 0 | N34: 회사점심 | P34: =SUMIFS($K$62:$K$500,$I$62:$I$500,$M$33,$J$62:$J$500,N34) -> 140900 | T34: 병원비 | X34: =SUMIFS($K$62:$K$500,$I$62:$I$500,$R$33,$J$62:$J$500,T34) -> 62010
C35: 저축 | D35: 주택청약 | F35: =SUMIFS($K$62:$K$500,$I$62:$I$500,$C$35,$J$62:$J$500,D35) -> 0 | I35: 통신비 | K35: =SUMIFS($K$62:$K$500,$I$62:$I$500,$H$33,$J$62:$J$500,I35) -> 44050 | N35: 간식/카페 | P35: =SUMIFS($K$62:$K$500,$I$62:$I$500,$M$33,$J$62:$J$500,N35) -> 43800 | T35: 영양제 | X35: =SUMIFS($K$62:$K$500,$I$62:$I$500,$R$33,$J$62:$J$500,T35) -> 0
D36: 우리은행 | F36: =SUMIFS($K$62:$K$500,$I$62:$I$500,$C$35,$J$62:$J$500,D36) -> 0 | I36: 보험료 | K36: =SUMIFS($K$62:$K$500,$I$62:$I$500,$H$33,$J$62:$J$500,I36) -> 88010 | N36: 외식/배달 | P36: =SUMIFS($K$62:$K$500,$I$62:$I$500,$M$33,$J$62:$J$500,N36) -> 20000 | T36: 교통비 | X36: =SUMIFS($K$62:$K$500,$I$62:$I$500,$R$33,$J$62:$J$500,T36) -> 0
D37: 케이뱅크 | F37: =SUMIFS($K$62:$K$500,$I$62:$I$500,$C$35,$J$62:$J$500,D37) -> 3000000 | I37: 곗돈 | K37: =SUMIFS($K$62:$K$500,$I$62:$I$500,$H$33,$J$62:$J$500,I37) -> 80000 | N37: 기타 | P37: =SUMIFS($K$62:$K$500,$I$62:$I$500,$M$33,$J$62:$J$500,N37) -> 0 | T37: 주유비 | X37: =SUMIFS($K$62:$K$500,$I$62:$I$500,$R$33,$J$62:$J$500,T37) -> 50000
D38: 연금저축 | F38: =SUMIFS($K$62:$K$500,$I$62:$I$500,$C$35,$J$62:$J$500,D38) -> 200000 | K38: =SUMIFS($K$62:$K$500,$I$62:$I$500,$H$33,$J$62:$J$500,I38) -> 0 | P38: =SUMIFS($K$62:$K$500,$I$62:$I$500,$M$33,$J$62:$J$500,N38) -> 0 | X38: =SUMIFS($K$62:$K$500,$I$62:$I$500,$R$33,$J$62:$J$500,T38) -> 0
F39: =SUMIFS($K$62:$K$500,$I$62:$I$500,$C$35,$J$62:$J$500,D39) -> 0 | H39: =IF(H33=0,"","총"&H33) -> 총🐻고정비 | K39: =SUM(K33:K38) -> 212060 | M39: =IF(M33=0,"","총"&M33) -> 총🐻식비 | P39: =SUM(P33:P38) -> 224700 | R39: =IF(R33=0,"","총"&R33) -> 총🐻기타 | X39: =SUM(X33:X38) -> 112010
F40: =SUMIFS($K$62:$K$500,$I$62:$I$500,$C$35,$J$62:$J$500,D40) -> 0 | K40: =K39-J33 -> 212060 | P40: =P39-O33 -> 224700 | X40: =X39-V33 -> 112010
F41: =SUMIFS($K$62:$K$500,$I$62:$I$500,$C$35,$J$62:$J$500,D41) -> 0 | H41: 🍪생필품 | I41: 주방/욕실 | K41: =SUMIFS($K$62:$K$500,$I$62:$I$500,$H$41,$J$62:$J$500,I41) -> 360370 | M41: 🍪여가비 | N41: 의류/잡화 | P41: =SUMIFS($K$62:$K$500,$I$62:$I$500,$M$41,$J$62:$J$500,N41) -> 154900 | R41: 🍪이벤트성 | T41: 축의/부의금 | X41: =SUMIFS($K$62:$K$500,$I$62:$I$500,$R$41,$J$62:$J$500,T41) -> 50000
F42: =SUMIFS($K$62:$K$500,$I$62:$I$500,$C$35,$J$62:$J$500,D42) -> 0 | I42: 소모품 | K42: =SUMIFS($K$62:$K$500,$I$62:$I$500,$H$41,$J$62:$J$500,I42) -> 57560 | N42: OTT | P42: =SUMIFS($K$62:$K$500,$I$62:$I$500,$M$41,$J$62:$J$500,N42) -> 13390 | T42: 생신/생일선물 | X42: =SUMIFS($K$62:$K$500,$I$62:$I$500,$R$41,$J$62:$J$500,T42) -> 51666
C43: =IF(C35=0,"","총"&C25) -> 총수입 | F43: =SUM(F35:F42) -> 3200000 | I43: 기타 | K43: =SUMIFS($K$62:$K$500,$I$62:$I$500,$H$41,$J$62:$J$500,I43) -> 38080 | N43: 문화생활 | P43: =SUMIFS($K$62:$K$500,$I$62:$I$500,$M$41,$J$62:$J$500,N43) -> 0 | T43: 명절/어버이날 | X43: =SUMIFS($K$62:$K$500,$I$62:$I$500,$R$41,$J$62:$J$500,T43) -> 0
F44: =F43-E35 -> 3200000 | K44: =SUMIFS($K$62:$K$500,$I$62:$I$500,$H$41,$J$62:$J$500,I44) -> 0 | N44: 자기계발 | P44: =SUMIFS($K$62:$K$500,$I$62:$I$500,$M$41,$J$62:$J$500,N44) -> 0 | T44: 여행 | X44: =SUMIFS($K$62:$K$500,$I$62:$I$500,$R$41,$J$62:$J$500,T44) -> 0
K45: =SUMIFS($K$62:$K$500,$I$62:$I$500,$H$41,$J$62:$J$500,I45) -> 0 | N45: 미용 | P45: =SUMIFS($K$62:$K$500,$I$62:$I$500,$M$41,$J$62:$J$500,N45) -> 123800 | T45: 기타 | X45: =SUMIFS($K$62:$K$500,$I$62:$I$500,$R$41,$J$62:$J$500,T45) -> 2276480
K46: =SUMIFS($K$62:$K$500,$I$62:$I$500,$H$41,$J$62:$J$500,I46) -> 0 | P46: =SUMIFS($K$62:$K$500,$I$62:$I$500,$M$41,$J$62:$J$500,N46) -> 0 | T46: 출산 | X46: =SUMIFS($K$62:$K$500,$I$62:$I$500,$R$41,$J$62:$J$500,T46) -> 0
H47: =IF(H41=0,"","총"&H41) -> 총🍪생필품 | K47: =SUM(K41:K46) -> 456010 | M47: =IF(M41=0,"","총"&M41) -> 총🍪여가비 | P47: =SUM(P41:P46) -> 292090 | R47: =IF(R41=0,"","총"&R41) -> 총🍪이벤트성 | X47: =SUM(X41:X46) -> 2378146
K48: =K47-J41 -> 456010 | P48: =P47-O41 -> 292090 | X48: =X47-V41 -> 2378146
...

Sheet 2월
C3: 2025 | D3: 2
E8: 결제수단 | F8: 금액 | R8: S | S8: M | T8: T | U8: W | V8: T | W8: F | X8: S | Y8: 누적 | AB8: 대분류 | AC8: 합계
E9: 🍪체크카드(현영) | F9: =SUMIFS($K$62:$K$500,$L$62:$L$500,E9,$I$62:$I$500,"<>수입",$I$62:$I$500,"<>저축") -> 0 | R9: =DATE($C$3,$D$3,1)-WEEKDAY(DATE($C$3,$D$3,1))+1 -> 45683 | S9: =R9 + 1 -> 45684 | T9: =S9 + 1 -> 45685 | U9: =T9 + 1 -> 45686 | V9: =U9 + 1 -> 45687 | W9: =V9 + 1 -> 45688 | X9: =W9 + 1 -> 45689 | AB9: =$H$25 -> 🍪고정비 | AC9: =$K$31 -> 2155212 | AD9: =_xlfn.RANK.EQ(AC9,$AB$9:$AC$20,0) + ROW(AB1)/10000 -> 2.0001 | AE9: =SMALL($AD$9:$AD$20, ROW(AB1)) -> 1.0011 | AF9: =INDEX($AB$9:$AB$20,MATCH(AE9,$AD$9:$AD$20,0)) -> 🍪이벤트성 | AG9: =INDEX($AC$9:$AC$20,MATCH(AE9,$AD$9:$AD$20,0)) -> 42387013
E10: 🍪현금/이체 | F10: =SUMIFS($K$62:$K$500,$L$62:$L$500,E10,$I$62:$I$500,"<>수입",$I$62:$I$500,"<>저축") -> 1129143 | R10: =SUMIFS($K$62:$K$500,$H$62:$H$500,R9,$I$62:$I$500,"<>수입",$I$62:$I$500,"<>저축") -> 0 | S10: =SUMIFS($K$62:$K$500,$H$62:$H$500,S9,$I$62:$I$500,"<>수입",$I$62:$I$500,"<>저축") -> 0 | T10: =SUMIFS($K$62:$K$500,$H$62:$H$500,T9,$I$62:$I$500,"<>수입",$I$62:$I$500,"<>저축") -> 0 | U10: =SUMIFS($K$62:$K$500,$H$62:$H$500,U9,$I$62:$I$500,"<>수입",$I$62:$I$500,"<>저축") -> 0 | V10: =SUMIFS($K$62:$K$500,$H$62:$H$500,V9,$I$62:$I$500,"<>수입",$I$62:$I$500,"<>저축") -> 0 | W10: =SUMIFS($K$62:$K$500,$H$62:$H$500,W9,$I$62:$I$500,"<>수입",$I$62:$I$500,"<>저축") -> 0 | X10: =SUMIFS($K$62:$K$500,$H$62:$H$500,X9,$I$62:$I$500,"<>수입",$I$62:$I$500,"<>저축") -> 213490 | Y10: =SUM(R10:X10) -> 213490 | AB10: =$H$33 -> 🐻고정비 | AC10: =$K$39 -> 694550 | AD10: =_xlfn.RANK.EQ(AC10,$AB$9:$AC$20,0) + ROW(AB2)/10000 -> 5.0002 | AE10: =SMALL($AD$9:$AD$20, ROW(AB2)) -> 2.0001 | AF10: =INDEX($AB$9:$AB$20,MATCH(AE10,$AD$9:$AD$20,0)) -> 🍪고정비 | AG10: =INDEX($AC$9:$AC$20,MATCH(AE10,$AD$9:$AD$20,0)) -> 2155212
C11: 항목 | D11: 금액 | E11: 🍪전통시장(제로페이) | F11: =SUMIFS($K$62:$K$500,$L$62:$L$500,E11,$I$62:$I$500,"<>수입",$I$62:$I$500,"<>저축") -> 0 | R11: =R9 + 7 -> 45690 | S11: =S9 + 7 -> 45691 | T11: =T9 + 7 -> 45692 | U11: =U9 + 7 -> 45693 | V11: =V9 + 7 -> 45694 | W11: =W9 + 7 -> 45695 | X11: =X9 + 7 -> 45696 | AB11: =$H$41 -> 🍪생필품 | AC11: =$K$47 -> 284480 | AD11: =_xlfn.RANK.EQ(AC11,$AB$9:$AC$20,0) + ROW(AB3)/10000 -> 8.0003 | AE11: =SMALL($AD$9:$AD$20, ROW(AB3)) -> 3.0008 | AF11: =INDEX($AB$9:$AB$20,MATCH(AE11,$AD$9:$AD$20,0)) -> 🐻여가비 | AG11: =INDEX($AC$9:$AC$20,MATCH(AE11,$AD$9:$AD$20,0)) -> 1364967
C12: 총수입 | D12: =F33 -> 5488395 | E12: 🍪현대카드 | F12: =SUMIFS($K$62:$K$500,$L$62:$L$500,E12,$I$62:$I$500,"<>수입",$I$62:$I$500,"<>저축") -> 1487200 | R12: =SUMIFS($K$62:$K$500,$H$62:$H$500,R11,$I$62:$I$500,"<>수입",$I$62:$I$500,"<>저축") -> 68920 | S12: =SUMIFS($K$62:$K$500,$H$62:$H$500,S11,$I$62:$I$500,"<>수입",$I$62:$I$500,"<>저축") -> 19200 | T12: =SUMIFS($K$62:$K$500,$H$62:$H$500,T11,$I$62:$I$500,"<>수입",$I$62:$I$500,"<>저축") -> 38575843 | U12: =SUMIFS($K$62:$K$500,$H$62:$H$500,U11,$I$62:$I$500,"<>수입",$I$62:$I$500,"<>저축") -> 1367170 | V12: =SUMIFS($K$62:$K$500,$H$62:$H$500,V11,$I$62:$I$500,"<>수입",$I$62:$I$500,"<>저축") -> 22400 | W12: =SUMIFS($K$62:$K$500,$H$62:$H$500,W11,$I$62:$I$500,"<>수입",$I$62:$I$500,"<>저축") -> 440400 | X12: =SUMIFS($K$62:$K$500,$H$62:$H$500,X11,$I$62:$I$500,"<>수입",$I$62:$I$500,"<>저축") -> 3692090 | Y12: =SUM(R12:X12) -> 44186023 | AB12: =$H$49 -> 🐻생필품 | AC12: =$K$55 -> 333748 | AD12: =_xlfn.RANK.EQ(AC12,$AB$9:$AC$20,0) + ROW(AB4)/10000 -> 7.0004 | AE12: =SMALL($AD$9:$AD$20, ROW(AB4)) -> 4.0005 | AF12: =INDEX($AB$9:$AB$20,MATCH(AE12,$AD$9:$AD$20,0)) -> 🍪식비 | AG12: =INDEX($AC$9:$AC$20,MATCH(AE12,$AD$9:$AD$20,0)) -> 984951
E13: 🍪국민카드 | F13: =SUMIFS($K$62:$K$500,$L$62:$L$500,E13,$I$62:$I$500,"<>수입",$I$62:$I$500,"<>저축") -> 839200 | R13: =R11+7 -> 45697 | S13: =S11+7 -> 45698 | T13: =T11+7 -> 45699 | U13: =U11+7 -> 45700 | V13: =V11+7 -> 45701 | W13: =W11+7 -> 45702 | X13: =X11+7 -> 45703 | AB13: =$M$25 -> 🍪식비 | AC13: =$P$31 -> 984951 | AD13: =_xlfn.RANK.EQ(AC13,$AB$9:$AC$20,0) + ROW(AB5)/10000 -> 4.0005 | AE13: =SMALL($AD$9:$AD$20, ROW(AB5)) -> 5.0002 | AF13: =INDEX($AB$9:$AB$20,MATCH(AE13,$AD$9:$AD$20,0)) -> 🐻고정비 | AG13: =INDEX($AC$9:$AC$20,MATCH(AE13,$AD$9:$AD$20,0)) -> 694550
C14: 총지출 | D14: =SUM($K$31+$K$39+$K$47+$K$55+$P$31+$P$39+$P$47+$P$55+X31+X39+X47+X55) -> 49045021 | E14: 🍪기업카드 | F14: =SUMIFS($K$62:$K$500,$L$62:$L$500,E14,$I$62:$I$500,"<>수입",$I$62:$I$500,"<>저축") -> 322280 | R14: =SUMIFS($K$62:$K$500,$H$62:$H$500,R13,$I$62:$I$500,"<>수입",$I$62:$I$500,"<>저축") -> 0 | S14: =SUMIFS($K$62:$K$500,$H$62:$H$500,S13,$I$62:$I$500,"<>수입",$I$62:$I$500,"<>저축") -> 244550 | T14: =SUMIFS($K$62:$K$500,$H$62:$H$500,T13,$I$62:$I$500,"<>수입",$I$62:$I$500,"<>저축") -> 0 | U14: =SUMIFS($K$62:$K$500,$H$62:$H$500,U13,$I$62:$I$500,"<>수입",$I$62:$I$500,"<>저축") -> 42600 | V14: =SUMIFS($K$62:$K$500,$H$62:$H$500,V13,$I$62:$I$500,"<>수입",$I$62:$I$500,"<>저축") -> 305380 | W14: =SUMIFS($K$62:$K$500,$H$62:$H$500,W13,$I$62:$I$500,"<>수입",$I$62:$I$500,"<>저축") -> 253200 | X14: =SUMIFS($K$62:$K$500,$H$62:$H$500,X13,$I$62:$I$500,"<>수입",$I$62:$I$500,"<>저축") -> 179200 | Y14: =SUM(R14:X14) -> 1024930 | AB14: =$M$33 -> 🐻식비 | AC14: =$P$39 -> 140200 | AD14: =_xlfn.RANK.EQ(AC14,$AB$9:$AC$20,0) + ROW(AB6)/10000 -> 10.0006 | AE14: =SMALL($AD$9:$AD$20, ROW(AB6)) -> 6.0012 | AF14: =INDEX($AB$9:$AB$20,MATCH(AE14,$AD$9:$AD$20,0)) -> 🐻 이벤트성 | AG14: =INDEX($AC$9:$AC$20,MATCH(AE14,$AD$9:$AD$20,0)) -> 409700
E15: 🍪하나카드 | F15: =SUMIFS($K$62:$K$500,$L$62:$L$500,E15,$I$62:$I$500,"<>수입",$I$62:$I$500,"<>저축") -> 0 | R15: =R13+7 -> 45704 | S15: =S13+7 -> 45705 | T15: =T13+7 -> 45706 | U15: =U13+7 -> 45707 | V15: =V13+7 -> 45708 | W15: =W13+7 -> 45709 | X15: =X13+7 -> 45710 | AB15: =$M$41 -> 🍪여가비 | AC15: =$P$47 -> 84920 | AD15: =_xlfn.RANK.EQ(AC15,$AB$9:$AC$20,0) + ROW(AB7)/10000 -> 11.0007 | AE15: =SMALL($AD$9:$AD$20, ROW(AB7)) -> 7.0004 | AF15: =INDEX($AB$9:$AB$20,MATCH(AE15,$AD$9:$AD$20,0)) -> 🐻생필품 | AG15: =INDEX($AC$9:$AC$20,MATCH(AE15,$AD$9:$AD$20,0)) -> 333748
C16: 총저축 | D16: =F43 -> 0 | E16: 🐻체크카드(현영) | F16: =SUMIFS($K$62:$K$500,$L$62:$L$500,E16,$I$62:$I$500,"<>수입",$I$62:$I$500,"<>저축") -> 1187680 | H16: 이벤트 | R16: =SUMIFS($K$62:$K$500,$H$62:$H$500,R15,$I$62:$I$500,"<>수입",$I$62:$I$500,"<>저축") -> 3000 | S16: =SUMIFS($K$62:$K$500,$H$62:$H$500,S15,$I$62:$I$500,"<>수입",$I$62:$I$500,"<>저축") -> 908050 | T16: =SUMIFS($K$62:$K$500,$H$62:$H$500,T15,$I$62:$I$500,"<>수입",$I$62:$I$500,"<>저축") -> 109781 | U16: =SUMIFS($K$62:$K$500,$H$62:$H$500,U15,$I$62:$I$500,"<>수입",$I$62:$I$500,"<>저축") -> 367808 | V16: =SUMIFS($K$62:$K$500,$H$62:$H$500,V15,$I$62:$I$500,"<>수입",$I$62:$I$500,"<>저축") -> 93600 | W16: =SUMIFS($K$62:$K$500,$H$62:$H$500,W15,$I$62:$I$500,"<>수입",$I$62:$I$500,"<>저축") -> 283760 | X16: =SUMIFS($K$62:$K$500,$H$62:$H$500,X15,$I$62:$I$500,"<>수입",$I$62:$I$500,"<>저축") -> 768930 | Y16: =SUM(R16:X16) -> 2534929 | AB16: =$M$49 -> 🐻여가비 | AC16: =$P$55 -> 1364967 | AD16: =_xlfn.RANK.EQ(AC16,$AB$9:$AC$20,0) + ROW(AB8)/10000 -> 3.0008 | AE16: =SMALL($AD$9:$AD$20, ROW(AB8)) -> 8.0003 | AF16: =INDEX($AB$9:$AB$20,MATCH(AE16,$AD$9:$AD$20,0)) -> 🍪생필품 | AG16: =INDEX($AC$9:$AC$20,MATCH(AE16,$AD$9:$AD$20,0)) -> 284480
E17: 🐻현금/이체 | F17: =SUMIFS($K$62:$K$500,$L$62:$L$500,E17,$I$62:$I$500,"<>수입",$I$62:$I$500,"<>저축") -> 627500 | H17: 차량구매 | R17: =R15+7 -> 45711 | S17: =S15+7 -> 45712 | T17: =T15+7 -> 45713 | U17: =U15+7 -> 45714 | V17: =V15+7 -> 45715 | W17: =W15+7 -> 45716 | X17: =X15+7 -> 45717 | AB17: =$R$25 -> 🍪기타 | AC17: =$X$31 -> 36080 | AD17: =_xlfn.RANK.EQ(AC17,$AB$9:$AC$20,0) + ROW(AB9)/10000 -> 12.0009 | AE17: =SMALL($AD$9:$AD$20, ROW(AB9)) -> 9.001 | AF17: =INDEX($AB$9:$AB$20,MATCH(AE17,$AD$9:$AD$20,0)) -> 🐻기타 | AG17: =INDEX($AC$9:$AC$20,MATCH(AE17,$AD$9:$AD$20,0)) -> 169200
C18: 잉여현금 | D18: =D12-D14-D16 -> -43556626 | E18: 🐻전통시장(제로페이) | F18: =SUMIFS($K$62:$K$500,$L$62:$L$500,E18,$I$62:$I$500,"<>수입",$I$62:$I$500,"<>저축") -> 342300 | H18: 강릉여행 | R18: =SUMIFS($K$62:$K$500,$H$62:$H$500,R17,$I$62:$I$500,"<>수입",$I$62:$I$500,"<>저축") -> 18000 | S18: =SUMIFS($K$62:$K$500,$H$62:$H$500,S17,$I$62:$I$500,"<>수입",$I$62:$I$500,"<>저축") -> 183312 | T18: =SUMIFS($K$62:$K$500,$H$62:$H$500,T17,$I$62:$I$500,"<>수입",$I$62:$I$500,"<>저축") -> 268480 | U18: =SUMIFS($K$62:$K$500,$H$62:$H$500,U17,$I$62:$I$500,"<>수입",$I$62:$I$500,"<>저축") -> 297880 | V18: =SUMIFS($K$62:$K$500,$H$62:$H$500,V17,$I$62:$I$500,"<>수입",$I$62:$I$500,"<>저축") -> 124287 | W18: =SUMIFS($K$62:$K$500,$H$62:$H$500,W17,$I$62:$I$500,"<>수입",$I$62:$I$500,"<>저축") -> 194890 | X18: =SUMIFS($K$62:$K$500,$H$62:$H$500,X17,$I$62:$I$500,"<>수입",$I$62:$I$500,"<>저축") -> 0 | Y18: =SUM(R18:X18) -> 1086849 | AB18: =$R$33 -> 🐻기타 | AC18: =$X$39 -> 169200 | AD18: =_xlfn.RANK.EQ(AC18,$AB$9:$AC$20,0) + ROW(AB10)/10000 -> 9.001 | AE18: =SMALL($AD$9:$AD$20, ROW(AB10)) -> 10.0006 | AF18: =INDEX($AB$9:$AB$20,MATCH(AE18,$AD$9:$AD$20,0)) -> 🐻식비 | AG18: =INDEX($AC$9:$AC$20,MATCH(AE18,$AD$9:$AD$20,0)) -> 140200
C19: 총저축률 | D19: =(D16+D18)/D12 -> -7.9361318 | E19: 🐻하나카드 | F19: =SUMIFS($K$62:$K$500,$L$62:$L$500,E19,$I$62:$I$500,"<>수입",$I$62:$I$500,"<>저축") -> 956085 | R19: =R17+7 -> 45718 | S19: =S17+7 -> 45719 | T19: =T17+7 -> 45720 | U19: =U17+7 -> 45721 | V19: =V17+7 -> 45722 | W19: =W17+7 -> 45723 | X19: =X17+7 -> 45724 | AB19: =$R$41 -> 🍪이벤트성 | AC19: =$X$47 -> 42387013 | AD19: =_xlfn.RANK.EQ(AC19,$AB$9:$AC$20,0) + ROW(AB11)/10000 -> 1.0011 | AE19: =SMALL($AD$9:$AD$20, ROW(AB11)) -> 11.0007 | AF19: =INDEX($AB$9:$AB$20,MATCH(AE19,$AD$9:$AD$20,0)) -> 🍪여가비 | AG19: =INDEX($AC$9:$AC$20,MATCH(AE19,$AD$9:$AD$20,0)) -> 84920
C20: 현금저축률 | D20: =D18/D12 -> -7.9361318 | E20: 🐻현백카드 | F20: =SUM($F$14:$F$19) -> 3435845 | R20: =SUMIFS($K$62:$K$500,$H$62:$H$500,R19,$I$62:$I$500,"<>수입",$I$62:$I$500,"<>저축") -> 0 | S20: =SUMIFS($K$62:$K$500,$H$62:$H$500,S19,$I$62:$I$500,"<>수입",$I$62:$I$500,"<>저축") -> 0 | T20: =SUMIFS($K$62:$K$500,$H$62:$H$500,T19,$I$62:$I$500,"<>수입",$I$62:$I$500,"<>저축") -> 0 | U20: =SUMIFS($K$62:$K$500,$H$62:$H$500,U19,$I$62:$I$500,"<>수입",$I$62:$I$500,"<>저축") -> 0 | V20: =SUMIFS($K$62:$K$500,$H$62:$H$500,V19,$I$62:$I$500,"<>수입",$I$62:$I$500,"<>저축") -> 0 | W20: =SUMIFS($K$62:$K$500,$H$62:$H$500,W19,$I$62:$I$500,"<>수입",$I$62:$I$500,"<>저축") -> 0 | X20: =SUMIFS($K$62:$K$500,$H$62:$H$500,X19,$I$62:$I$500,"<>수입",$I$62:$I$500,"<>저축") -> 0 | Y20: =SUM(R20:X20) -> 0 | AB20: =$R$49 -> 🐻 이벤트성 | AC20: =$X$55 -> 409700 | AD20: =_xlfn.RANK.EQ(AC20,$AB$9:$AC$20,0) + ROW(AB12)/10000 -> 6.0012 | AE20: =SMALL($AD$9:$AD$20, ROW(AB12)) -> 12.0009 | AF20: =INDEX($AB$9:$AB$20,MATCH(AE20,$AD$9:$AD$20,0)) -> 🍪기타 | AG20: =INDEX($AC$9:$AC$20,MATCH(AE20,$AD$9:$AD$20,0)) -> 36080
E21: 🐻국민카드
C24: 대분류 | D24: 소분류 | E24: 목표 | F24: 합계 | H24: 대분류 | I24: 소분류 | J24: 예산 | K24: 합계 | M24: 대분류 | N24: 소분류 | O24: 예산 | P24: 합계 | R24: 대분류 | T24: 소분류 | V24: 예산 | X24: 합계
C25: 수입 | D25: 🍪 월급 | F25: =SUMIFS($K$62:$K$500,$I$62:$I$500,$C$25,$J$62:$J$500,D25) -> 3257030 | H25: 🍪고정비 | I25: 관리비 | K25: =SUMIFS($K$62:$K$500,$I$62:$I$500,$H$25,$J$62:$J$500,I25) -> 0 | M25: 🍪식비 | N25: 식재료비 | P25: =SUMIFS($K$62:$K$500,$I$62:$I$500,$M$25,$J$62:$J$500,N25) -> 279251 | R25: 🍪기타 | T25: 약국 | X25: =SUMIFS($K$62:$K$500,$I$62:$I$500,$R$25,$J$62:$J$500,T25) -> 3500
D26: 🍪 부수입 | F26: =SUMIFS($K$62:$K$500,$I$62:$I$500,$C$25,$J$62:$J$500,D26) -> 872670 | I26: 월세 | K26: =SUMIFS($K$62:$K$500,$I$62:$I$500,$H$25,$J$62:$J$500,I26) -> 800000 | N26: 회사점심 | P26: =SUMIFS($K$62:$K$500,$I$62:$I$500,$M$25,$J$62:$J$500,N26) -> 248000 | T26: 병원비 | X26: =SUMIFS($K$62:$K$500,$I$62:$I$500,$R$25,$J$62:$J$500,T26) -> 9300
D27: 🐻 월급 | F27: =SUMIFS($K$62:$K$500,$I$62:$I$500,$C$25,$J$62:$J$500,D27) -> 0 | I27: 대출이자 | K27: =SUMIFS($K$62:$K$500,$I$62:$I$500,$H$25,$J$62:$J$500,I27) -> 192822 | N27: 간식/카페 | P27: =SUMIFS($K$62:$K$500,$I$62:$I$500,$M$25,$J$62:$J$500,N27) -> 46000 | T27: 영양제 | X27: =SUMIFS($K$62:$K$500,$I$62:$I$500,$R$25,$J$62:$J$500,T27) -> 15780
D28: 🐻 부수입 | F28: =SUMIFS($K$62:$K$500,$I$62:$I$500,$C$25,$J$62:$J$500,D28) -> 0 | I28: 통신비 | K28: =SUMIFS($K$62:$K$500,$I$62:$I$500,$H$25,$J$62:$J$500,I28) -> 111600 | N28: 외식/배달 | P28: =SUMIFS($K$62:$K$500,$I$62:$I$500,$M$25,$J$62:$J$500,N28) -> 411700 | T28: 교통비 | X28: =SUMIFS($K$62:$K$500,$I$62:$I$500,$R$25,$J$62:$J$500,T28) -> 7500
D29: 기타 | F29: =SUMIFS($K$62:$K$500,$I$62:$I$500,$C$25,$J$62:$J$500,D29) -> 1358695 | I29: 보험료 | K29: =SUMIFS($K$62:$K$500,$I$62:$I$500,$H$25,$J$62:$J$500,I29) -> 1050790 | N29: 기타 | P29: =SUMIFS($K$62:$K$500,$I$62:$I$500,$M$25,$J$62:$J$500,N29) -> 0 | T29: 주유비 | X29: =SUMIFS($K$62:$K$500,$I$62:$I$500,$R$25,$J$62:$J$500,T29) -> 0
F30: =SUMIFS($K$62:$K$500,$I$62:$I$500,$C$25,$J$62:$J$500,D30) -> 0 | K30: =SUMIFS($K$62:$K$500,$I$62:$I$500,$H$25,$J$62:$J$500,I30) -> 0 | P30: =SUMIFS($K$62:$K$500,$I$62:$I$500,$M$25,$J$62:$J$500,N30) -> 0 | X30: =SUMIFS($K$62:$K$500,$I$62:$I$500,$R$25,$J$62:$J$500,T30) -> 0
F31: =SUMIFS($K$62:$K$500,$I$62:$I$500,$C$25,$J$62:$J$500,D31) -> 0 | H31: =IF(H25=0,"","총"&H25) -> 총🍪고정비 | K31: =SUM(K25:K30) -> 2155212 | M31: =IF(M25=0,"","총"&M25) -> 총🍪식비 | P31: =SUM(P25:P30) -> 984951 | R31: =IF(R25=0,"","총"&R25) -> 총🍪기타 | X31: =SUM(X25:X30) -> 36080
F32: =SUMIFS($K$62:$K$500,$I$62:$I$500,$C$25,$J$62:$J$500,D32) -> 0 | K32: =K31-J25 -> 2155212 | P32: =P31-O25 -> 984951 | X32: =X31-V25 -> 36080
C33: =IF(C25=0,"","총"&C25) -> 총수입 | F33: =SUM(F25:F32) -> 5488395 | H33: 🐻고정비 | I33: 관리비 | K33: =SUMIFS($K$62:$K$500,$I$62:$I$500,$H$33,$J$62:$J$500,I33) -> 457490 | M33: 🐻식비 | N33: 식재료비 | P33: =SUMIFS($K$62:$K$500,$I$62:$I$500,$M$33,$J$62:$J$500,N33) -> 36500 | R33: 🐻기타 | T33: 약국 | X33: =SUMIFS($K$62:$K$500,$I$62:$I$500,$R$33,$J$62:$J$500,T33) -> 2700
F34: =F33-E25 -> 5488395 | I34: 대출이자 | K34: =SUMIFS($K$62:$K$500,$I$62:$I$500,$H$33,$J$62:$J$500,I34) -> 0 | N34: 회사점심 | P34: =SUMIFS($K$62:$K$500,$I$62:$I$500,$M$33,$J$62:$J$500,N34) -> 33500 | T34: 병원비 | X34: =SUMIFS($K$62:$K$500,$I$62:$I$500,$R$33,$J$62:$J$500,T34) -> 5500
C35: 저축 | D35: 주택청약 | F35: =SUMIFS($K$62:$K$500,$I$62:$I$500,$C$35,$J$62:$J$500,D35) -> 0 | I35: 통신비 | K35: =SUMIFS($K$62:$K$500,$I$62:$I$500,$H$33,$J$62:$J$500,I35) -> 69050 | N35: 간식/카페 | P35: =SUMIFS($K$62:$K$500,$I$62:$I$500,$M$33,$J$62:$J$500,N35) -> 37400 | T35: 영양제 | X35: =SUMIFS($K$62:$K$500,$I$62:$I$500,$R$33,$J$62:$J$500,T35) -> 0
D36: 우리은행 | F36: =SUMIFS($K$62:$K$500,$I$62:$I$500,$C$35,$J$62:$J$500,D36) -> 0 | I36: 보험료 | K36: =SUMIFS($K$62:$K$500,$I$62:$I$500,$H$33,$J$62:$J$500,I36) -> 88010 | N36: 외식/배달 | P36: =SUMIFS($K$62:$K$500,$I$62:$I$500,$M$33,$J$62:$J$500,N36) -> 28900 | T36: 교통비 | X36: =SUMIFS($K$62:$K$500,$I$62:$I$500,$R$33,$J$62:$J$500,T36) -> 3000
D37: 케이뱅크 | F37: =SUMIFS($K$62:$K$500,$I$62:$I$500,$C$35,$J$62:$J$500,D37) -> 0 | I37: 곗돈 | K37: =SUMIFS($K$62:$K$500,$I$62:$I$500,$H$33,$J$62:$J$500,I37) -> 80000 | N37: 기타 | P37: =SUMIFS($K$62:$K$500,$I$62:$I$500,$M$33,$J$62:$J$500,N37) -> 3900 | T37: 주유비 | X37: =SUMIFS($K$62:$K$500,$I$62:$I$500,$R$33,$J$62:$J$500,T37) -> 158000
D38: 연금저축 | F38: =SUMIFS($K$62:$K$500,$I$62:$I$500,$C$35,$J$62:$J$500,D38) -> 0 | K38: =SUMIFS($K$62:$K$500,$I$62:$I$500,$H$33,$J$62:$J$500,I38) -> 0 | P38: =SUMIFS($K$62:$K$500,$I$62:$I$500,$M$33,$J$62:$J$500,N38) -> 0 | X38: =SUMIFS($K$62:$K$500,$I$62:$I$500,$R$33,$J$62:$J$500,T38) -> 0
F39: =SUMIFS($K$62:$K$500,$I$62:$I$500,$C$35,$J$62:$J$500,D39) -> 0 | H39: =IF(H33=0,"","총"&H33) -> 총🐻고정비 | K39: =SUM(K33:K38) -> 694550 | M39: =IF(M33=0,"","총"&M33) -> 총🐻식비 | P39: =SUM(P33:P38) -> 140200 | R39: =IF(R33=0,"","총"&R33) -> 총🐻기타 | X39: =SUM(X33:X38) -> 169200
F40: =SUMIFS($K$62:$K$500,$I$62:$I$500,$C$35,$J$62:$J$500,D40) -> 0 | K40: =K39-J33 -> 694550 | P40: =P39-O33 -> 140200 | X40: =X39-V33 -> 169200
F41: =SUMIFS($K$62:$K$500,$I$62:$I$500,$C$35,$J$62:$J$500,D41) -> 0 | H41: 🍪생필품 | I41: 주방/욕실 | K41: =SUMIFS($K$62:$K$500,$I$62:$I$500,$H$41,$J$62:$J$500,I41) -> 251480 | M41: 🍪여가비 | N41: 의류/잡화 | P41: =SUMIFS($K$62:$K$500,$I$62:$I$500,$M$41,$J$62:$J$500,N41) -> 44030 | R41: 🍪이벤트성 | T41: 축의/부의금 | X41: =SUMIFS($K$62:$K$500,$I$62:$I$500,$R$41,$J$62:$J$500,T41) -> 0
F42: =SUMIFS($K$62:$K$500,$I$62:$I$500,$C$35,$J$62:$J$500,D42) -> 0 | I42: 소모품 | K42: =SUMIFS($K$62:$K$500,$I$62:$I$500,$H$41,$J$62:$J$500,I42) -> 0 | N42: OTT | P42: =SUMIFS($K$62:$K$500,$I$62:$I$500,$M$41,$J$62:$J$500,N42) -> 7890 | T42: 생신/생일선물 | X42: =SUMIFS($K$62:$K$500,$I$62:$I$500,$R$41,$J$62:$J$500,T42) -> 0
C43: =IF(C35=0,"","총"&C25) -> 총수입 | F43: =SUM(F35:F42) -> 0 | I43: 기타 | K43: =SUMIFS($K$62:$K$500,$I$62:$I$500,$H$41,$J$62:$J$500,I43) -> 33000 | N43: 문화생활 | P43: =SUMIFS($K$62:$K$500,$I$62:$I$500,$M$41,$J$62:$J$500,N43) -> 23000 | T43: 명절/어버이날 | X43: =SUMIFS($K$62:$K$500,$I$62:$I$500,$R$41,$J$62:$J$500,T43) -> 0
F44: =F43-E35 -> 0 | K44: =SUMIFS($K$62:$K$500,$I$62:$I$500,$H$41,$J$62:$J$500,I44) -> 0 | N44: 자기계발 | P44: =SUMIFS($K$62:$K$500,$I$62:$I$500,$M$41,$J$62:$J$500,N44) -> 0 | T44: 여행 | X44: =SUMIFS($K$62:$K$500,$I$62:$I$500,$R$41,$J$62:$J$500,T44) -> 213480
K45: =SUMIFS($K$62:$K$500,$I$62:$I$500,$H$41,$J$62:$J$500,I45) -> 0 | N45: 미용 | P45: =SUMIFS($K$62:$K$500,$I$62:$I$500,$M$41,$J$62:$J$500,N45) -> 10000 | T45: 기타 | X45: =SUMIFS($K$62:$K$500,$I$62:$I$500,$R$41,$J$62:$J$500,T45) -> 42173533
K46: =SUMIFS($K$62:$K$500,$I$62:$I$500,$H$41,$J$62:$J$500,I46) -> 0 | P46: =SUMIFS($K$62:$K$500,$I$62:$I$500,$M$41,$J$62:$J$500,N46) -> 0 | T46: 출산 | X46: =SUMIFS($K$62:$K$500,$I$62:$I$500,$R$41,$J$62:$J$500,T46) -> 0
H47: =IF(H41=0,"","총"&H41) -> 총🍪생필품 | K47: =SUM(K41:K46) -> 284480 | M47: =IF(M41=0,"","총"&M41) -> 총🍪여가비 | P47: =SUM(P41:P46) -> 84920 | R47: =IF(R41=0,"","총"&R41) -> 총🍪이벤트성 | X47: =SUM(X41:X46) -> 42387013
K48: =K47-J41 -> 284480 | P48: =P47-O41 -> 84920 | X48: =X47-V41 -> 42387013
...

Sheet 3월
C3: 2025 | D3: 3
E8: 결제수단 | F8: 금액 | R8: S | S8: M | T8: T | U8: W | V8: T | W8: F | X8: S | Y8: 누적 | AB8: 대분류 | AC8: 합계
E9: 🍪체크카드(현영) | F9: =SUMIFS($K$62:$K$500,$L$62:$L$500,E9,$I$62:$I$500,"<>수입",$I$62:$I$500,"<>저축") -> 0 | R9: =DATE($C$3,$D$3,1)-WEEKDAY(DATE($C$3,$D$3,1))+1 -> 45711 | S9: =R9 + 1 -> 45712 | T9: =S9 + 1 -> 45713 | U9: =T9 + 1 -> 45714 | V9: =U9 + 1 -> 45715 | W9: =V9 + 1 -> 45716 | X9: =W9 + 1 -> 45717 | AB9: =$H$25 -> 🍪고정비 | AC9: =$K$31 -> 606561 | AD9: =_xlfn.RANK.EQ(AC9,$AB$9:$AC$20,0) + ROW(AB1)/10000 -> 4.0001 | AE9: =SMALL($AD$9:$AD$20, ROW(AB1)) -> 1.0005 | AF9: =INDEX($AB$9:$AB$20,MATCH(AE9,$AD$9:$AD$20,0)) -> 🍪식비 | AG9: =INDEX($AC$9:$AC$20,MATCH(AE9,$AD$9:$AD$20,0)) -> 1159150
E10: 🍪현금/이체 | F10: =SUMIFS($K$62:$K$500,$L$62:$L$500,E10,$I$62:$I$500,"<>수입",$I$62:$I$500,"<>저축") -> 344011 | R10: =SUMIFS($K$62:$K$500,$H$62:$H$500,R9,$I$62:$I$500,"<>수입",$I$62:$I$500,"<>저축") -> 0 | S10: =SUMIFS($K$62:$K$500,$H$62:$H$500,S9,$I$62:$I$500,"<>수입",$I$62:$I$500,"<>저축") -> 0 | T10: =SUMIFS($K$62:$K$500,$H$62:$H$500,T9,$I$62:$I$500,"<>수입",$I$62:$I$500,"<>저축") -> 0 | U10: =SUMIFS($K$62:$K$500,$H$62:$H$500,U9,$I$62:$I$500,"<>수입",$I$62:$I$500,"<>저축") -> 0 | V10: =SUMIFS($K$62:$K$500,$H$62:$H$500,V9,$I$62:$I$500,"<>수입",$I$62:$I$500,"<>저축") -> 0 | W10: =SUMIFS($K$62:$K$500,$H$62:$H$500,W9,$I$62:$I$500,"<>수입",$I$62:$I$500,"<>저축") -> 0 | X10: =SUMIFS($K$62:$K$500,$H$62:$H$500,X9,$I$62:$I$500,"<>수입",$I$62:$I$500,"<>저축") -> 294450 | Y10: =SUM(R10:X10) -> 294450 | AB10: =$H$33 -> 🐻고정비 | AC10: =$K$39 -> 641030 | AD10: =_xlfn.RANK.EQ(AC10,$AB$9:$AC$20,0) + ROW(AB2)/10000 -> 3.0002 | AE10: =SMALL($AD$9:$AD$20, ROW(AB2)) -> 2.0003 | AF10: =INDEX($AB$9:$AB$20,MATCH(AE10,$AD$9:$AD$20,0)) -> 🍪생필품 | AG10: =INDEX($AC$9:$AC$20,MATCH(AE10,$AD$9:$AD$20,0)) -> 691611
C11: 항목 | D11: 금액 | E11: 🍪전통시장(제로페이) | F11: =SUMIFS($K$62:$K$500,$L$62:$L$500,E11,$I$62:$I$500,"<>수입",$I$62:$I$500,"<>저축") -> 0 | R11: =R9 + 7 -> 45718 | S11: =S9 + 7 -> 45719 | T11: =T9 + 7 -> 45720 | U11: =U9 + 7 -> 45721 | V11: =V9 + 7 -> 45722 | W11: =W9 + 7 -> 45723 | X11: =X9 + 7 -> 45724 | AB11: =$H$41 -> 🍪생필품 | AC11: =$K$47 -> 691611 | AD11: =_xlfn.RANK.EQ(AC11,$AB$9:$AC$20,0) + ROW(AB3)/10000 -> 2.0003 | AE11: =SMALL($AD$9:$AD$20, ROW(AB3)) -> 3.0002 | AF11: =INDEX($AB$9:$AB$20,MATCH(AE11,$AD$9:$AD$20,0)) -> 🐻고정비 | AG11: =INDEX($AC$9:$AC$20,MATCH(AE11,$AD$9:$AD$20,0)) -> 641030
